2020-10-29 13:36:05,965 > INFO > JOBNAME:1603958765_8785334
2020-10-29 13:36:05,965 > INFO > CONFIG FILE:D:\scripts\GIT\Aruba_Controller_upgrade\conf_files\LAB WIRELESS UPGRADE 8.6
2020-10-29 13:36:06,031 > INFO > Starting Job
2020-10-29 13:36:06,044 > INFO > INFO:Running: 1603958765_8785334 Type:Upgrade
2020-10-29 13:36:06,058 > INFO > INFO:Starting Configuration LAB WIRELESS UPGRADE 8.6 Validation
2020-10-29 13:36:06,107 > INFO > Inserting upgrade list to upgrade.db
2020-10-29 13:36:10,157 > INFO > yes
2020-10-29 13:36:10,157 > INFO > INFO:Starting precheck
2020-10-29 13:36:10,183 > INFO > INFO:Executing Precheck
2020-10-29 13:36:12,472 > INFO > INFO:Login Success => 10.17.84.220:4343
2020-10-29 13:36:17,004 > INFO > INFO:Login Success => 10.17.84.221:4343
2020-10-29 13:36:20,102 > INFO > INFO:Session Valid : 10.17.84.220:4343
2020-10-29 13:36:22,542 > INFO > INFO:Session Valid : 10.17.84.221:4343
2020-10-29 13:36:24,596 > INFO > INFO:Session Valid : 10.17.84.220:4343
2020-10-29 13:36:27,365 > INFO > INFO:Session Valid : 10.17.84.221:4343
2020-10-29 13:36:31,260 > INFO > INFO:Session Valid : 10.17.84.220:4343
2020-10-29 13:36:33,622 > INFO > INFO:Session Valid : 10.17.84.221:4343
2020-10-29 13:36:34,610 > INFO > INFO:Installation Disk Auto not provided for 10.17.84.220:4343 , Trying to auto detect
2020-10-29 13:36:35,305 > INFO > INFO:Session Valid : 10.17.84.220:4343
2020-10-29 13:36:36,038 > INFO > INFO:NaaS-MM-1-10.17.84.220:4343 :Auto detect alternative partition: 1
2020-10-29 13:36:36,279 > INFO > INFO:Installation Disk Auto not provided for 10.17.84.221:4343 , Trying to auto detect
2020-10-29 13:36:36,984 > INFO > INFO:Session Valid : 10.17.84.221:4343
2020-10-29 13:36:38,799 > INFO > INFO:NaaS-VMC-1-10.17.84.221:4343 :Auto detect alternative partition: 0
2020-10-29 13:36:39,558 > INFO > INFO:PRECHECK started for : (MM) NaaS-MM-1:10.17.84.220:4343
2020-10-29 13:36:40,309 > INFO > INFO:Session Valid : 10.17.84.220:4343
2020-10-29 13:36:40,507 > INFO > INFO:Executing NaaS-MM-1 - 10.17.84.220:4343 => show clock
2020-10-29 13:36:41,271 > INFO > INFO:Executing NaaS-MM-1 - 10.17.84.220:4343 => show version
2020-10-29 13:36:42,077 > INFO > INFO:Executing NaaS-MM-1 - 10.17.84.220:4343 => show image version
2020-10-29 13:36:42,858 > INFO > INFO:Executing NaaS-MM-1 - 10.17.84.220:4343 => show storage
2020-10-29 13:36:43,636 > INFO > INFO:Executing NaaS-MM-1 - 10.17.84.220:4343 => show cpuload
2020-10-29 13:36:44,370 > INFO > INFO:Executing NaaS-MM-1 - 10.17.84.220:4343 => show memory
2020-10-29 13:36:45,081 > INFO > INFO:Executing NaaS-MM-1 - 10.17.84.220:4343 => show boot
2020-10-29 13:36:45,821 > INFO > INFO:Executing NaaS-MM-1 - 10.17.84.220:4343 => show switches
2020-10-29 13:36:46,549 > INFO > INFO:Executing NaaS-MM-1 - 10.17.84.220:4343 => show switchinfo
2020-10-29 13:36:47,349 > INFO > INFO:Executing NaaS-MM-1 - 10.17.84.220:4343 => show boot history
2020-10-29 13:36:48,627 > INFO > INFO:Executing NaaS-MM-1 - 10.17.84.220:4343 => show crypto ipsec sa
2020-10-29 13:36:49,497 > INFO > INFO:Executing NaaS-MM-1 - 10.17.84.220:4343 => show master-redundancy
2020-10-29 13:36:50,402 > INFO > INFO:Executing NaaS-MM-1 - 10.17.84.220:4343 => show database synchronize
2020-10-29 13:36:51,231 > INFO > INFO:Executing NaaS-MM-1 - 10.17.84.220:4343 => show license
2020-10-29 13:36:52,012 > INFO > INFO:Executing NaaS-MM-1 - 10.17.84.220:4343 => show running-config
2020-10-29 13:36:53,159 > INFO > INFO:PRECHECK started for : (MD) NaaS-VMC-1:10.17.84.221:4343
2020-10-29 13:36:53,777 > ERROR > get_session:
Traceback (most recent call last):
  File "D:\scripts\py\lib\site-packages\urllib3\connectionpool.py", line 677, in urlopen
    chunked=chunked,
  File "D:\scripts\py\lib\site-packages\urllib3\connectionpool.py", line 426, in _make_request
    six.raise_from(e, None)
  File "<string>", line 3, in raise_from
  File "D:\scripts\py\lib\site-packages\urllib3\connectionpool.py", line 421, in _make_request
    httplib_response = conn.getresponse()
  File "D:\scripts\py\lib\http\client.py", line 1321, in getresponse
    response.begin()
  File "D:\scripts\py\lib\http\client.py", line 296, in begin
    version, status, reason = self._read_status()
  File "D:\scripts\py\lib\http\client.py", line 265, in _read_status
    raise RemoteDisconnected("Remote end closed connection without"
http.client.RemoteDisconnected: Remote end closed connection without response

During handling of the above exception, another exception occurred:

Traceback (most recent call last):
  File "D:\scripts\py\lib\site-packages\requests\adapters.py", line 449, in send
    timeout=timeout
  File "D:\scripts\py\lib\site-packages\urllib3\connectionpool.py", line 725, in urlopen
    method, url, error=e, _pool=self, _stacktrace=sys.exc_info()[2]
  File "D:\scripts\py\lib\site-packages\urllib3\util\retry.py", line 403, in increment
    raise six.reraise(type(error), error, _stacktrace)
  File "D:\scripts\py\lib\site-packages\urllib3\packages\six.py", line 734, in reraise
    raise value.with_traceback(tb)
  File "D:\scripts\py\lib\site-packages\urllib3\connectionpool.py", line 677, in urlopen
    chunked=chunked,
  File "D:\scripts\py\lib\site-packages\urllib3\connectionpool.py", line 426, in _make_request
    six.raise_from(e, None)
  File "<string>", line 3, in raise_from
  File "D:\scripts\py\lib\site-packages\urllib3\connectionpool.py", line 421, in _make_request
    httplib_response = conn.getresponse()
  File "D:\scripts\py\lib\http\client.py", line 1321, in getresponse
    response.begin()
  File "D:\scripts\py\lib\http\client.py", line 296, in begin
    version, status, reason = self._read_status()
  File "D:\scripts\py\lib\http\client.py", line 265, in _read_status
    raise RemoteDisconnected("Remote end closed connection without"
urllib3.exceptions.ProtocolError: ('Connection aborted.', RemoteDisconnected('Remote end closed connection without response'))

During handling of the above exception, another exception occurred:

Traceback (most recent call last):
  File "D:\scripts\GIT\Aruba_Controller_upgrade\Aruba_Wireless_Upgrade_APP.py", line 87, in get_session
    res = r_session.get(get_clock,verify=False)
  File "D:\scripts\py\lib\site-packages\requests\sessions.py", line 543, in get
    return self.request('GET', url, **kwargs)
  File "D:\scripts\py\lib\site-packages\requests\sessions.py", line 530, in request
    resp = self.send(prep, **send_kwargs)
  File "D:\scripts\py\lib\site-packages\requests\sessions.py", line 643, in send
    r = adapter.send(request, **kwargs)
  File "D:\scripts\py\lib\site-packages\requests\adapters.py", line 498, in send
    raise ConnectionError(err, request=request)
requests.exceptions.ConnectionError: ('Connection aborted.', RemoteDisconnected('Remote end closed connection without response'))
2020-10-29 13:36:56,367 > INFO > INFO:Login Success => 10.17.84.221:4343
2020-10-29 13:36:56,773 > INFO > INFO:Executing NaaS-VMC-1 - 10.17.84.221:4343 => show clock
2020-10-29 13:36:59,255 > INFO > INFO:Executing NaaS-VMC-1 - 10.17.84.221:4343 => show version
2020-10-29 13:37:00,135 > INFO > INFO:Executing NaaS-VMC-1 - 10.17.84.221:4343 => show image version
2020-10-29 13:37:01,007 > INFO > INFO:Executing NaaS-VMC-1 - 10.17.84.221:4343 => show storage
2020-10-29 13:37:01,917 > INFO > INFO:Executing NaaS-VMC-1 - 10.17.84.221:4343 => show cpuload
2020-10-29 13:37:02,709 > INFO > INFO:Executing NaaS-VMC-1 - 10.17.84.221:4343 => show memory
2020-10-29 13:37:03,476 > INFO > INFO:Executing NaaS-VMC-1 - 10.17.84.221:4343 => show boot
2020-10-29 13:37:04,213 > INFO > INFO:Executing NaaS-VMC-1 - 10.17.84.221:4343 => show switches
2020-10-29 13:37:04,960 > INFO > INFO:Executing NaaS-VMC-1 - 10.17.84.221:4343 => show switchinfo
2020-10-29 13:37:05,825 > INFO > INFO:Executing NaaS-VMC-1 - 10.17.84.221:4343 => show boot history
2020-10-29 13:37:06,985 > INFO > INFO:Executing NaaS-VMC-1 - 10.17.84.221:4343 => show user
2020-10-29 13:37:07,680 > INFO > INFO:Executing NaaS-VMC-1 - 10.17.84.221:4343 => show ap database long
2020-10-29 13:37:08,411 > INFO > INFO:Executing NaaS-VMC-1 - 10.17.84.221:4343 => show ap bss-table
2020-10-29 13:37:09,219 > INFO > INFO:Executing NaaS-VMC-1 - 10.17.84.221:4343 => show ap essid
2020-10-29 13:37:09,930 > INFO > INFO:Executing NaaS-VMC-1 - 10.17.84.221:4343 => show ap active counters
2020-10-29 13:37:10,651 > INFO > INFO:Executing NaaS-VMC-1 - 10.17.84.221:4343 => show ap debug counters
2020-10-29 13:37:11,346 > INFO > INFO:Executing NaaS-VMC-1 - 10.17.84.221:4343 => show lc-cluster group-membership
2020-10-29 13:37:12,070 > INFO > INFO:Executing NaaS-VMC-1 - 10.17.84.221:4343 => show switches
2020-10-29 13:37:12,778 > INFO > INFO:Executing NaaS-VMC-1 - 10.17.84.221:4343 => show license
2020-10-29 13:37:13,478 > INFO > INFO:Executing NaaS-VMC-1 - 10.17.84.221:4343 => show running-config
2020-10-29 13:37:15,842 > INFO > INFO:Executing NaaS-VMC-1 - 10.17.84.221:4343 => show boot
2020-10-29 13:37:16,596 > INFO > INFO:Executing NaaS-VMC-1 - 10.17.84.221:4343 => show version
2020-10-29 13:37:17,395 > INFO > INFO:Precheck Completed
2020-10-29 13:38:05,784 > INFO > INFO:Total upgrade hosts:2
2020-10-29 13:38:05,800 > INFO > INFO:MM: Preparing for host NaaS-MM-1 IP: 10.17.84.220:4343
2020-10-29 13:38:08,124 > INFO > INFO:Session Valid : 10.17.84.220:4343
2020-10-29 13:38:08,857 > WARNING > WARNING:Required image version for (MM) Host:NaaS-MM-1:10.17.84.220:4343 = Disk:1 Version:8.6.0.5 Build:75979
2020-10-29 13:38:08,889 > DEBUG > WARNING:Required image version for (MM) Host:NaaS-MM-1:10.17.84.220:4343 = Disk:1 Version:8.6.0.5 Build:75979
2020-10-29 13:38:26,970 > WARNING > WARNING:User aborted to install : Do you want to install: Image Version:8.6.0.5-75979 on Disk:1 Host:NaaS-MM-1:10.17.84.220:4343
2020-10-29 13:38:26,986 > DEBUG > WARNING:User aborted to install : Do you want to install: Image Version:8.6.0.5-75979 on Disk:1 Host:NaaS-MM-1:10.17.84.220:4343
2020-10-29 13:38:29,306 > INFO > INFO:Session Valid : 10.17.84.220:4343
2020-10-29 13:38:30,026 > WARNING > WARNING:Required image version for (MM) Host:NaaS-MM-1:10.17.84.220:4343 = Disk:1 Version:8.6.0.5 Build:75979
2020-10-29 13:38:30,076 > DEBUG > WARNING:Required image version for (MM) Host:NaaS-MM-1:10.17.84.220:4343 = Disk:1 Version:8.6.0.5 Build:75979
2020-10-29 13:38:30,100 > INFO > INFO:User accepted : Do you want to install: Image Version:8.6.0.5-75979 on Disk:1 Host:NaaS-MM-1:10.17.84.220:4343
2020-10-29 13:38:30,815 > INFO > INFO:Session Valid : 10.17.84.220:4343
2020-10-29 13:38:30,869 > INFO > INFO:NaaS-MM-1:10.17.84.220:4343- Installing AOS: ArubaOS_MM_8.6.0.5_75979 from ftp server:10.17.84.225
2020-10-29 13:39:27,460 > DEBUG > DEBUG:b'<html>  <script>  top.(null)("<re><SUCCESS>10.17.84.225</SUCCESS></re>", "image");  </script></html>'
2020-10-29 13:39:27,502 > INFO > INFO:File copy completed COMPLETED: UPLOADED IMAGE TO DISK 1 ArubaOS_MM_8.6.0.5_75979
2020-10-29 13:39:27,519 > INFO > b'<html>  <script>  top.(null)("<re><SUCCESS>10.17.84.225</SUCCESS></re>", "image");  </script></html>'
2020-10-29 13:39:27,532 > INFO > INFO:MD: Preparing for host NaaS-VMC-1 IP: 10.17.84.221:4343
2020-10-29 13:39:29,792 > INFO > INFO:Session Valid : 10.17.84.221:4343
2020-10-29 13:39:30,516 > WARNING > WARNING:Required image version for (MD) Host:NaaS-VMC-1:10.17.84.221:4343 = Disk:0 Version:8.6.0.5 Build:75979
2020-10-29 13:39:30,543 > DEBUG > WARNING:Required image version for (MD) Host:NaaS-VMC-1:10.17.84.221:4343 = Disk:0 Version:8.6.0.5 Build:75979
2020-10-29 13:41:54,730 > WARNING > WARNING:User aborted to install : Do you want to install: Image Version:8.6.0.5-75979 on Disk:0 Host:NaaS-VMC-1:10.17.84.221:4343
2020-10-29 13:41:54,748 > DEBUG > WARNING:User aborted to install : Do you want to install: Image Version:8.6.0.5-75979 on Disk:0 Host:NaaS-VMC-1:10.17.84.221:4343
2020-10-29 13:41:56,968 > INFO > INFO:Session Valid : 10.17.84.221:4343
2020-10-29 13:41:57,660 > WARNING > WARNING:Required image version for (MD) Host:NaaS-VMC-1:10.17.84.221:4343 = Disk:0 Version:8.6.0.5 Build:75979
2020-10-29 13:41:57,680 > DEBUG > WARNING:Required image version for (MD) Host:NaaS-VMC-1:10.17.84.221:4343 = Disk:0 Version:8.6.0.5 Build:75979
2020-10-29 13:41:57,695 > INFO > INFO:User accepted : Do you want to install: Image Version:8.6.0.5-75979 on Disk:0 Host:NaaS-VMC-1:10.17.84.221:4343
2020-10-29 13:41:58,379 > INFO > INFO:Session Valid : 10.17.84.221:4343
2020-10-29 13:41:58,419 > INFO > INFO:NaaS-VMC-1:10.17.84.221:4343- Installing AOS: ArubaOS_VMC_8.6.0.5_75979 from ftp server:10.17.84.225
2020-10-29 13:47:21,586 > DEBUG > DEBUG:b'<html>  <script>  top.(null)("<re><SUCCESS>10.17.84.225</SUCCESS></re>", "image");  </script></html>'
2020-10-29 13:47:21,620 > INFO > INFO:File copy completed COMPLETED: UPLOADED IMAGE TO DISK 0 ArubaOS_VMC_8.6.0.5_75979
2020-10-29 13:47:21,637 > INFO > b'<html>  <script>  top.(null)("<re><SUCCESS>10.17.84.225</SUCCESS></re>", "image");  </script></html>'
2020-10-29 13:48:15,711 > INFO > INFO:STARTING AP IMAGE PRELOAD FOR NaaS-VMC-1-10.17.84.221:4343 FROM DISK:0 MAX AP:1
2020-10-29 13:48:18,176 > INFO > INFO:Session Valid : 10.17.84.221:4343
2020-10-29 13:48:19,000 > WARNING > WARNING:AP Pre-load Failed:NaaS-VMC-1-10.17.84.221:4343 => An AP image preload has already been executed. You must reload the controller before executing another one.
2020-10-29 13:48:19,024 > DEBUG > WARNING:AP Pre-load Failed:NaaS-VMC-1-10.17.84.221:4343 => An AP image preload has already been executed. You must reload the controller before executing another one.
2020-10-29 13:48:22,816 > INFO > INFO:Session Valid : 10.17.84.221:4343
2020-10-29 13:48:24,185 > INFO > INFO:Validating AP Preload status for:NaaS-VMC-1 - 10.17.84.221:4343
2020-10-29 13:48:27,925 > INFO > INFO:Session Valid : 10.17.84.221:4343
2020-10-29 13:48:29,275 > INFO > INFO:Validating AP Preload status for:NaaS-VMC-1 - 10.17.84.221:4343
2020-10-29 13:48:33,066 > INFO > INFO:Session Valid : 10.17.84.221:4343
2020-10-29 13:48:34,376 > INFO > INFO:Validating AP Preload status for:NaaS-VMC-1 - 10.17.84.221:4343
2020-10-29 13:48:39,326 > INFO > INFO:Session Valid : 10.17.84.221:4343
2020-10-29 13:48:41,051 > INFO > INFO:Validating AP Preload status for:NaaS-VMC-1 - 10.17.84.221:4343
2020-10-29 13:48:44,782 > INFO > INFO:Session Valid : 10.17.84.221:4343
2020-10-29 13:48:46,260 > INFO > INFO:Validating AP Preload status for:NaaS-VMC-1 - 10.17.84.221:4343
2020-10-29 13:48:50,035 > INFO > INFO:Session Valid : 10.17.84.221:4343
2020-10-29 13:48:51,356 > INFO > INFO:Validating AP Preload status for:NaaS-VMC-1 - 10.17.84.221:4343
2020-10-29 13:48:55,100 > INFO > INFO:Session Valid : 10.17.84.221:4343
2020-10-29 13:48:56,480 > INFO > INFO:Validating AP Preload status for:NaaS-VMC-1 - 10.17.84.221:4343
2020-10-29 13:49:00,179 > INFO > INFO:Session Valid : 10.17.84.221:4343
2020-10-29 13:49:01,500 > INFO > INFO:Validating AP Preload status for:NaaS-VMC-1 - 10.17.84.221:4343
2020-10-29 13:49:05,188 > INFO > INFO:Session Valid : 10.17.84.221:4343
2020-10-29 13:49:06,513 > INFO > INFO:Validating AP Preload status for:NaaS-VMC-1 - 10.17.84.221:4343
2020-10-29 13:49:09,568 > WARNING > WARNING:USER SKIPPED AP IMAGE PRELOAD FOR NaaS-VMC-1-10.17.84.221:4343
2020-10-29 13:49:09,784 > DEBUG > WARNING:USER SKIPPED AP IMAGE PRELOAD FOR NaaS-VMC-1-10.17.84.221:4343
2020-10-29 13:49:13,646 > INFO > INFO:Starting Upgrade
2020-10-29 13:49:19,686 > INFO > INFO:Starting reboot
2020-10-29 13:50:23,386 > INFO > INFO:Session Valid : 10.17.84.220:4343
2020-10-29 13:50:29,561 > WARNING > WARNING:=> Reloading MM: NaaS-MM-1 - 10.17.84.220:4343
2020-10-29 13:50:29,579 > DEBUG > WARNING:=> Reloading MM: NaaS-MM-1 - 10.17.84.220:4343
2020-10-29 13:50:33,285 > INFO > INFO:Please wait: (MM) NaaS-MM-1 10.17.84.220:4343 -- Pinging...
2020-10-29 13:50:37,283 > INFO > INFO:Please wait: (MM) NaaS-MM-1 10.17.84.220:4343 -- Pinging...
2020-10-29 13:51:59,858 > INFO > INFO:Please wait: Trying (MM) NaaS-MM-1 10.17.84.220:4343 -- Request timeout...
2020-10-29 13:52:24,016 > INFO > INFO:Please wait: Trying (MM) NaaS-MM-1 10.17.84.220:4343 -- Request timeout...
2020-10-29 13:52:48,066 > INFO > INFO:Please wait: Trying (MM) NaaS-MM-1 10.17.84.220:4343 -- Request timeout...
2020-10-29 13:53:12,118 > INFO > INFO:Please wait: Trying (MM) NaaS-MM-1 10.17.84.220:4343 -- Request timeout...
2020-10-29 13:53:36,154 > INFO > INFO:Please wait: Trying (MM) NaaS-MM-1 10.17.84.220:4343 -- Request timeout...
2020-10-29 13:54:00,197 > INFO > INFO:Please wait: Trying (MM) NaaS-MM-1 10.17.84.220:4343 -- Request timeout...
2020-10-29 13:54:09,026 > INFO > INFO:Please wait: Trying (MM) NaaS-MM-1 10.17.84.220:4343 -- Request timeout...
2020-10-29 13:54:14,575 > INFO > INFO:Reload Completed for (MM) NaaS-MM-1 10.17.84.220:4343
2020-10-29 13:54:19,090 > ERROR > ERROR:Login error : 10.17.84.220:4343
2020-10-29 13:54:19,114 > DEBUG > ERROR:Login error : 10.17.84.220:4343
2020-10-29 13:54:19,133 > ERROR > Login error:10.17.84.220:4343 
Traceback (most recent call last):
  File "D:\scripts\py\lib\site-packages\urllib3\connectionpool.py", line 677, in urlopen
    chunked=chunked,
  File "D:\scripts\py\lib\site-packages\urllib3\connectionpool.py", line 426, in _make_request
    six.raise_from(e, None)
  File "<string>", line 3, in raise_from
  File "D:\scripts\py\lib\site-packages\urllib3\connectionpool.py", line 421, in _make_request
    httplib_response = conn.getresponse()
  File "D:\scripts\py\lib\http\client.py", line 1321, in getresponse
    response.begin()
  File "D:\scripts\py\lib\http\client.py", line 296, in begin
    version, status, reason = self._read_status()
  File "D:\scripts\py\lib\http\client.py", line 265, in _read_status
    raise RemoteDisconnected("Remote end closed connection without"
http.client.RemoteDisconnected: Remote end closed connection without response

During handling of the above exception, another exception occurred:

Traceback (most recent call last):
  File "D:\scripts\py\lib\site-packages\requests\adapters.py", line 449, in send
    timeout=timeout
  File "D:\scripts\py\lib\site-packages\urllib3\connectionpool.py", line 725, in urlopen
    method, url, error=e, _pool=self, _stacktrace=sys.exc_info()[2]
  File "D:\scripts\py\lib\site-packages\urllib3\util\retry.py", line 403, in increment
    raise six.reraise(type(error), error, _stacktrace)
  File "D:\scripts\py\lib\site-packages\urllib3\packages\six.py", line 734, in reraise
    raise value.with_traceback(tb)
  File "D:\scripts\py\lib\site-packages\urllib3\connectionpool.py", line 677, in urlopen
    chunked=chunked,
  File "D:\scripts\py\lib\site-packages\urllib3\connectionpool.py", line 426, in _make_request
    six.raise_from(e, None)
  File "<string>", line 3, in raise_from
  File "D:\scripts\py\lib\site-packages\urllib3\connectionpool.py", line 421, in _make_request
    httplib_response = conn.getresponse()
  File "D:\scripts\py\lib\http\client.py", line 1321, in getresponse
    response.begin()
  File "D:\scripts\py\lib\http\client.py", line 296, in begin
    version, status, reason = self._read_status()
  File "D:\scripts\py\lib\http\client.py", line 265, in _read_status
    raise RemoteDisconnected("Remote end closed connection without"
urllib3.exceptions.ProtocolError: ('Connection aborted.', RemoteDisconnected('Remote end closed connection without response'))

During handling of the above exception, another exception occurred:

Traceback (most recent call last):
  File "D:\scripts\GIT\Aruba_Controller_upgrade\Aruba_Wireless_Upgrade_APP.py", line 105, in get_session
    res = r_session.post(login_url, data = login_post,verify=False)
  File "D:\scripts\py\lib\site-packages\requests\sessions.py", line 578, in post
    return self.request('POST', url, data=data, json=json, **kwargs)
  File "D:\scripts\py\lib\site-packages\requests\sessions.py", line 530, in request
    resp = self.send(prep, **send_kwargs)
  File "D:\scripts\py\lib\site-packages\requests\sessions.py", line 643, in send
    r = adapter.send(request, **kwargs)
  File "D:\scripts\py\lib\site-packages\requests\adapters.py", line 498, in send
    raise ConnectionError(err, request=request)
requests.exceptions.ConnectionError: ('Connection aborted.', RemoteDisconnected('Remote end closed connection without response'))
2020-10-29 13:54:19,148 > INFO > INFO:=>(MM) NaaS-MM-1-10.17.84.220:4343 8.6.0.5:75979 : NEW IMAGE UPGRADE SUCCESS
2020-10-29 14:00:50,807 > ERROR > get_session:
Traceback (most recent call last):
  File "D:\scripts\py\lib\site-packages\urllib3\connection.py", line 160, in _new_conn
    (self._dns_host, self.port), self.timeout, **extra_kw
  File "D:\scripts\py\lib\site-packages\urllib3\util\connection.py", line 84, in create_connection
    raise err
  File "D:\scripts\py\lib\site-packages\urllib3\util\connection.py", line 74, in create_connection
    sock.connect(sa)
TimeoutError: [WinError 10060] A connection attempt failed because the connected party did not properly respond after a period of time, or established connection failed because connected host has failed to respond

During handling of the above exception, another exception occurred:

Traceback (most recent call last):
  File "D:\scripts\py\lib\site-packages\urllib3\connectionpool.py", line 677, in urlopen
    chunked=chunked,
  File "D:\scripts\py\lib\site-packages\urllib3\connectionpool.py", line 381, in _make_request
    self._validate_conn(conn)
  File "D:\scripts\py\lib\site-packages\urllib3\connectionpool.py", line 976, in _validate_conn
    conn.connect()
  File "D:\scripts\py\lib\site-packages\urllib3\connection.py", line 308, in connect
    conn = self._new_conn()
  File "D:\scripts\py\lib\site-packages\urllib3\connection.py", line 172, in _new_conn
    self, "Failed to establish a new connection: %s" % e
urllib3.exceptions.NewConnectionError: <urllib3.connection.HTTPSConnection object at 0x00000254E456F080>: Failed to establish a new connection: [WinError 10060] A connection attempt failed because the connected party did not properly respond after a period of time, or established connection failed because connected host has failed to respond

During handling of the above exception, another exception occurred:

Traceback (most recent call last):
  File "D:\scripts\py\lib\site-packages\requests\adapters.py", line 449, in send
    timeout=timeout
  File "D:\scripts\py\lib\site-packages\urllib3\connectionpool.py", line 725, in urlopen
    method, url, error=e, _pool=self, _stacktrace=sys.exc_info()[2]
  File "D:\scripts\py\lib\site-packages\urllib3\util\retry.py", line 439, in increment
    raise MaxRetryError(_pool, url, error or ResponseError(cause))
urllib3.exceptions.MaxRetryError: HTTPSConnectionPool(host='10.17.84.221', port=4343): Max retries exceeded with url: /v1/configuration/showcommand?command=show%20clock&UIDARUBA=Y2E3MGIwZDQtZThlYi00ODUxLTkxZTctNzhi (Caused by NewConnectionError('<urllib3.connection.HTTPSConnection object at 0x00000254E456F080>: Failed to establish a new connection: [WinError 10060] A connection attempt failed because the connected party did not properly respond after a period of time, or established connection failed because connected host has failed to respond'))

During handling of the above exception, another exception occurred:

Traceback (most recent call last):
  File "D:\scripts\GIT\Aruba_Controller_upgrade\Aruba_Wireless_Upgrade_APP.py", line 87, in get_session
    res = r_session.get(get_clock,verify=False)
  File "D:\scripts\py\lib\site-packages\requests\sessions.py", line 543, in get
    return self.request('GET', url, **kwargs)
  File "D:\scripts\py\lib\site-packages\requests\sessions.py", line 530, in request
    resp = self.send(prep, **send_kwargs)
  File "D:\scripts\py\lib\site-packages\requests\sessions.py", line 643, in send
    r = adapter.send(request, **kwargs)
  File "D:\scripts\py\lib\site-packages\requests\adapters.py", line 516, in send
    raise ConnectionError(e, request=request)
requests.exceptions.ConnectionError: HTTPSConnectionPool(host='10.17.84.221', port=4343): Max retries exceeded with url: /v1/configuration/showcommand?command=show%20clock&UIDARUBA=Y2E3MGIwZDQtZThlYi00ODUxLTkxZTctNzhi (Caused by NewConnectionError('<urllib3.connection.HTTPSConnection object at 0x00000254E456F080>: Failed to establish a new connection: [WinError 10060] A connection attempt failed because the connected party did not properly respond after a period of time, or established connection failed because connected host has failed to respond'))
2020-10-29 14:01:12,051 > ERROR > ERROR:Login error : 10.17.84.221:4343
2020-10-29 14:01:12,821 > DEBUG > ERROR:Login error : 10.17.84.221:4343
2020-10-29 14:01:12,853 > ERROR > Login error:10.17.84.221:4343 
Traceback (most recent call last):
  File "D:\scripts\py\lib\site-packages\urllib3\connection.py", line 160, in _new_conn
    (self._dns_host, self.port), self.timeout, **extra_kw
  File "D:\scripts\py\lib\site-packages\urllib3\util\connection.py", line 84, in create_connection
    raise err
  File "D:\scripts\py\lib\site-packages\urllib3\util\connection.py", line 74, in create_connection
    sock.connect(sa)
TimeoutError: [WinError 10060] A connection attempt failed because the connected party did not properly respond after a period of time, or established connection failed because connected host has failed to respond

During handling of the above exception, another exception occurred:

Traceback (most recent call last):
  File "D:\scripts\py\lib\site-packages\urllib3\connectionpool.py", line 677, in urlopen
    chunked=chunked,
  File "D:\scripts\py\lib\site-packages\urllib3\connectionpool.py", line 381, in _make_request
    self._validate_conn(conn)
  File "D:\scripts\py\lib\site-packages\urllib3\connectionpool.py", line 976, in _validate_conn
    conn.connect()
  File "D:\scripts\py\lib\site-packages\urllib3\connection.py", line 308, in connect
    conn = self._new_conn()
  File "D:\scripts\py\lib\site-packages\urllib3\connection.py", line 172, in _new_conn
    self, "Failed to establish a new connection: %s" % e
urllib3.exceptions.NewConnectionError: <urllib3.connection.HTTPSConnection object at 0x00000254E44EB0B8>: Failed to establish a new connection: [WinError 10060] A connection attempt failed because the connected party did not properly respond after a period of time, or established connection failed because connected host has failed to respond

During handling of the above exception, another exception occurred:

Traceback (most recent call last):
  File "D:\scripts\py\lib\site-packages\requests\adapters.py", line 449, in send
    timeout=timeout
  File "D:\scripts\py\lib\site-packages\urllib3\connectionpool.py", line 725, in urlopen
    method, url, error=e, _pool=self, _stacktrace=sys.exc_info()[2]
  File "D:\scripts\py\lib\site-packages\urllib3\util\retry.py", line 439, in increment
    raise MaxRetryError(_pool, url, error or ResponseError(cause))
urllib3.exceptions.MaxRetryError: HTTPSConnectionPool(host='10.17.84.221', port=4343): Max retries exceeded with url: /v1/api/login (Caused by NewConnectionError('<urllib3.connection.HTTPSConnection object at 0x00000254E44EB0B8>: Failed to establish a new connection: [WinError 10060] A connection attempt failed because the connected party did not properly respond after a period of time, or established connection failed because connected host has failed to respond'))

During handling of the above exception, another exception occurred:

Traceback (most recent call last):
  File "D:\scripts\GIT\Aruba_Controller_upgrade\Aruba_Wireless_Upgrade_APP.py", line 105, in get_session
    res = r_session.post(login_url, data = login_post,verify=False)
  File "D:\scripts\py\lib\site-packages\requests\sessions.py", line 578, in post
    return self.request('POST', url, data=data, json=json, **kwargs)
  File "D:\scripts\py\lib\site-packages\requests\sessions.py", line 530, in request
    resp = self.send(prep, **send_kwargs)
  File "D:\scripts\py\lib\site-packages\requests\sessions.py", line 643, in send
    r = adapter.send(request, **kwargs)
  File "D:\scripts\py\lib\site-packages\requests\adapters.py", line 516, in send
    raise ConnectionError(e, request=request)
requests.exceptions.ConnectionError: HTTPSConnectionPool(host='10.17.84.221', port=4343): Max retries exceeded with url: /v1/api/login (Caused by NewConnectionError('<urllib3.connection.HTTPSConnection object at 0x00000254E44EB0B8>: Failed to establish a new connection: [WinError 10060] A connection attempt failed because the connected party did not properly respond after a period of time, or established connection failed because connected host has failed to respond'))
2020-10-29 14:01:12,854 > ERROR > ERROR:*** Warning : Failed to get reboot info (Please check manualy...)
2020-10-29 14:01:12,872 > DEBUG > ERROR:*** Warning : Failed to get reboot info (Please check manualy...)
2020-10-29 14:01:33,893 > ERROR > get_session:
Traceback (most recent call last):
  File "D:\scripts\py\lib\site-packages\urllib3\connection.py", line 160, in _new_conn
    (self._dns_host, self.port), self.timeout, **extra_kw
  File "D:\scripts\py\lib\site-packages\urllib3\util\connection.py", line 84, in create_connection
    raise err
  File "D:\scripts\py\lib\site-packages\urllib3\util\connection.py", line 74, in create_connection
    sock.connect(sa)
TimeoutError: [WinError 10060] A connection attempt failed because the connected party did not properly respond after a period of time, or established connection failed because connected host has failed to respond

During handling of the above exception, another exception occurred:

Traceback (most recent call last):
  File "D:\scripts\py\lib\site-packages\urllib3\connectionpool.py", line 677, in urlopen
    chunked=chunked,
  File "D:\scripts\py\lib\site-packages\urllib3\connectionpool.py", line 381, in _make_request
    self._validate_conn(conn)
  File "D:\scripts\py\lib\site-packages\urllib3\connectionpool.py", line 976, in _validate_conn
    conn.connect()
  File "D:\scripts\py\lib\site-packages\urllib3\connection.py", line 308, in connect
    conn = self._new_conn()
  File "D:\scripts\py\lib\site-packages\urllib3\connection.py", line 172, in _new_conn
    self, "Failed to establish a new connection: %s" % e
urllib3.exceptions.NewConnectionError: <urllib3.connection.HTTPSConnection object at 0x00000254E44F76D8>: Failed to establish a new connection: [WinError 10060] A connection attempt failed because the connected party did not properly respond after a period of time, or established connection failed because connected host has failed to respond

During handling of the above exception, another exception occurred:

Traceback (most recent call last):
  File "D:\scripts\py\lib\site-packages\requests\adapters.py", line 449, in send
    timeout=timeout
  File "D:\scripts\py\lib\site-packages\urllib3\connectionpool.py", line 725, in urlopen
    method, url, error=e, _pool=self, _stacktrace=sys.exc_info()[2]
  File "D:\scripts\py\lib\site-packages\urllib3\util\retry.py", line 439, in increment
    raise MaxRetryError(_pool, url, error or ResponseError(cause))
urllib3.exceptions.MaxRetryError: HTTPSConnectionPool(host='10.17.84.221', port=4343): Max retries exceeded with url: /v1/configuration/showcommand?command=show%20clock&UIDARUBA=Y2E3MGIwZDQtZThlYi00ODUxLTkxZTctNzhi (Caused by NewConnectionError('<urllib3.connection.HTTPSConnection object at 0x00000254E44F76D8>: Failed to establish a new connection: [WinError 10060] A connection attempt failed because the connected party did not properly respond after a period of time, or established connection failed because connected host has failed to respond'))

During handling of the above exception, another exception occurred:

Traceback (most recent call last):
  File "D:\scripts\GIT\Aruba_Controller_upgrade\Aruba_Wireless_Upgrade_APP.py", line 87, in get_session
    res = r_session.get(get_clock,verify=False)
  File "D:\scripts\py\lib\site-packages\requests\sessions.py", line 543, in get
    return self.request('GET', url, **kwargs)
  File "D:\scripts\py\lib\site-packages\requests\sessions.py", line 530, in request
    resp = self.send(prep, **send_kwargs)
  File "D:\scripts\py\lib\site-packages\requests\sessions.py", line 643, in send
    r = adapter.send(request, **kwargs)
  File "D:\scripts\py\lib\site-packages\requests\adapters.py", line 516, in send
    raise ConnectionError(e, request=request)
requests.exceptions.ConnectionError: HTTPSConnectionPool(host='10.17.84.221', port=4343): Max retries exceeded with url: /v1/configuration/showcommand?command=show%20clock&UIDARUBA=Y2E3MGIwZDQtZThlYi00ODUxLTkxZTctNzhi (Caused by NewConnectionError('<urllib3.connection.HTTPSConnection object at 0x00000254E44F76D8>: Failed to establish a new connection: [WinError 10060] A connection attempt failed because the connected party did not properly respond after a period of time, or established connection failed because connected host has failed to respond'))
2020-10-29 14:01:54,898 > ERROR > ERROR:Login error : 10.17.84.221:4343
2020-10-29 14:01:55,146 > DEBUG > ERROR:Login error : 10.17.84.221:4343
2020-10-29 14:01:55,163 > ERROR > Login error:10.17.84.221:4343 
Traceback (most recent call last):
  File "D:\scripts\py\lib\site-packages\urllib3\connection.py", line 160, in _new_conn
    (self._dns_host, self.port), self.timeout, **extra_kw
  File "D:\scripts\py\lib\site-packages\urllib3\util\connection.py", line 84, in create_connection
    raise err
  File "D:\scripts\py\lib\site-packages\urllib3\util\connection.py", line 74, in create_connection
    sock.connect(sa)
TimeoutError: [WinError 10060] A connection attempt failed because the connected party did not properly respond after a period of time, or established connection failed because connected host has failed to respond

During handling of the above exception, another exception occurred:

Traceback (most recent call last):
  File "D:\scripts\py\lib\site-packages\urllib3\connectionpool.py", line 677, in urlopen
    chunked=chunked,
  File "D:\scripts\py\lib\site-packages\urllib3\connectionpool.py", line 381, in _make_request
    self._validate_conn(conn)
  File "D:\scripts\py\lib\site-packages\urllib3\connectionpool.py", line 976, in _validate_conn
    conn.connect()
  File "D:\scripts\py\lib\site-packages\urllib3\connection.py", line 308, in connect
    conn = self._new_conn()
  File "D:\scripts\py\lib\site-packages\urllib3\connection.py", line 172, in _new_conn
    self, "Failed to establish a new connection: %s" % e
urllib3.exceptions.NewConnectionError: <urllib3.connection.HTTPSConnection object at 0x00000254E34D36D8>: Failed to establish a new connection: [WinError 10060] A connection attempt failed because the connected party did not properly respond after a period of time, or established connection failed because connected host has failed to respond

During handling of the above exception, another exception occurred:

Traceback (most recent call last):
  File "D:\scripts\py\lib\site-packages\requests\adapters.py", line 449, in send
    timeout=timeout
  File "D:\scripts\py\lib\site-packages\urllib3\connectionpool.py", line 725, in urlopen
    method, url, error=e, _pool=self, _stacktrace=sys.exc_info()[2]
  File "D:\scripts\py\lib\site-packages\urllib3\util\retry.py", line 439, in increment
    raise MaxRetryError(_pool, url, error or ResponseError(cause))
urllib3.exceptions.MaxRetryError: HTTPSConnectionPool(host='10.17.84.221', port=4343): Max retries exceeded with url: /v1/api/login (Caused by NewConnectionError('<urllib3.connection.HTTPSConnection object at 0x00000254E34D36D8>: Failed to establish a new connection: [WinError 10060] A connection attempt failed because the connected party did not properly respond after a period of time, or established connection failed because connected host has failed to respond'))

During handling of the above exception, another exception occurred:

Traceback (most recent call last):
  File "D:\scripts\GIT\Aruba_Controller_upgrade\Aruba_Wireless_Upgrade_APP.py", line 105, in get_session
    res = r_session.post(login_url, data = login_post,verify=False)
  File "D:\scripts\py\lib\site-packages\requests\sessions.py", line 578, in post
    return self.request('POST', url, data=data, json=json, **kwargs)
  File "D:\scripts\py\lib\site-packages\requests\sessions.py", line 530, in request
    resp = self.send(prep, **send_kwargs)
  File "D:\scripts\py\lib\site-packages\requests\sessions.py", line 643, in send
    r = adapter.send(request, **kwargs)
  File "D:\scripts\py\lib\site-packages\requests\adapters.py", line 516, in send
    raise ConnectionError(e, request=request)
requests.exceptions.ConnectionError: HTTPSConnectionPool(host='10.17.84.221', port=4343): Max retries exceeded with url: /v1/api/login (Caused by NewConnectionError('<urllib3.connection.HTTPSConnection object at 0x00000254E34D36D8>: Failed to establish a new connection: [WinError 10060] A connection attempt failed because the connected party did not properly respond after a period of time, or established connection failed because connected host has failed to respond'))
2020-10-29 14:01:55,179 > INFO > INFO:=>(MD) NaaS-VMC-1-10.17.84.221:4343 8.6.0.5:75979 : NEW IMAGE UPGRADE SUCCESS
2020-10-29 14:04:47,438 > INFO > yes
2020-10-29 14:04:47,438 > INFO > INFO:Starting postcheck
2020-10-29 14:04:47,486 > INFO > INFO:Executing Postcheck
2020-10-29 14:04:52,565 > INFO > INFO:Login Success => 10.17.84.220:4343
2020-10-29 14:04:59,644 > INFO > INFO:Login Success => 10.17.84.221:4343
2020-10-29 14:05:02,486 > INFO > INFO:Session Valid : 10.17.84.220:4343
2020-10-29 14:05:04,485 > INFO > INFO:Session Valid : 10.17.84.221:4343
2020-10-29 14:05:06,640 > INFO > INFO:Session Valid : 10.17.84.220:4343
2020-10-29 14:05:09,468 > INFO > INFO:Session Valid : 10.17.84.221:4343
2020-10-29 14:05:12,249 > INFO > INFO:Session Valid : 10.17.84.220:4343
2020-10-29 14:05:13,726 > INFO > INFO:Session Valid : 10.17.84.221:4343
2020-10-29 14:05:14,627 > INFO > INFO:POSTCHECK started for : (MM) NaaS-MM-1:10.17.84.220:4343
2020-10-29 14:05:15,314 > INFO > INFO:Session Valid : 10.17.84.220:4343
2020-10-29 14:05:15,370 > INFO > INFO:Executing NaaS-MM-1 - 10.17.84.220:4343 => show clock
2020-10-29 14:05:16,044 > INFO > INFO:Executing NaaS-MM-1 - 10.17.84.220:4343 => show version
2020-10-29 14:05:16,770 > INFO > INFO:Executing NaaS-MM-1 - 10.17.84.220:4343 => show image version
2020-10-29 14:05:17,461 > INFO > INFO:Executing NaaS-MM-1 - 10.17.84.220:4343 => show storage
2020-10-29 14:05:18,155 > INFO > INFO:Executing NaaS-MM-1 - 10.17.84.220:4343 => show cpuload
2020-10-29 14:05:18,862 > INFO > INFO:Executing NaaS-MM-1 - 10.17.84.220:4343 => show memory
2020-10-29 14:05:19,546 > INFO > INFO:Executing NaaS-MM-1 - 10.17.84.220:4343 => show boot
2020-10-29 14:05:20,278 > INFO > INFO:Executing NaaS-MM-1 - 10.17.84.220:4343 => show switches
2020-10-29 14:05:21,048 > INFO > INFO:Executing NaaS-MM-1 - 10.17.84.220:4343 => show switchinfo
2020-10-29 14:05:21,778 > INFO > INFO:Executing NaaS-MM-1 - 10.17.84.220:4343 => show boot history
2020-10-29 14:05:22,898 > INFO > INFO:Executing NaaS-MM-1 - 10.17.84.220:4343 => show crypto ipsec sa
2020-10-29 14:05:23,568 > INFO > INFO:Executing NaaS-MM-1 - 10.17.84.220:4343 => show master-redundancy
2020-10-29 14:05:24,257 > INFO > INFO:Executing NaaS-MM-1 - 10.17.84.220:4343 => show database synchronize
2020-10-29 14:05:24,925 > INFO > INFO:Executing NaaS-MM-1 - 10.17.84.220:4343 => show license
2020-10-29 14:05:25,659 > INFO > INFO:Executing NaaS-MM-1 - 10.17.84.220:4343 => show running-config
2020-10-29 14:05:26,739 > INFO > INFO:POSTCHECK started for : (MD) NaaS-VMC-1:10.17.84.221:4343
2020-10-29 14:05:27,391 > INFO > INFO:Session Valid : 10.17.84.221:4343
2020-10-29 14:05:27,456 > INFO > INFO:Executing NaaS-VMC-1 - 10.17.84.221:4343 => show clock
2020-10-29 14:05:28,117 > INFO > INFO:Executing NaaS-VMC-1 - 10.17.84.221:4343 => show version
2020-10-29 14:05:28,974 > INFO > INFO:Executing NaaS-VMC-1 - 10.17.84.221:4343 => show image version
2020-10-29 14:05:29,697 > INFO > INFO:Executing NaaS-VMC-1 - 10.17.84.221:4343 => show storage
2020-10-29 14:05:30,565 > INFO > INFO:Executing NaaS-VMC-1 - 10.17.84.221:4343 => show cpuload
2020-10-29 14:05:31,489 > INFO > INFO:Executing NaaS-VMC-1 - 10.17.84.221:4343 => show memory
2020-10-29 14:05:32,337 > INFO > INFO:Executing NaaS-VMC-1 - 10.17.84.221:4343 => show boot
2020-10-29 14:05:33,132 > INFO > INFO:Executing NaaS-VMC-1 - 10.17.84.221:4343 => show switches
2020-10-29 14:05:33,994 > INFO > INFO:Executing NaaS-VMC-1 - 10.17.84.221:4343 => show switchinfo
2020-10-29 14:05:34,901 > INFO > INFO:Executing NaaS-VMC-1 - 10.17.84.221:4343 => show boot history
2020-10-29 14:05:35,891 > INFO > INFO:Executing NaaS-VMC-1 - 10.17.84.221:4343 => show user
2020-10-29 14:05:36,842 > INFO > INFO:Executing NaaS-VMC-1 - 10.17.84.221:4343 => show ap database long
2020-10-29 14:05:37,827 > INFO > INFO:Executing NaaS-VMC-1 - 10.17.84.221:4343 => show ap bss-table
2020-10-29 14:05:38,887 > INFO > INFO:Executing NaaS-VMC-1 - 10.17.84.221:4343 => show ap essid
2020-10-29 14:05:39,915 > INFO > INFO:Executing NaaS-VMC-1 - 10.17.84.221:4343 => show ap active counters
2020-10-29 14:05:40,765 > INFO > INFO:Executing NaaS-VMC-1 - 10.17.84.221:4343 => show ap debug counters
2020-10-29 14:05:41,570 > INFO > INFO:Executing NaaS-VMC-1 - 10.17.84.221:4343 => show lc-cluster group-membership
2020-10-29 14:05:42,331 > INFO > INFO:Executing NaaS-VMC-1 - 10.17.84.221:4343 => show switches
2020-10-29 14:05:43,252 > INFO > INFO:Executing NaaS-VMC-1 - 10.17.84.221:4343 => show license
2020-10-29 14:05:44,263 > INFO > INFO:Executing NaaS-VMC-1 - 10.17.84.221:4343 => show running-config
2020-10-29 14:05:45,680 > INFO > INFO:Executing NaaS-VMC-1 - 10.17.84.221:4343 => show boot
2020-10-29 14:05:46,678 > INFO > INFO:Executing NaaS-VMC-1 - 10.17.84.221:4343 => show version
2020-10-29 14:05:47,513 > INFO > INFO:Postcheck Completed
2020-10-29 14:05:47,796 > INFO > INFO:==== Completed ====
