2020-09-12 16:51:15,942 > INFO > JOBNAME:1599909675_923374
2020-09-12 16:51:15,942 > INFO > CONFIG FILE:D:\scripts\GIT\Aruba_Controller_upgrade\conf_files\LAB WIRELESS UPGRADE
2020-09-12 16:51:15,980 > INFO > Starting Job
2020-09-12 16:51:15,995 > INFO > INFO:Running: 1599909675_923374 Type:precheck
2020-09-12 16:51:16,010 > INFO > INFO:Starting Configuration LAB WIRELESS UPGRADE Validation
2020-09-12 16:51:16,076 > INFO > Inserting upgrade list to upgrade.db
2020-09-12 16:51:22,543 > INFO > yes
2020-09-12 16:51:22,543 > INFO > INFO:Starting precheck
2020-09-12 16:51:22,571 > INFO > INFO:Executing Precheck
2020-09-12 16:51:22,600 > INFO > INFO:Precheck started for : (MM) NaaS-MM-1:10.17.84.220:4343
2020-09-12 16:51:29,818 > INFO > INFO:Login Success => 10.17.84.220:4343
2020-09-12 16:51:29,858 > INFO > INFO:Executing NaaS-MM-1 - 10.17.84.220:4343 => show clock
2020-09-12 16:51:32,555 > INFO > INFO:Executing NaaS-MM-1 - 10.17.84.220:4343 => show version
2020-09-12 16:51:49,139 > INFO > INFO:Executing NaaS-MM-1 - 10.17.84.220:4343 => show image version
2020-09-12 16:51:53,152 > INFO > INFO:Executing NaaS-MM-1 - 10.17.84.220:4343 => show storage
2020-09-12 16:51:55,083 > INFO > INFO:Executing NaaS-MM-1 - 10.17.84.220:4343 => show cpuload
2020-09-12 16:51:56,096 > INFO > INFO:Executing NaaS-MM-1 - 10.17.84.220:4343 => show memory
2020-09-12 16:51:56,913 > INFO > INFO:Executing NaaS-MM-1 - 10.17.84.220:4343 => show boot
2020-09-12 16:51:58,028 > INFO > INFO:Executing NaaS-MM-1 - 10.17.84.220:4343 => show switches
2020-09-12 16:52:00,194 > INFO > INFO:Executing NaaS-MM-1 - 10.17.84.220:4343 => show switchinfo
2020-09-12 16:52:04,095 > INFO > INFO:Executing NaaS-MM-1 - 10.17.84.220:4343 => show boot history
2020-09-12 16:52:23,432 > INFO > INFO:Executing NaaS-MM-1 - 10.17.84.220:4343 => show crypto ipsec sa
2020-09-12 16:52:23,926 > ERROR > Error host pre_post_check
Traceback (most recent call last):
  File "d:\scripts\py\lib\site-packages\urllib3\connectionpool.py", line 677, in urlopen
    chunked=chunked,
  File "d:\scripts\py\lib\site-packages\urllib3\connectionpool.py", line 426, in _make_request
    six.raise_from(e, None)
  File "<string>", line 3, in raise_from
  File "d:\scripts\py\lib\site-packages\urllib3\connectionpool.py", line 421, in _make_request
    httplib_response = conn.getresponse()
  File "d:\scripts\py\lib\http\client.py", line 1321, in getresponse
    response.begin()
  File "d:\scripts\py\lib\http\client.py", line 296, in begin
    version, status, reason = self._read_status()
  File "d:\scripts\py\lib\http\client.py", line 265, in _read_status
    raise RemoteDisconnected("Remote end closed connection without"
http.client.RemoteDisconnected: Remote end closed connection without response

During handling of the above exception, another exception occurred:

Traceback (most recent call last):
  File "d:\scripts\py\lib\site-packages\requests\adapters.py", line 449, in send
    timeout=timeout
  File "d:\scripts\py\lib\site-packages\urllib3\connectionpool.py", line 725, in urlopen
    method, url, error=e, _pool=self, _stacktrace=sys.exc_info()[2]
  File "d:\scripts\py\lib\site-packages\urllib3\util\retry.py", line 403, in increment
    raise six.reraise(type(error), error, _stacktrace)
  File "d:\scripts\py\lib\site-packages\urllib3\packages\six.py", line 734, in reraise
    raise value.with_traceback(tb)
  File "d:\scripts\py\lib\site-packages\urllib3\connectionpool.py", line 677, in urlopen
    chunked=chunked,
  File "d:\scripts\py\lib\site-packages\urllib3\connectionpool.py", line 426, in _make_request
    six.raise_from(e, None)
  File "<string>", line 3, in raise_from
  File "d:\scripts\py\lib\site-packages\urllib3\connectionpool.py", line 421, in _make_request
    httplib_response = conn.getresponse()
  File "d:\scripts\py\lib\http\client.py", line 1321, in getresponse
    response.begin()
  File "d:\scripts\py\lib\http\client.py", line 296, in begin
    version, status, reason = self._read_status()
  File "d:\scripts\py\lib\http\client.py", line 265, in _read_status
    raise RemoteDisconnected("Remote end closed connection without"
urllib3.exceptions.ProtocolError: ('Connection aborted.', RemoteDisconnected('Remote end closed connection without response'))

During handling of the above exception, another exception occurred:

Traceback (most recent call last):
  File "D:\scripts\GIT\Aruba_Controller_upgrade\Aruba_Wireless_Upgrade_APP.py", line 289, in Pre_Post_check
    res = session.get(req_url,verify=False)
  File "d:\scripts\py\lib\site-packages\requests\sessions.py", line 543, in get
    return self.request('GET', url, **kwargs)
  File "d:\scripts\py\lib\site-packages\requests\sessions.py", line 530, in request
    resp = self.send(prep, **send_kwargs)
  File "d:\scripts\py\lib\site-packages\requests\sessions.py", line 643, in send
    r = adapter.send(request, **kwargs)
  File "d:\scripts\py\lib\site-packages\requests\adapters.py", line 498, in send
    raise ConnectionError(err, request=request)
requests.exceptions.ConnectionError: ('Connection aborted.', RemoteDisconnected('Remote end closed connection without response'))
2020-09-12 16:52:24,044 > INFO > INFO:Precheck started for : (MD) NaaS-VMC-1:10.17.84.221:4343
2020-09-12 16:52:31,039 > INFO > INFO:Login Success => 10.17.84.221:4343
2020-09-12 16:52:31,089 > INFO > INFO:Executing NaaS-VMC-1 - 10.17.84.221:4343 => show clock
2020-09-12 16:52:41,332 > ERROR > Error host pre_post_check
Traceback (most recent call last):
  File "d:\scripts\py\lib\site-packages\urllib3\connectionpool.py", line 677, in urlopen
    chunked=chunked,
  File "d:\scripts\py\lib\site-packages\urllib3\connectionpool.py", line 426, in _make_request
    six.raise_from(e, None)
  File "<string>", line 3, in raise_from
  File "d:\scripts\py\lib\site-packages\urllib3\connectionpool.py", line 421, in _make_request
    httplib_response = conn.getresponse()
  File "d:\scripts\py\lib\http\client.py", line 1321, in getresponse
    response.begin()
  File "d:\scripts\py\lib\http\client.py", line 296, in begin
    version, status, reason = self._read_status()
  File "d:\scripts\py\lib\http\client.py", line 265, in _read_status
    raise RemoteDisconnected("Remote end closed connection without"
http.client.RemoteDisconnected: Remote end closed connection without response

During handling of the above exception, another exception occurred:

Traceback (most recent call last):
  File "d:\scripts\py\lib\site-packages\requests\adapters.py", line 449, in send
    timeout=timeout
  File "d:\scripts\py\lib\site-packages\urllib3\connectionpool.py", line 725, in urlopen
    method, url, error=e, _pool=self, _stacktrace=sys.exc_info()[2]
  File "d:\scripts\py\lib\site-packages\urllib3\util\retry.py", line 403, in increment
    raise six.reraise(type(error), error, _stacktrace)
  File "d:\scripts\py\lib\site-packages\urllib3\packages\six.py", line 734, in reraise
    raise value.with_traceback(tb)
  File "d:\scripts\py\lib\site-packages\urllib3\connectionpool.py", line 677, in urlopen
    chunked=chunked,
  File "d:\scripts\py\lib\site-packages\urllib3\connectionpool.py", line 426, in _make_request
    six.raise_from(e, None)
  File "<string>", line 3, in raise_from
  File "d:\scripts\py\lib\site-packages\urllib3\connectionpool.py", line 421, in _make_request
    httplib_response = conn.getresponse()
  File "d:\scripts\py\lib\http\client.py", line 1321, in getresponse
    response.begin()
  File "d:\scripts\py\lib\http\client.py", line 296, in begin
    version, status, reason = self._read_status()
  File "d:\scripts\py\lib\http\client.py", line 265, in _read_status
    raise RemoteDisconnected("Remote end closed connection without"
urllib3.exceptions.ProtocolError: ('Connection aborted.', RemoteDisconnected('Remote end closed connection without response'))

During handling of the above exception, another exception occurred:

Traceback (most recent call last):
  File "D:\scripts\GIT\Aruba_Controller_upgrade\Aruba_Wireless_Upgrade_APP.py", line 289, in Pre_Post_check
    res = session.get(req_url,verify=False)
  File "d:\scripts\py\lib\site-packages\requests\sessions.py", line 543, in get
    return self.request('GET', url, **kwargs)
  File "d:\scripts\py\lib\site-packages\requests\sessions.py", line 530, in request
    resp = self.send(prep, **send_kwargs)
  File "d:\scripts\py\lib\site-packages\requests\sessions.py", line 643, in send
    r = adapter.send(request, **kwargs)
  File "d:\scripts\py\lib\site-packages\requests\adapters.py", line 498, in send
    raise ConnectionError(err, request=request)
requests.exceptions.ConnectionError: ('Connection aborted.', RemoteDisconnected('Remote end closed connection without response'))
2020-09-12 16:52:41,365 > INFO > INFO:Precheck Completed
2020-09-12 16:52:41,393 > INFO > INFO:==== Completed ====
