2020-10-28 11:06:06,182 > INFO > JOBNAME:1603863366_1510873
2020-10-28 11:06:06,184 > INFO > CONFIG FILE:D:\scripts\GIT\Aruba_Controller_upgrade\conf_files\LAB WIRELESS UPGRADE 8.5
2020-10-28 11:06:06,336 > INFO > Starting Job
2020-10-28 11:06:06,369 > INFO > INFO:Running: 1603863366_1510873 Type:P,r,e,c,h,e,c,k
2020-10-28 11:06:06,402 > INFO > INFO:Starting Configuration LAB WIRELESS UPGRADE 8.5 Validation
2020-10-28 11:06:06,449 > INFO > Inserting upgrade list to upgrade.db
2020-10-28 11:06:08,549 > INFO > yes
2020-10-28 11:06:08,552 > INFO > INFO:Starting precheck
2020-10-28 11:06:08,588 > INFO > INFO:Executing Precheck
2020-10-28 11:06:29,667 > ERROR > ERROR:Login error : 10.17.84.220:4343
2020-10-28 11:06:29,694 > DEBUG > ERROR:Login error : 10.17.84.220:4343
2020-10-28 11:06:29,710 > ERROR > Login error:10.17.84.220:4343 
Traceback (most recent call last):
  File "D:\scripts\py\lib\site-packages\urllib3\connection.py", line 160, in _new_conn
    (self._dns_host, self.port), self.timeout, **extra_kw
  File "D:\scripts\py\lib\site-packages\urllib3\util\connection.py", line 84, in create_connection
    raise err
  File "D:\scripts\py\lib\site-packages\urllib3\util\connection.py", line 74, in create_connection
    sock.connect(sa)
TimeoutError: [WinError 10060] A connection attempt failed because the connected party did not properly respond after a period of time, or established connection failed because connected host has failed to respond

During handling of the above exception, another exception occurred:

Traceback (most recent call last):
  File "D:\scripts\py\lib\site-packages\urllib3\connectionpool.py", line 677, in urlopen
    chunked=chunked,
  File "D:\scripts\py\lib\site-packages\urllib3\connectionpool.py", line 381, in _make_request
    self._validate_conn(conn)
  File "D:\scripts\py\lib\site-packages\urllib3\connectionpool.py", line 976, in _validate_conn
    conn.connect()
  File "D:\scripts\py\lib\site-packages\urllib3\connection.py", line 308, in connect
    conn = self._new_conn()
  File "D:\scripts\py\lib\site-packages\urllib3\connection.py", line 172, in _new_conn
    self, "Failed to establish a new connection: %s" % e
urllib3.exceptions.NewConnectionError: <urllib3.connection.HTTPSConnection object at 0x000002977074FEB8>: Failed to establish a new connection: [WinError 10060] A connection attempt failed because the connected party did not properly respond after a period of time, or established connection failed because connected host has failed to respond

During handling of the above exception, another exception occurred:

Traceback (most recent call last):
  File "D:\scripts\py\lib\site-packages\requests\adapters.py", line 449, in send
    timeout=timeout
  File "D:\scripts\py\lib\site-packages\urllib3\connectionpool.py", line 725, in urlopen
    method, url, error=e, _pool=self, _stacktrace=sys.exc_info()[2]
  File "D:\scripts\py\lib\site-packages\urllib3\util\retry.py", line 439, in increment
    raise MaxRetryError(_pool, url, error or ResponseError(cause))
urllib3.exceptions.MaxRetryError: HTTPSConnectionPool(host='10.17.84.220', port=4343): Max retries exceeded with url: /v1/api/login (Caused by NewConnectionError('<urllib3.connection.HTTPSConnection object at 0x000002977074FEB8>: Failed to establish a new connection: [WinError 10060] A connection attempt failed because the connected party did not properly respond after a period of time, or established connection failed because connected host has failed to respond'))

During handling of the above exception, another exception occurred:

Traceback (most recent call last):
  File "D:\scripts\GIT\Aruba_Controller_upgrade\Aruba_Wireless_Upgrade_APP.py", line 105, in get_session
    res = r_session.post(login_url, data = login_post,verify=False)
  File "D:\scripts\py\lib\site-packages\requests\sessions.py", line 578, in post
    return self.request('POST', url, data=data, json=json, **kwargs)
  File "D:\scripts\py\lib\site-packages\requests\sessions.py", line 530, in request
    resp = self.send(prep, **send_kwargs)
  File "D:\scripts\py\lib\site-packages\requests\sessions.py", line 643, in send
    r = adapter.send(request, **kwargs)
  File "D:\scripts\py\lib\site-packages\requests\adapters.py", line 516, in send
    raise ConnectionError(e, request=request)
requests.exceptions.ConnectionError: HTTPSConnectionPool(host='10.17.84.220', port=4343): Max retries exceeded with url: /v1/api/login (Caused by NewConnectionError('<urllib3.connection.HTTPSConnection object at 0x000002977074FEB8>: Failed to establish a new connection: [WinError 10060] A connection attempt failed because the connected party did not properly respond after a period of time, or established connection failed because connected host has failed to respond'))
2020-10-28 11:06:50,730 > ERROR > ERROR:Login error : 10.17.84.221:4343
2020-10-28 11:06:50,767 > DEBUG > ERROR:Login error : 10.17.84.221:4343
2020-10-28 11:06:50,783 > ERROR > Login error:10.17.84.221:4343 
Traceback (most recent call last):
  File "D:\scripts\py\lib\site-packages\urllib3\connection.py", line 160, in _new_conn
    (self._dns_host, self.port), self.timeout, **extra_kw
  File "D:\scripts\py\lib\site-packages\urllib3\util\connection.py", line 84, in create_connection
    raise err
  File "D:\scripts\py\lib\site-packages\urllib3\util\connection.py", line 74, in create_connection
    sock.connect(sa)
TimeoutError: [WinError 10060] A connection attempt failed because the connected party did not properly respond after a period of time, or established connection failed because connected host has failed to respond

During handling of the above exception, another exception occurred:

Traceback (most recent call last):
  File "D:\scripts\py\lib\site-packages\urllib3\connectionpool.py", line 677, in urlopen
    chunked=chunked,
  File "D:\scripts\py\lib\site-packages\urllib3\connectionpool.py", line 381, in _make_request
    self._validate_conn(conn)
  File "D:\scripts\py\lib\site-packages\urllib3\connectionpool.py", line 976, in _validate_conn
    conn.connect()
  File "D:\scripts\py\lib\site-packages\urllib3\connection.py", line 308, in connect
    conn = self._new_conn()
  File "D:\scripts\py\lib\site-packages\urllib3\connection.py", line 172, in _new_conn
    self, "Failed to establish a new connection: %s" % e
urllib3.exceptions.NewConnectionError: <urllib3.connection.HTTPSConnection object at 0x00000297706F04A8>: Failed to establish a new connection: [WinError 10060] A connection attempt failed because the connected party did not properly respond after a period of time, or established connection failed because connected host has failed to respond

During handling of the above exception, another exception occurred:

Traceback (most recent call last):
  File "D:\scripts\py\lib\site-packages\requests\adapters.py", line 449, in send
    timeout=timeout
  File "D:\scripts\py\lib\site-packages\urllib3\connectionpool.py", line 725, in urlopen
    method, url, error=e, _pool=self, _stacktrace=sys.exc_info()[2]
  File "D:\scripts\py\lib\site-packages\urllib3\util\retry.py", line 439, in increment
    raise MaxRetryError(_pool, url, error or ResponseError(cause))
urllib3.exceptions.MaxRetryError: HTTPSConnectionPool(host='10.17.84.221', port=4343): Max retries exceeded with url: /v1/api/login (Caused by NewConnectionError('<urllib3.connection.HTTPSConnection object at 0x00000297706F04A8>: Failed to establish a new connection: [WinError 10060] A connection attempt failed because the connected party did not properly respond after a period of time, or established connection failed because connected host has failed to respond'))

During handling of the above exception, another exception occurred:

Traceback (most recent call last):
  File "D:\scripts\GIT\Aruba_Controller_upgrade\Aruba_Wireless_Upgrade_APP.py", line 105, in get_session
    res = r_session.post(login_url, data = login_post,verify=False)
  File "D:\scripts\py\lib\site-packages\requests\sessions.py", line 578, in post
    return self.request('POST', url, data=data, json=json, **kwargs)
  File "D:\scripts\py\lib\site-packages\requests\sessions.py", line 530, in request
    resp = self.send(prep, **send_kwargs)
  File "D:\scripts\py\lib\site-packages\requests\sessions.py", line 643, in send
    r = adapter.send(request, **kwargs)
  File "D:\scripts\py\lib\site-packages\requests\adapters.py", line 516, in send
    raise ConnectionError(e, request=request)
requests.exceptions.ConnectionError: HTTPSConnectionPool(host='10.17.84.221', port=4343): Max retries exceeded with url: /v1/api/login (Caused by NewConnectionError('<urllib3.connection.HTTPSConnection object at 0x00000297706F04A8>: Failed to establish a new connection: [WinError 10060] A connection attempt failed because the connected party did not properly respond after a period of time, or established connection failed because connected host has failed to respond'))
2020-10-28 11:06:50,825 > INFO > INFO:Precheck Completed
2020-10-28 11:07:26,938 > INFO > INFO:==== Completed ====
2020-10-28 11:23:05,020 > INFO > JOBNAME:1603864385_000034
2020-10-28 11:23:05,023 > INFO > CONFIG FILE:D:\scripts\GIT\Aruba_Controller_upgrade\conf_files\LAB WIRELESS UPGRADE 8.5
2020-10-28 11:23:05,100 > INFO > Starting Job
2020-10-28 11:23:05,113 > INFO > INFO:Running: 1603864385_000034 Type:P,r,e,c,h,e,c,k
2020-10-28 11:23:05,128 > INFO > INFO:Starting Configuration LAB WIRELESS UPGRADE 8.5 Validation
2020-10-28 11:23:05,156 > INFO > Inserting upgrade list to upgrade.db
2020-10-28 11:23:09,201 > INFO > yes
2020-10-28 11:23:09,202 > INFO > INFO:Starting precheck
2020-10-28 11:23:09,218 > INFO > INFO:Executing Precheck
2020-10-28 11:23:11,819 > INFO > INFO:Login Success => 10.17.84.220:4343
2020-10-28 11:23:20,193 > INFO > INFO:Login Success => 10.17.84.221:4343
2020-10-28 11:23:23,596 > INFO > INFO:Session Valid : 10.17.84.220:4343
2020-10-28 11:23:25,615 > INFO > INFO:Session Valid : 10.17.84.221:4343
2020-10-28 11:23:28,115 > INFO > INFO:Session Valid : 10.17.84.220:4343
2020-10-28 11:23:30,781 > INFO > INFO:Session Valid : 10.17.84.221:4343
2020-10-28 11:23:33,442 > INFO > INFO:Session Valid : 10.17.84.220:4343
2020-10-28 11:23:34,977 > INFO > INFO:Session Valid : 10.17.84.221:4343
2020-10-28 11:23:35,811 > INFO > INFO:Precheck Completed
2020-10-28 11:24:39,975 > INFO > INFO:==== Completed ====
