2020-08-05 03:10:20,627 > INFO > Starting Aruba Upgrade....
2020-08-05 03:10:44,548 > ERROR > upload_image_tftp
Traceback (most recent call last):
  File "Aruba_Wireless_Upgrade_V3.py", line 513, in upload_image_tftp
    if response.find("SUCCESS") != -1:
TypeError: argument should be integer or bytes-like object, not 'str'
2020-08-05 03:14:10,634 > INFO > Starting Aruba Upgrade....
2020-08-05 03:14:31,112 > ERROR > upload_image_tftp
Traceback (most recent call last):
  File "Aruba_Wireless_Upgrade_V3.py", line 515, in upload_image_tftp
    if response.find("SUCCESS") != -1:
TypeError: argument should be integer or bytes-like object, not 'str'
2020-08-05 03:33:50,533 > INFO > Starting Aruba Upgrade....
2020-08-05 03:51:47,389 > ERROR > upload_image_tftp
Traceback (most recent call last):
  File "Aruba_Wireless_Upgrade_V3.py", line 515, in upload_image_tftp
    if response.find("SUCCESS") != -1:
TypeError: argument should be integer or bytes-like object, not 'str'
2020-08-05 04:07:49,127 > ERROR > upload_image_tftp
Traceback (most recent call last):
  File "Aruba_Wireless_Upgrade_V3.py", line 515, in upload_image_tftp
    if response.find("SUCCESS") != -1:
TypeError: argument should be integer or bytes-like object, not 'str'
2020-08-05 04:57:29,607 > INFO > Starting Aruba Upgrade....
2020-08-05 04:59:00,028 > ERROR > upload_image_tftp
Traceback (most recent call last):
  File "Aruba_Wireless_Upgrade_V3.py", line 515, in upload_image_tftp
    if response.find("SUCCESS") != -1:
TypeError: argument should be integer or bytes-like object, not 'str'
2020-08-05 05:02:01,679 > ERROR > Login error: 
Traceback (most recent call last):
  File "d:\scripts\py\lib\site-packages\urllib3\connectionpool.py", line 677, in urlopen
    chunked=chunked,
  File "d:\scripts\py\lib\site-packages\urllib3\connectionpool.py", line 381, in _make_request
    self._validate_conn(conn)
  File "d:\scripts\py\lib\site-packages\urllib3\connectionpool.py", line 976, in _validate_conn
    conn.connect()
  File "d:\scripts\py\lib\site-packages\urllib3\connection.py", line 370, in connect
    ssl_context=context,
  File "d:\scripts\py\lib\site-packages\urllib3\util\ssl_.py", line 390, in ssl_wrap_socket
    return context.wrap_socket(sock)
  File "d:\scripts\py\lib\ssl.py", line 412, in wrap_socket
    session=session
  File "d:\scripts\py\lib\ssl.py", line 850, in _create
    self.do_handshake()
  File "d:\scripts\py\lib\ssl.py", line 1108, in do_handshake
    self._sslobj.do_handshake()
ConnectionResetError: [WinError 10054] An existing connection was forcibly closed by the remote host

During handling of the above exception, another exception occurred:

Traceback (most recent call last):
  File "d:\scripts\py\lib\site-packages\requests\adapters.py", line 449, in send
    timeout=timeout
  File "d:\scripts\py\lib\site-packages\urllib3\connectionpool.py", line 725, in urlopen
    method, url, error=e, _pool=self, _stacktrace=sys.exc_info()[2]
  File "d:\scripts\py\lib\site-packages\urllib3\util\retry.py", line 403, in increment
    raise six.reraise(type(error), error, _stacktrace)
  File "d:\scripts\py\lib\site-packages\urllib3\packages\six.py", line 734, in reraise
    raise value.with_traceback(tb)
  File "d:\scripts\py\lib\site-packages\urllib3\connectionpool.py", line 677, in urlopen
    chunked=chunked,
  File "d:\scripts\py\lib\site-packages\urllib3\connectionpool.py", line 381, in _make_request
    self._validate_conn(conn)
  File "d:\scripts\py\lib\site-packages\urllib3\connectionpool.py", line 976, in _validate_conn
    conn.connect()
  File "d:\scripts\py\lib\site-packages\urllib3\connection.py", line 370, in connect
    ssl_context=context,
  File "d:\scripts\py\lib\site-packages\urllib3\util\ssl_.py", line 390, in ssl_wrap_socket
    return context.wrap_socket(sock)
  File "d:\scripts\py\lib\ssl.py", line 412, in wrap_socket
    session=session
  File "d:\scripts\py\lib\ssl.py", line 850, in _create
    self.do_handshake()
  File "d:\scripts\py\lib\ssl.py", line 1108, in do_handshake
    self._sslobj.do_handshake()
urllib3.exceptions.ProtocolError: ('Connection aborted.', ConnectionResetError(10054, 'An existing connection was forcibly closed by the remote host', None, 10054, None))

During handling of the above exception, another exception occurred:

Traceback (most recent call last):
  File "Aruba_Wireless_Upgrade_V3.py", line 174, in login
    res = r_session.post(login_url, data = login_post,verify=False)
  File "d:\scripts\py\lib\site-packages\requests\sessions.py", line 578, in post
    return self.request('POST', url, data=data, json=json, **kwargs)
  File "d:\scripts\py\lib\site-packages\requests\sessions.py", line 530, in request
    resp = self.send(prep, **send_kwargs)
  File "d:\scripts\py\lib\site-packages\requests\sessions.py", line 643, in send
    r = adapter.send(request, **kwargs)
  File "d:\scripts\py\lib\site-packages\requests\adapters.py", line 498, in send
    raise ConnectionError(err, request=request)
requests.exceptions.ConnectionError: ('Connection aborted.', ConnectionResetError(10054, 'An existing connection was forcibly closed by the remote host', None, 10054, None))
2020-08-05 05:02:25,723 > ERROR > Login error: 
Traceback (most recent call last):
  File "d:\scripts\py\lib\site-packages\urllib3\connection.py", line 160, in _new_conn
    (self._dns_host, self.port), self.timeout, **extra_kw
  File "d:\scripts\py\lib\site-packages\urllib3\util\connection.py", line 84, in create_connection
    raise err
  File "d:\scripts\py\lib\site-packages\urllib3\util\connection.py", line 74, in create_connection
    sock.connect(sa)
TimeoutError: [WinError 10060] A connection attempt failed because the connected party did not properly respond after a period of time, or established connection failed because connected host has failed to respond

During handling of the above exception, another exception occurred:

Traceback (most recent call last):
  File "d:\scripts\py\lib\site-packages\urllib3\connectionpool.py", line 677, in urlopen
    chunked=chunked,
  File "d:\scripts\py\lib\site-packages\urllib3\connectionpool.py", line 381, in _make_request
    self._validate_conn(conn)
  File "d:\scripts\py\lib\site-packages\urllib3\connectionpool.py", line 976, in _validate_conn
    conn.connect()
  File "d:\scripts\py\lib\site-packages\urllib3\connection.py", line 308, in connect
    conn = self._new_conn()
  File "d:\scripts\py\lib\site-packages\urllib3\connection.py", line 172, in _new_conn
    self, "Failed to establish a new connection: %s" % e
urllib3.exceptions.NewConnectionError: <urllib3.connection.HTTPSConnection object at 0x000001F5F11DC4E0>: Failed to establish a new connection: [WinError 10060] A connection attempt failed because the connected party did not properly respond after a period of time, or established connection failed because connected host has failed to respond

During handling of the above exception, another exception occurred:

Traceback (most recent call last):
  File "d:\scripts\py\lib\site-packages\requests\adapters.py", line 449, in send
    timeout=timeout
  File "d:\scripts\py\lib\site-packages\urllib3\connectionpool.py", line 725, in urlopen
    method, url, error=e, _pool=self, _stacktrace=sys.exc_info()[2]
  File "d:\scripts\py\lib\site-packages\urllib3\util\retry.py", line 439, in increment
    raise MaxRetryError(_pool, url, error or ResponseError(cause))
urllib3.exceptions.MaxRetryError: HTTPSConnectionPool(host='10.17.84.221', port=4343): Max retries exceeded with url: /v1/api/login (Caused by NewConnectionError('<urllib3.connection.HTTPSConnection object at 0x000001F5F11DC4E0>: Failed to establish a new connection: [WinError 10060] A connection attempt failed because the connected party did not properly respond after a period of time, or established connection failed because connected host has failed to respond'))

During handling of the above exception, another exception occurred:

Traceback (most recent call last):
  File "Aruba_Wireless_Upgrade_V3.py", line 174, in login
    res = r_session.post(login_url, data = login_post,verify=False)
  File "d:\scripts\py\lib\site-packages\requests\sessions.py", line 578, in post
    return self.request('POST', url, data=data, json=json, **kwargs)
  File "d:\scripts\py\lib\site-packages\requests\sessions.py", line 530, in request
    resp = self.send(prep, **send_kwargs)
  File "d:\scripts\py\lib\site-packages\requests\sessions.py", line 643, in send
    r = adapter.send(request, **kwargs)
  File "d:\scripts\py\lib\site-packages\requests\adapters.py", line 516, in send
    raise ConnectionError(e, request=request)
requests.exceptions.ConnectionError: HTTPSConnectionPool(host='10.17.84.221', port=4343): Max retries exceeded with url: /v1/api/login (Caused by NewConnectionError('<urllib3.connection.HTTPSConnection object at 0x000001F5F11DC4E0>: Failed to establish a new connection: [WinError 10060] A connection attempt failed because the connected party did not properly respond after a period of time, or established connection failed because connected host has failed to respond'))
2020-08-05 05:02:49,738 > ERROR > Login error: 
Traceback (most recent call last):
  File "d:\scripts\py\lib\site-packages\urllib3\connection.py", line 160, in _new_conn
    (self._dns_host, self.port), self.timeout, **extra_kw
  File "d:\scripts\py\lib\site-packages\urllib3\util\connection.py", line 84, in create_connection
    raise err
  File "d:\scripts\py\lib\site-packages\urllib3\util\connection.py", line 74, in create_connection
    sock.connect(sa)
TimeoutError: [WinError 10060] A connection attempt failed because the connected party did not properly respond after a period of time, or established connection failed because connected host has failed to respond

During handling of the above exception, another exception occurred:

Traceback (most recent call last):
  File "d:\scripts\py\lib\site-packages\urllib3\connectionpool.py", line 677, in urlopen
    chunked=chunked,
  File "d:\scripts\py\lib\site-packages\urllib3\connectionpool.py", line 381, in _make_request
    self._validate_conn(conn)
  File "d:\scripts\py\lib\site-packages\urllib3\connectionpool.py", line 976, in _validate_conn
    conn.connect()
  File "d:\scripts\py\lib\site-packages\urllib3\connection.py", line 308, in connect
    conn = self._new_conn()
  File "d:\scripts\py\lib\site-packages\urllib3\connection.py", line 172, in _new_conn
    self, "Failed to establish a new connection: %s" % e
urllib3.exceptions.NewConnectionError: <urllib3.connection.HTTPSConnection object at 0x000001F5F11DCB70>: Failed to establish a new connection: [WinError 10060] A connection attempt failed because the connected party did not properly respond after a period of time, or established connection failed because connected host has failed to respond

During handling of the above exception, another exception occurred:

Traceback (most recent call last):
  File "d:\scripts\py\lib\site-packages\requests\adapters.py", line 449, in send
    timeout=timeout
  File "d:\scripts\py\lib\site-packages\urllib3\connectionpool.py", line 725, in urlopen
    method, url, error=e, _pool=self, _stacktrace=sys.exc_info()[2]
  File "d:\scripts\py\lib\site-packages\urllib3\util\retry.py", line 439, in increment
    raise MaxRetryError(_pool, url, error or ResponseError(cause))
urllib3.exceptions.MaxRetryError: HTTPSConnectionPool(host='10.17.84.221', port=4343): Max retries exceeded with url: /v1/api/login (Caused by NewConnectionError('<urllib3.connection.HTTPSConnection object at 0x000001F5F11DCB70>: Failed to establish a new connection: [WinError 10060] A connection attempt failed because the connected party did not properly respond after a period of time, or established connection failed because connected host has failed to respond'))

During handling of the above exception, another exception occurred:

Traceback (most recent call last):
  File "Aruba_Wireless_Upgrade_V3.py", line 174, in login
    res = r_session.post(login_url, data = login_post,verify=False)
  File "d:\scripts\py\lib\site-packages\requests\sessions.py", line 578, in post
    return self.request('POST', url, data=data, json=json, **kwargs)
  File "d:\scripts\py\lib\site-packages\requests\sessions.py", line 530, in request
    resp = self.send(prep, **send_kwargs)
  File "d:\scripts\py\lib\site-packages\requests\sessions.py", line 643, in send
    r = adapter.send(request, **kwargs)
  File "d:\scripts\py\lib\site-packages\requests\adapters.py", line 516, in send
    raise ConnectionError(e, request=request)
requests.exceptions.ConnectionError: HTTPSConnectionPool(host='10.17.84.221', port=4343): Max retries exceeded with url: /v1/api/login (Caused by NewConnectionError('<urllib3.connection.HTTPSConnection object at 0x000001F5F11DCB70>: Failed to establish a new connection: [WinError 10060] A connection attempt failed because the connected party did not properly respond after a period of time, or established connection failed because connected host has failed to respond'))
2020-08-05 05:03:02,399 > ERROR > Login error: 
Traceback (most recent call last):
  File "d:\scripts\py\lib\site-packages\urllib3\connection.py", line 160, in _new_conn
    (self._dns_host, self.port), self.timeout, **extra_kw
  File "d:\scripts\py\lib\site-packages\urllib3\util\connection.py", line 84, in create_connection
    raise err
  File "d:\scripts\py\lib\site-packages\urllib3\util\connection.py", line 74, in create_connection
    sock.connect(sa)
ConnectionRefusedError: [WinError 10061] No connection could be made because the target machine actively refused it

During handling of the above exception, another exception occurred:

Traceback (most recent call last):
  File "d:\scripts\py\lib\site-packages\urllib3\connectionpool.py", line 677, in urlopen
    chunked=chunked,
  File "d:\scripts\py\lib\site-packages\urllib3\connectionpool.py", line 381, in _make_request
    self._validate_conn(conn)
  File "d:\scripts\py\lib\site-packages\urllib3\connectionpool.py", line 976, in _validate_conn
    conn.connect()
  File "d:\scripts\py\lib\site-packages\urllib3\connection.py", line 308, in connect
    conn = self._new_conn()
  File "d:\scripts\py\lib\site-packages\urllib3\connection.py", line 172, in _new_conn
    self, "Failed to establish a new connection: %s" % e
urllib3.exceptions.NewConnectionError: <urllib3.connection.HTTPSConnection object at 0x000001F5F12CE2E8>: Failed to establish a new connection: [WinError 10061] No connection could be made because the target machine actively refused it

During handling of the above exception, another exception occurred:

Traceback (most recent call last):
  File "d:\scripts\py\lib\site-packages\requests\adapters.py", line 449, in send
    timeout=timeout
  File "d:\scripts\py\lib\site-packages\urllib3\connectionpool.py", line 725, in urlopen
    method, url, error=e, _pool=self, _stacktrace=sys.exc_info()[2]
  File "d:\scripts\py\lib\site-packages\urllib3\util\retry.py", line 439, in increment
    raise MaxRetryError(_pool, url, error or ResponseError(cause))
urllib3.exceptions.MaxRetryError: HTTPSConnectionPool(host='10.17.84.221', port=4343): Max retries exceeded with url: /v1/api/login (Caused by NewConnectionError('<urllib3.connection.HTTPSConnection object at 0x000001F5F12CE2E8>: Failed to establish a new connection: [WinError 10061] No connection could be made because the target machine actively refused it'))

During handling of the above exception, another exception occurred:

Traceback (most recent call last):
  File "Aruba_Wireless_Upgrade_V3.py", line 174, in login
    res = r_session.post(login_url, data = login_post,verify=False)
  File "d:\scripts\py\lib\site-packages\requests\sessions.py", line 578, in post
    return self.request('POST', url, data=data, json=json, **kwargs)
  File "d:\scripts\py\lib\site-packages\requests\sessions.py", line 530, in request
    resp = self.send(prep, **send_kwargs)
  File "d:\scripts\py\lib\site-packages\requests\sessions.py", line 643, in send
    r = adapter.send(request, **kwargs)
  File "d:\scripts\py\lib\site-packages\requests\adapters.py", line 516, in send
    raise ConnectionError(e, request=request)
requests.exceptions.ConnectionError: HTTPSConnectionPool(host='10.17.84.221', port=4343): Max retries exceeded with url: /v1/api/login (Caused by NewConnectionError('<urllib3.connection.HTTPSConnection object at 0x000001F5F12CE2E8>: Failed to establish a new connection: [WinError 10061] No connection could be made because the target machine actively refused it'))
2020-08-05 05:03:21,679 > ERROR > Login error: 
Traceback (most recent call last):
  File "d:\scripts\py\lib\site-packages\urllib3\connectionpool.py", line 677, in urlopen
    chunked=chunked,
  File "d:\scripts\py\lib\site-packages\urllib3\connectionpool.py", line 426, in _make_request
    six.raise_from(e, None)
  File "<string>", line 3, in raise_from
  File "d:\scripts\py\lib\site-packages\urllib3\connectionpool.py", line 421, in _make_request
    httplib_response = conn.getresponse()
  File "d:\scripts\py\lib\http\client.py", line 1321, in getresponse
    response.begin()
  File "d:\scripts\py\lib\http\client.py", line 296, in begin
    version, status, reason = self._read_status()
  File "d:\scripts\py\lib\http\client.py", line 257, in _read_status
    line = str(self.fp.readline(_MAXLINE + 1), "iso-8859-1")
  File "d:\scripts\py\lib\socket.py", line 589, in readinto
    return self._sock.recv_into(b)
  File "d:\scripts\py\lib\ssl.py", line 1049, in recv_into
    return self.read(nbytes, buffer)
  File "d:\scripts\py\lib\ssl.py", line 908, in read
    return self._sslobj.read(len, buffer)
ConnectionResetError: [WinError 10054] An existing connection was forcibly closed by the remote host

During handling of the above exception, another exception occurred:

Traceback (most recent call last):
  File "d:\scripts\py\lib\site-packages\requests\adapters.py", line 449, in send
    timeout=timeout
  File "d:\scripts\py\lib\site-packages\urllib3\connectionpool.py", line 725, in urlopen
    method, url, error=e, _pool=self, _stacktrace=sys.exc_info()[2]
  File "d:\scripts\py\lib\site-packages\urllib3\util\retry.py", line 403, in increment
    raise six.reraise(type(error), error, _stacktrace)
  File "d:\scripts\py\lib\site-packages\urllib3\packages\six.py", line 734, in reraise
    raise value.with_traceback(tb)
  File "d:\scripts\py\lib\site-packages\urllib3\connectionpool.py", line 677, in urlopen
    chunked=chunked,
  File "d:\scripts\py\lib\site-packages\urllib3\connectionpool.py", line 426, in _make_request
    six.raise_from(e, None)
  File "<string>", line 3, in raise_from
  File "d:\scripts\py\lib\site-packages\urllib3\connectionpool.py", line 421, in _make_request
    httplib_response = conn.getresponse()
  File "d:\scripts\py\lib\http\client.py", line 1321, in getresponse
    response.begin()
  File "d:\scripts\py\lib\http\client.py", line 296, in begin
    version, status, reason = self._read_status()
  File "d:\scripts\py\lib\http\client.py", line 257, in _read_status
    line = str(self.fp.readline(_MAXLINE + 1), "iso-8859-1")
  File "d:\scripts\py\lib\socket.py", line 589, in readinto
    return self._sock.recv_into(b)
  File "d:\scripts\py\lib\ssl.py", line 1049, in recv_into
    return self.read(nbytes, buffer)
  File "d:\scripts\py\lib\ssl.py", line 908, in read
    return self._sslobj.read(len, buffer)
urllib3.exceptions.ProtocolError: ('Connection aborted.', ConnectionResetError(10054, 'An existing connection was forcibly closed by the remote host', None, 10054, None))

During handling of the above exception, another exception occurred:

Traceback (most recent call last):
  File "Aruba_Wireless_Upgrade_V3.py", line 174, in login
    res = r_session.post(login_url, data = login_post,verify=False)
  File "d:\scripts\py\lib\site-packages\requests\sessions.py", line 578, in post
    return self.request('POST', url, data=data, json=json, **kwargs)
  File "d:\scripts\py\lib\site-packages\requests\sessions.py", line 530, in request
    resp = self.send(prep, **send_kwargs)
  File "d:\scripts\py\lib\site-packages\requests\sessions.py", line 643, in send
    r = adapter.send(request, **kwargs)
  File "d:\scripts\py\lib\site-packages\requests\adapters.py", line 498, in send
    raise ConnectionError(err, request=request)
requests.exceptions.ConnectionError: ('Connection aborted.', ConnectionResetError(10054, 'An existing connection was forcibly closed by the remote host', None, 10054, None))
2020-08-05 05:04:42,765 > INFO > Starting Aruba Upgrade....
2020-08-05 05:08:12,294 > ERROR > AP_IMAGE_PRELOAD POST: 
Traceback (most recent call last):
  File "Aruba_Wireless_Upgrade_V4.py", line 731, in AP_IMAGE_PRELOAD
    self.print(itm)
TypeError: 'PrettyPrinter' object is not callable
2020-08-05 05:08:21,818 > ERROR > AP_IMAGE_PRELOAD POST: 
Traceback (most recent call last):
  File "Aruba_Wireless_Upgrade_V4.py", line 731, in AP_IMAGE_PRELOAD
    self.print(itm)
TypeError: 'PrettyPrinter' object is not callable
2020-08-05 05:08:31,227 > ERROR > AP_IMAGE_PRELOAD POST: 
Traceback (most recent call last):
  File "Aruba_Wireless_Upgrade_V4.py", line 731, in AP_IMAGE_PRELOAD
    self.print(itm)
TypeError: 'PrettyPrinter' object is not callable
2020-08-05 05:08:40,616 > ERROR > AP_IMAGE_PRELOAD POST: 
Traceback (most recent call last):
  File "Aruba_Wireless_Upgrade_V4.py", line 731, in AP_IMAGE_PRELOAD
    self.print(itm)
TypeError: 'PrettyPrinter' object is not callable
2020-08-05 05:10:29,546 > INFO > Starting Aruba Upgrade....
2020-08-05 05:11:52,149 > INFO > Starting Aruba Upgrade....
2020-08-05 05:13:13,681 > ERROR > Login error: 
Traceback (most recent call last):
  File "d:\scripts\py\lib\site-packages\urllib3\connectionpool.py", line 677, in urlopen
    chunked=chunked,
  File "d:\scripts\py\lib\site-packages\urllib3\connectionpool.py", line 381, in _make_request
    self._validate_conn(conn)
  File "d:\scripts\py\lib\site-packages\urllib3\connectionpool.py", line 976, in _validate_conn
    conn.connect()
  File "d:\scripts\py\lib\site-packages\urllib3\connection.py", line 370, in connect
    ssl_context=context,
  File "d:\scripts\py\lib\site-packages\urllib3\util\ssl_.py", line 390, in ssl_wrap_socket
    return context.wrap_socket(sock)
  File "d:\scripts\py\lib\ssl.py", line 412, in wrap_socket
    session=session
  File "d:\scripts\py\lib\ssl.py", line 850, in _create
    self.do_handshake()
  File "d:\scripts\py\lib\ssl.py", line 1108, in do_handshake
    self._sslobj.do_handshake()
ConnectionResetError: [WinError 10054] An existing connection was forcibly closed by the remote host

During handling of the above exception, another exception occurred:

Traceback (most recent call last):
  File "d:\scripts\py\lib\site-packages\requests\adapters.py", line 449, in send
    timeout=timeout
  File "d:\scripts\py\lib\site-packages\urllib3\connectionpool.py", line 725, in urlopen
    method, url, error=e, _pool=self, _stacktrace=sys.exc_info()[2]
  File "d:\scripts\py\lib\site-packages\urllib3\util\retry.py", line 403, in increment
    raise six.reraise(type(error), error, _stacktrace)
  File "d:\scripts\py\lib\site-packages\urllib3\packages\six.py", line 734, in reraise
    raise value.with_traceback(tb)
  File "d:\scripts\py\lib\site-packages\urllib3\connectionpool.py", line 677, in urlopen
    chunked=chunked,
  File "d:\scripts\py\lib\site-packages\urllib3\connectionpool.py", line 381, in _make_request
    self._validate_conn(conn)
  File "d:\scripts\py\lib\site-packages\urllib3\connectionpool.py", line 976, in _validate_conn
    conn.connect()
  File "d:\scripts\py\lib\site-packages\urllib3\connection.py", line 370, in connect
    ssl_context=context,
  File "d:\scripts\py\lib\site-packages\urllib3\util\ssl_.py", line 390, in ssl_wrap_socket
    return context.wrap_socket(sock)
  File "d:\scripts\py\lib\ssl.py", line 412, in wrap_socket
    session=session
  File "d:\scripts\py\lib\ssl.py", line 850, in _create
    self.do_handshake()
  File "d:\scripts\py\lib\ssl.py", line 1108, in do_handshake
    self._sslobj.do_handshake()
urllib3.exceptions.ProtocolError: ('Connection aborted.', ConnectionResetError(10054, 'An existing connection was forcibly closed by the remote host', None, 10054, None))

During handling of the above exception, another exception occurred:

Traceback (most recent call last):
  File "Aruba_Wireless_Upgrade_V4.py", line 174, in login
    res = r_session.post(login_url, data = login_post,verify=False)
  File "d:\scripts\py\lib\site-packages\requests\sessions.py", line 578, in post
    return self.request('POST', url, data=data, json=json, **kwargs)
  File "d:\scripts\py\lib\site-packages\requests\sessions.py", line 530, in request
    resp = self.send(prep, **send_kwargs)
  File "d:\scripts\py\lib\site-packages\requests\sessions.py", line 643, in send
    r = adapter.send(request, **kwargs)
  File "d:\scripts\py\lib\site-packages\requests\adapters.py", line 498, in send
    raise ConnectionError(err, request=request)
requests.exceptions.ConnectionError: ('Connection aborted.', ConnectionResetError(10054, 'An existing connection was forcibly closed by the remote host', None, 10054, None))
2020-08-05 05:13:13,693 > ERROR > Auto detect alternative partition failed
Traceback (most recent call last):
  File "Aruba_Wireless_Upgrade_V4.py", line 606, in MM_MD_Upload
    out = cmd_out.get("show boot")
AttributeError: 'NoneType' object has no attribute 'get'
2020-08-05 05:16:27,211 > ERROR > AP_IMAGE_PRELOAD POST: 
Traceback (most recent call last):
  File "Aruba_Wireless_Upgrade_V4.py", line 743, in AP_IMAGE_PRELOAD
    print("==> AP Preload Status:{}-{} => {} : {} ".format(host_name,host_ip,itm,value))
NameError: name 'value' is not defined
2020-08-05 05:16:36,615 > ERROR > AP_IMAGE_PRELOAD POST: 
Traceback (most recent call last):
  File "Aruba_Wireless_Upgrade_V4.py", line 743, in AP_IMAGE_PRELOAD
    print("==> AP Preload Status:{}-{} => {} : {} ".format(host_name,host_ip,itm,value))
NameError: name 'value' is not defined
2020-08-05 05:16:46,044 > ERROR > AP_IMAGE_PRELOAD POST: 
Traceback (most recent call last):
  File "Aruba_Wireless_Upgrade_V4.py", line 743, in AP_IMAGE_PRELOAD
    print("==> AP Preload Status:{}-{} => {} : {} ".format(host_name,host_ip,itm,value))
NameError: name 'value' is not defined
2020-08-05 05:16:55,458 > ERROR > AP_IMAGE_PRELOAD POST: 
Traceback (most recent call last):
  File "Aruba_Wireless_Upgrade_V4.py", line 743, in AP_IMAGE_PRELOAD
    print("==> AP Preload Status:{}-{} => {} : {} ".format(host_name,host_ip,itm,value))
NameError: name 'value' is not defined
2020-08-05 05:17:04,821 > ERROR > AP_IMAGE_PRELOAD POST: 
Traceback (most recent call last):
  File "Aruba_Wireless_Upgrade_V4.py", line 743, in AP_IMAGE_PRELOAD
    print("==> AP Preload Status:{}-{} => {} : {} ".format(host_name,host_ip,itm,value))
NameError: name 'value' is not defined
2020-08-05 05:17:14,200 > ERROR > AP_IMAGE_PRELOAD POST: 
Traceback (most recent call last):
  File "Aruba_Wireless_Upgrade_V4.py", line 743, in AP_IMAGE_PRELOAD
    print("** ==>AP Preload status check failed:{}-{}".format(host_name,host_ip))
NameError: name 'value' is not defined
2020-08-05 05:17:23,618 > ERROR > AP_IMAGE_PRELOAD POST: 
Traceback (most recent call last):
  File "Aruba_Wireless_Upgrade_V4.py", line 743, in AP_IMAGE_PRELOAD
    print("** ==>AP Preload status check failed:{}-{}".format(host_name,host_ip))
NameError: name 'value' is not defined
2020-08-05 05:17:33,021 > ERROR > AP_IMAGE_PRELOAD POST: 
Traceback (most recent call last):
  File "Aruba_Wireless_Upgrade_V4.py", line 743, in AP_IMAGE_PRELOAD
    print("** ==>AP Preload status check failed:{}-{}".format(host_name,host_ip))
NameError: name 'value' is not defined
2020-08-05 05:17:42,492 > ERROR > AP_IMAGE_PRELOAD POST: 
Traceback (most recent call last):
  File "Aruba_Wireless_Upgrade_V4.py", line 743, in AP_IMAGE_PRELOAD
    print("** ==>AP Preload status check failed:{}-{}".format(host_name,host_ip))
NameError: name 'value' is not defined
2020-08-05 05:17:51,958 > ERROR > AP_IMAGE_PRELOAD POST: 
Traceback (most recent call last):
  File "Aruba_Wireless_Upgrade_V4.py", line 743, in AP_IMAGE_PRELOAD
    print("** ==>AP Preload status check failed:{}-{}".format(host_name,host_ip))
NameError: name 'value' is not defined
2020-08-05 05:18:01,372 > ERROR > AP_IMAGE_PRELOAD POST: 
Traceback (most recent call last):
  File "Aruba_Wireless_Upgrade_V4.py", line 743, in AP_IMAGE_PRELOAD
    print("** ==>AP Preload status check failed:{}-{}".format(host_name,host_ip))
NameError: name 'value' is not defined
2020-08-05 05:18:10,798 > ERROR > AP_IMAGE_PRELOAD POST: 
Traceback (most recent call last):
  File "Aruba_Wireless_Upgrade_V4.py", line 743, in AP_IMAGE_PRELOAD
    print("** ==>AP Preload status check failed:{}-{}".format(host_name,host_ip))
NameError: name 'value' is not defined
2020-08-05 05:18:20,603 > ERROR > AP_IMAGE_PRELOAD POST: 
Traceback (most recent call last):
  File "Aruba_Wireless_Upgrade_V4.py", line 743, in AP_IMAGE_PRELOAD
    print("** ==>AP Preload status check failed:{}-{}".format(host_name,host_ip))
NameError: name 'value' is not defined
2020-08-05 05:18:29,976 > ERROR > AP_IMAGE_PRELOAD POST: 
Traceback (most recent call last):
  File "Aruba_Wireless_Upgrade_V4.py", line 743, in AP_IMAGE_PRELOAD
    print("** ==>AP Preload status check failed:{}-{}".format(host_name,host_ip))
NameError: name 'value' is not defined
2020-08-05 05:18:39,666 > ERROR > AP_IMAGE_PRELOAD POST: 
Traceback (most recent call last):
  File "Aruba_Wireless_Upgrade_V4.py", line 743, in AP_IMAGE_PRELOAD
    print("** ==>AP Preload status check failed:{}-{}".format(host_name,host_ip))
NameError: name 'value' is not defined
2020-08-05 05:18:49,027 > ERROR > AP_IMAGE_PRELOAD POST: 
Traceback (most recent call last):
  File "Aruba_Wireless_Upgrade_V4.py", line 743, in AP_IMAGE_PRELOAD
    print("** ==>AP Preload status check failed:{}-{}".format(host_name,host_ip))
NameError: name 'value' is not defined
2020-08-05 05:18:58,393 > ERROR > AP_IMAGE_PRELOAD POST: 
Traceback (most recent call last):
  File "Aruba_Wireless_Upgrade_V4.py", line 743, in AP_IMAGE_PRELOAD
    print("** ==>AP Preload status check failed:{}-{}".format(host_name,host_ip))
NameError: name 'value' is not defined
2020-08-05 05:19:07,794 > ERROR > AP_IMAGE_PRELOAD POST: 
Traceback (most recent call last):
  File "Aruba_Wireless_Upgrade_V4.py", line 743, in AP_IMAGE_PRELOAD
    print("** ==>AP Preload status check failed:{}-{}".format(host_name,host_ip))
NameError: name 'value' is not defined
2020-08-05 05:19:17,175 > ERROR > AP_IMAGE_PRELOAD POST: 
Traceback (most recent call last):
  File "Aruba_Wireless_Upgrade_V4.py", line 743, in AP_IMAGE_PRELOAD
    print("** ==>AP Preload status check failed:{}-{}".format(host_name,host_ip))
NameError: name 'value' is not defined
2020-08-05 05:19:26,845 > ERROR > AP_IMAGE_PRELOAD POST: 
Traceback (most recent call last):
  File "Aruba_Wireless_Upgrade_V4.py", line 743, in AP_IMAGE_PRELOAD
    else:
NameError: name 'value' is not defined
2020-08-05 05:19:36,232 > ERROR > AP_IMAGE_PRELOAD POST: 
Traceback (most recent call last):
  File "Aruba_Wireless_Upgrade_V4.py", line 743, in AP_IMAGE_PRELOAD
    else:
NameError: name 'value' is not defined
2020-08-05 05:19:45,660 > ERROR > AP_IMAGE_PRELOAD POST: 
Traceback (most recent call last):
  File "Aruba_Wireless_Upgrade_V4.py", line 743, in AP_IMAGE_PRELOAD
    else:
NameError: name 'value' is not defined
2020-08-05 05:21:46,699 > INFO > Starting Aruba Upgrade....
