2020-08-03 08:23:07,843 > INFO > Starting Aruba Upgrade....
2020-08-03 08:24:53,483 > ERROR > Logout error:
Traceback (most recent call last):
  File "Aruba_Wireless_Upgrade_V1.py", line 199, in logout
    res = session.get(url,verify=False)
AttributeError: 'NoneType' object has no attribute 'get'
2020-08-03 08:26:49,358 > INFO > Starting Aruba Upgrade....
2020-08-03 08:27:11,366 > ERROR > validating_pre_check
Traceback (most recent call last):
  File "Aruba_Wireless_Upgrade_V1.py", line 362, in validating_pre_check
    if int(new_disk) == running_disk:
TypeError: int() argument must be a string, a bytes-like object or a number, not 'NoneType'
2020-08-03 08:27:32,295 > ERROR > validating_pre_check
Traceback (most recent call last):
  File "Aruba_Wireless_Upgrade_V1.py", line 362, in validating_pre_check
    if int(new_disk) == running_disk:
TypeError: int() argument must be a string, a bytes-like object or a number, not 'NoneType'
2020-08-03 08:44:17,215 > INFO > Starting Aruba Upgrade....
2020-08-03 08:45:38,582 > INFO > Starting Aruba Upgrade....
2020-08-03 08:45:55,849 > ERROR > validating_pre_check
Traceback (most recent call last):
  File "Aruba_Wireless_Upgrade_V1.py", line 362, in validating_pre_check
    if int(new_disk) == running_disk:
TypeError: int() argument must be a string, a bytes-like object or a number, not 'NoneType'
2020-08-03 08:46:18,582 > ERROR > validating_pre_check
Traceback (most recent call last):
  File "Aruba_Wireless_Upgrade_V1.py", line 362, in validating_pre_check
    if int(new_disk) == running_disk:
TypeError: int() argument must be a string, a bytes-like object or a number, not 'NoneType'
2020-08-03 18:24:38,656 > INFO > Starting Aruba Upgrade....
2020-08-03 19:49:10,909 > INFO > Starting Aruba Upgrade....
2020-08-03 19:49:35,423 > ERROR > Login error: 
Traceback (most recent call last):
  File "d:\scripts\py\lib\site-packages\urllib3\connection.py", line 160, in _new_conn
    (self._dns_host, self.port), self.timeout, **extra_kw
  File "d:\scripts\py\lib\site-packages\urllib3\util\connection.py", line 84, in create_connection
    raise err
  File "d:\scripts\py\lib\site-packages\urllib3\util\connection.py", line 74, in create_connection
    sock.connect(sa)
TimeoutError: [WinError 10060] A connection attempt failed because the connected party did not properly respond after a period of time, or established connection failed because connected host has failed to respond

During handling of the above exception, another exception occurred:

Traceback (most recent call last):
  File "d:\scripts\py\lib\site-packages\urllib3\connectionpool.py", line 677, in urlopen
    chunked=chunked,
  File "d:\scripts\py\lib\site-packages\urllib3\connectionpool.py", line 381, in _make_request
    self._validate_conn(conn)
  File "d:\scripts\py\lib\site-packages\urllib3\connectionpool.py", line 976, in _validate_conn
    conn.connect()
  File "d:\scripts\py\lib\site-packages\urllib3\connection.py", line 308, in connect
    conn = self._new_conn()
  File "d:\scripts\py\lib\site-packages\urllib3\connection.py", line 172, in _new_conn
    self, "Failed to establish a new connection: %s" % e
urllib3.exceptions.NewConnectionError: <urllib3.connection.HTTPSConnection object at 0x0000020BC20020B8>: Failed to establish a new connection: [WinError 10060] A connection attempt failed because the connected party did not properly respond after a period of time, or established connection failed because connected host has failed to respond

During handling of the above exception, another exception occurred:

Traceback (most recent call last):
  File "d:\scripts\py\lib\site-packages\requests\adapters.py", line 449, in send
    timeout=timeout
  File "d:\scripts\py\lib\site-packages\urllib3\connectionpool.py", line 725, in urlopen
    method, url, error=e, _pool=self, _stacktrace=sys.exc_info()[2]
  File "d:\scripts\py\lib\site-packages\urllib3\util\retry.py", line 439, in increment
    raise MaxRetryError(_pool, url, error or ResponseError(cause))
urllib3.exceptions.MaxRetryError: HTTPSConnectionPool(host='10.17.84.220', port=4343): Max retries exceeded with url: /v1/api/login (Caused by NewConnectionError('<urllib3.connection.HTTPSConnection object at 0x0000020BC20020B8>: Failed to establish a new connection: [WinError 10060] A connection attempt failed because the connected party did not properly respond after a period of time, or established connection failed because connected host has failed to respond'))

During handling of the above exception, another exception occurred:

Traceback (most recent call last):
  File "Aruba_Wireless_Upgrade_V1.py", line 173, in login
    res = r_session.post(login_url, data = login_post,verify=False)
  File "d:\scripts\py\lib\site-packages\requests\sessions.py", line 578, in post
    return self.request('POST', url, data=data, json=json, **kwargs)
  File "d:\scripts\py\lib\site-packages\requests\sessions.py", line 530, in request
    resp = self.send(prep, **send_kwargs)
  File "d:\scripts\py\lib\site-packages\requests\sessions.py", line 643, in send
    r = adapter.send(request, **kwargs)
  File "d:\scripts\py\lib\site-packages\requests\adapters.py", line 516, in send
    raise ConnectionError(e, request=request)
requests.exceptions.ConnectionError: HTTPSConnectionPool(host='10.17.84.220', port=4343): Max retries exceeded with url: /v1/api/login (Caused by NewConnectionError('<urllib3.connection.HTTPSConnection object at 0x0000020BC20020B8>: Failed to establish a new connection: [WinError 10060] A connection attempt failed because the connected party did not properly respond after a period of time, or established connection failed because connected host has failed to respond'))
2020-08-03 19:49:35,485 > ERROR > Auto detect alternative partition failed
Traceback (most recent call last):
  File "Aruba_Wireless_Upgrade_V1.py", line 569, in MM_MD_Upload
    out = cmd_out.get("show boot")
AttributeError: 'NoneType' object has no attribute 'get'
2020-08-03 19:50:24,974 > ERROR > upload_image_http: 
Traceback (most recent call last):
  File "Aruba_Wireless_Upgrade_V1.py", line 499, in upload_image_http
    file_data = open(file_path,'rb')
FileNotFoundError: [Errno 2] No such file or directory: 'D:\\scripts\\GIT\\Aruba_Controller_upgrade\\ArubaOS_VMC_8.5.0.10-FIPS_76207'
2020-08-03 20:14:03,713 > ERROR > upload_image_http: 
Traceback (most recent call last):
  File "d:\scripts\py\lib\site-packages\urllib3\connectionpool.py", line 677, in urlopen
    chunked=chunked,
  File "d:\scripts\py\lib\site-packages\urllib3\connectionpool.py", line 392, in _make_request
    conn.request(method, url, **httplib_request_kw)
  File "d:\scripts\py\lib\http\client.py", line 1229, in request
    self._send_request(method, url, body, headers, encode_chunked)
  File "d:\scripts\py\lib\http\client.py", line 1275, in _send_request
    self.endheaders(body, encode_chunked=encode_chunked)
  File "d:\scripts\py\lib\http\client.py", line 1224, in endheaders
    self._send_output(message_body, encode_chunked=encode_chunked)
  File "d:\scripts\py\lib\http\client.py", line 1055, in _send_output
    self.send(chunk)
  File "d:\scripts\py\lib\http\client.py", line 977, in send
    self.sock.sendall(data)
  File "d:\scripts\py\lib\ssl.py", line 1012, in sendall
    v = self.send(byte_view[count:])
  File "d:\scripts\py\lib\ssl.py", line 981, in send
    return self._sslobj.write(data)
ConnectionResetError: [WinError 10054] An existing connection was forcibly closed by the remote host

During handling of the above exception, another exception occurred:

Traceback (most recent call last):
  File "d:\scripts\py\lib\site-packages\requests\adapters.py", line 449, in send
    timeout=timeout
  File "d:\scripts\py\lib\site-packages\urllib3\connectionpool.py", line 725, in urlopen
    method, url, error=e, _pool=self, _stacktrace=sys.exc_info()[2]
  File "d:\scripts\py\lib\site-packages\urllib3\util\retry.py", line 403, in increment
    raise six.reraise(type(error), error, _stacktrace)
  File "d:\scripts\py\lib\site-packages\urllib3\packages\six.py", line 734, in reraise
    raise value.with_traceback(tb)
  File "d:\scripts\py\lib\site-packages\urllib3\connectionpool.py", line 677, in urlopen
    chunked=chunked,
  File "d:\scripts\py\lib\site-packages\urllib3\connectionpool.py", line 392, in _make_request
    conn.request(method, url, **httplib_request_kw)
  File "d:\scripts\py\lib\http\client.py", line 1229, in request
    self._send_request(method, url, body, headers, encode_chunked)
  File "d:\scripts\py\lib\http\client.py", line 1275, in _send_request
    self.endheaders(body, encode_chunked=encode_chunked)
  File "d:\scripts\py\lib\http\client.py", line 1224, in endheaders
    self._send_output(message_body, encode_chunked=encode_chunked)
  File "d:\scripts\py\lib\http\client.py", line 1055, in _send_output
    self.send(chunk)
  File "d:\scripts\py\lib\http\client.py", line 977, in send
    self.sock.sendall(data)
  File "d:\scripts\py\lib\ssl.py", line 1012, in sendall
    v = self.send(byte_view[count:])
  File "d:\scripts\py\lib\ssl.py", line 981, in send
    return self._sslobj.write(data)
urllib3.exceptions.ProtocolError: ('Connection aborted.', ConnectionResetError(10054, 'An existing connection was forcibly closed by the remote host', None, 10054, None))

During handling of the above exception, another exception occurred:

Traceback (most recent call last):
  File "Aruba_Wireless_Upgrade_V1.py", line 518, in upload_image_http
    res = session.post(url,data=mp,headers=headers,verify=False)
  File "d:\scripts\py\lib\site-packages\requests\sessions.py", line 578, in post
    return self.request('POST', url, data=data, json=json, **kwargs)
  File "d:\scripts\py\lib\site-packages\requests\sessions.py", line 530, in request
    resp = self.send(prep, **send_kwargs)
  File "d:\scripts\py\lib\site-packages\requests\sessions.py", line 643, in send
    r = adapter.send(request, **kwargs)
  File "d:\scripts\py\lib\site-packages\requests\adapters.py", line 498, in send
    raise ConnectionError(err, request=request)
requests.exceptions.ConnectionError: ('Connection aborted.', ConnectionResetError(10054, 'An existing connection was forcibly closed by the remote host', None, 10054, None))
2020-08-04 01:26:47,384 > INFO > Starting Aruba Upgrade....
2020-08-04 01:30:34,387 > INFO > Starting Aruba Upgrade....
