2020-09-24 09:11:49,577 > INFO > JOBNAME:1600918909_5507176
2020-09-24 09:11:49,577 > INFO > CONFIG FILE:D:\scripts\GIT\Aruba_Controller_upgrade\conf_files\LAB WIRELESS UPGRADE 8.5
2020-09-24 09:11:49,675 > INFO > Starting Job
2020-09-24 09:11:49,690 > INFO > INFO:Running: 1600918909_5507176 Type:precheck
2020-09-24 09:11:49,707 > INFO > INFO:Starting Configuration LAB WIRELESS UPGRADE 8.5 Validation
2020-09-24 09:11:49,759 > INFO > Inserting upgrade list to upgrade.db
2020-09-24 09:11:53,814 > INFO > yes
2020-09-24 09:11:53,814 > INFO > INFO:Starting precheck
2020-09-24 09:11:53,827 > INFO > INFO:Executing Precheck
2020-09-24 09:11:53,854 > INFO > INFO:Installation Disk Auto not provided for 10.17.84.220:4343 , Trying to auto detect
2020-09-24 09:12:14,909 > ERROR > ERROR:Login error : 10.17.84.220:4343
2020-09-24 09:12:14,926 > DEBUG > ERROR:Login error : 10.17.84.220:4343
2020-09-24 09:12:14,941 > ERROR > Login error:10.17.84.220:4343 
Traceback (most recent call last):
  File "d:\scripts\py\lib\site-packages\urllib3\connection.py", line 160, in _new_conn
    (self._dns_host, self.port), self.timeout, **extra_kw
  File "d:\scripts\py\lib\site-packages\urllib3\util\connection.py", line 84, in create_connection
    raise err
  File "d:\scripts\py\lib\site-packages\urllib3\util\connection.py", line 74, in create_connection
    sock.connect(sa)
TimeoutError: [WinError 10060] A connection attempt failed because the connected party did not properly respond after a period of time, or established connection failed because connected host has failed to respond

During handling of the above exception, another exception occurred:

Traceback (most recent call last):
  File "d:\scripts\py\lib\site-packages\urllib3\connectionpool.py", line 677, in urlopen
    chunked=chunked,
  File "d:\scripts\py\lib\site-packages\urllib3\connectionpool.py", line 381, in _make_request
    self._validate_conn(conn)
  File "d:\scripts\py\lib\site-packages\urllib3\connectionpool.py", line 976, in _validate_conn
    conn.connect()
  File "d:\scripts\py\lib\site-packages\urllib3\connection.py", line 308, in connect
    conn = self._new_conn()
  File "d:\scripts\py\lib\site-packages\urllib3\connection.py", line 172, in _new_conn
    self, "Failed to establish a new connection: %s" % e
urllib3.exceptions.NewConnectionError: <urllib3.connection.HTTPSConnection object at 0x00000261D2333588>: Failed to establish a new connection: [WinError 10060] A connection attempt failed because the connected party did not properly respond after a period of time, or established connection failed because connected host has failed to respond

During handling of the above exception, another exception occurred:

Traceback (most recent call last):
  File "d:\scripts\py\lib\site-packages\requests\adapters.py", line 449, in send
    timeout=timeout
  File "d:\scripts\py\lib\site-packages\urllib3\connectionpool.py", line 725, in urlopen
    method, url, error=e, _pool=self, _stacktrace=sys.exc_info()[2]
  File "d:\scripts\py\lib\site-packages\urllib3\util\retry.py", line 439, in increment
    raise MaxRetryError(_pool, url, error or ResponseError(cause))
urllib3.exceptions.MaxRetryError: HTTPSConnectionPool(host='10.17.84.220', port=4343): Max retries exceeded with url: /v1/api/login (Caused by NewConnectionError('<urllib3.connection.HTTPSConnection object at 0x00000261D2333588>: Failed to establish a new connection: [WinError 10060] A connection attempt failed because the connected party did not properly respond after a period of time, or established connection failed because connected host has failed to respond'))

During handling of the above exception, another exception occurred:

Traceback (most recent call last):
  File "D:\scripts\GIT\Aruba_Controller_upgrade\Aruba_Wireless_Upgrade_APP.py", line 101, in get_session
    res = r_session.post(login_url, data = login_post,verify=False)
  File "d:\scripts\py\lib\site-packages\requests\sessions.py", line 578, in post
    return self.request('POST', url, data=data, json=json, **kwargs)
  File "d:\scripts\py\lib\site-packages\requests\sessions.py", line 530, in request
    resp = self.send(prep, **send_kwargs)
  File "d:\scripts\py\lib\site-packages\requests\sessions.py", line 643, in send
    r = adapter.send(request, **kwargs)
  File "d:\scripts\py\lib\site-packages\requests\adapters.py", line 516, in send
    raise ConnectionError(e, request=request)
requests.exceptions.ConnectionError: HTTPSConnectionPool(host='10.17.84.220', port=4343): Max retries exceeded with url: /v1/api/login (Caused by NewConnectionError('<urllib3.connection.HTTPSConnection object at 0x00000261D2333588>: Failed to establish a new connection: [WinError 10060] A connection attempt failed because the connected party did not properly respond after a period of time, or established connection failed because connected host has failed to respond'))
2020-09-24 09:12:15,003 > ERROR > ERROR:NaaS-MM-1-10.17.84.220:4343 : Auto detect alternative partition failed
2020-09-24 09:12:15,017 > DEBUG > ERROR:NaaS-MM-1-10.17.84.220:4343 : Auto detect alternative partition failed
2020-09-24 09:12:15,030 > ERROR > Auto detect alternative partition failed
Traceback (most recent call last):
  File "D:\scripts\GIT\Aruba_Controller_upgrade\Aruba_Wireless_Upgrade_APP.py", line 284, in find_alternative_partition
    out = cmd_out.get("show boot")
AttributeError: 'NoneType' object has no attribute 'get'
2020-09-24 09:12:15,073 > INFO > INFO:Installation Disk Auto not provided for 10.17.84.221:4343 , Trying to auto detect
2020-09-24 09:12:36,092 > ERROR > ERROR:Login error : 10.17.84.221:4343
2020-09-24 09:12:36,108 > DEBUG > ERROR:Login error : 10.17.84.221:4343
2020-09-24 09:12:36,124 > ERROR > Login error:10.17.84.221:4343 
Traceback (most recent call last):
  File "d:\scripts\py\lib\site-packages\urllib3\connection.py", line 160, in _new_conn
    (self._dns_host, self.port), self.timeout, **extra_kw
  File "d:\scripts\py\lib\site-packages\urllib3\util\connection.py", line 84, in create_connection
    raise err
  File "d:\scripts\py\lib\site-packages\urllib3\util\connection.py", line 74, in create_connection
    sock.connect(sa)
TimeoutError: [WinError 10060] A connection attempt failed because the connected party did not properly respond after a period of time, or established connection failed because connected host has failed to respond

During handling of the above exception, another exception occurred:

Traceback (most recent call last):
  File "d:\scripts\py\lib\site-packages\urllib3\connectionpool.py", line 677, in urlopen
    chunked=chunked,
  File "d:\scripts\py\lib\site-packages\urllib3\connectionpool.py", line 381, in _make_request
    self._validate_conn(conn)
  File "d:\scripts\py\lib\site-packages\urllib3\connectionpool.py", line 976, in _validate_conn
    conn.connect()
  File "d:\scripts\py\lib\site-packages\urllib3\connection.py", line 308, in connect
    conn = self._new_conn()
  File "d:\scripts\py\lib\site-packages\urllib3\connection.py", line 172, in _new_conn
    self, "Failed to establish a new connection: %s" % e
urllib3.exceptions.NewConnectionError: <urllib3.connection.HTTPSConnection object at 0x00000261D2337AC8>: Failed to establish a new connection: [WinError 10060] A connection attempt failed because the connected party did not properly respond after a period of time, or established connection failed because connected host has failed to respond

During handling of the above exception, another exception occurred:

Traceback (most recent call last):
  File "d:\scripts\py\lib\site-packages\requests\adapters.py", line 449, in send
    timeout=timeout
  File "d:\scripts\py\lib\site-packages\urllib3\connectionpool.py", line 725, in urlopen
    method, url, error=e, _pool=self, _stacktrace=sys.exc_info()[2]
  File "d:\scripts\py\lib\site-packages\urllib3\util\retry.py", line 439, in increment
    raise MaxRetryError(_pool, url, error or ResponseError(cause))
urllib3.exceptions.MaxRetryError: HTTPSConnectionPool(host='10.17.84.221', port=4343): Max retries exceeded with url: /v1/api/login (Caused by NewConnectionError('<urllib3.connection.HTTPSConnection object at 0x00000261D2337AC8>: Failed to establish a new connection: [WinError 10060] A connection attempt failed because the connected party did not properly respond after a period of time, or established connection failed because connected host has failed to respond'))

During handling of the above exception, another exception occurred:

Traceback (most recent call last):
  File "D:\scripts\GIT\Aruba_Controller_upgrade\Aruba_Wireless_Upgrade_APP.py", line 101, in get_session
    res = r_session.post(login_url, data = login_post,verify=False)
  File "d:\scripts\py\lib\site-packages\requests\sessions.py", line 578, in post
    return self.request('POST', url, data=data, json=json, **kwargs)
  File "d:\scripts\py\lib\site-packages\requests\sessions.py", line 530, in request
    resp = self.send(prep, **send_kwargs)
  File "d:\scripts\py\lib\site-packages\requests\sessions.py", line 643, in send
    r = adapter.send(request, **kwargs)
  File "d:\scripts\py\lib\site-packages\requests\adapters.py", line 516, in send
    raise ConnectionError(e, request=request)
requests.exceptions.ConnectionError: HTTPSConnectionPool(host='10.17.84.221', port=4343): Max retries exceeded with url: /v1/api/login (Caused by NewConnectionError('<urllib3.connection.HTTPSConnection object at 0x00000261D2337AC8>: Failed to establish a new connection: [WinError 10060] A connection attempt failed because the connected party did not properly respond after a period of time, or established connection failed because connected host has failed to respond'))
2020-09-24 09:12:36,139 > ERROR > ERROR:NaaS-VMC-1-10.17.84.221:4343 : Auto detect alternative partition failed
2020-09-24 09:12:36,326 > DEBUG > ERROR:NaaS-VMC-1-10.17.84.221:4343 : Auto detect alternative partition failed
2020-09-24 09:12:36,339 > ERROR > Auto detect alternative partition failed
Traceback (most recent call last):
  File "D:\scripts\GIT\Aruba_Controller_upgrade\Aruba_Wireless_Upgrade_APP.py", line 284, in find_alternative_partition
    out = cmd_out.get("show boot")
AttributeError: 'NoneType' object has no attribute 'get'
2020-09-24 09:12:57,376 > ERROR > ERROR:Login error : 10.17.84.220:4343
2020-09-24 09:12:57,403 > DEBUG > ERROR:Login error : 10.17.84.220:4343
2020-09-24 09:12:57,417 > ERROR > Login error:10.17.84.220:4343 
Traceback (most recent call last):
  File "d:\scripts\py\lib\site-packages\urllib3\connection.py", line 160, in _new_conn
    (self._dns_host, self.port), self.timeout, **extra_kw
  File "d:\scripts\py\lib\site-packages\urllib3\util\connection.py", line 84, in create_connection
    raise err
  File "d:\scripts\py\lib\site-packages\urllib3\util\connection.py", line 74, in create_connection
    sock.connect(sa)
TimeoutError: [WinError 10060] A connection attempt failed because the connected party did not properly respond after a period of time, or established connection failed because connected host has failed to respond

During handling of the above exception, another exception occurred:

Traceback (most recent call last):
  File "d:\scripts\py\lib\site-packages\urllib3\connectionpool.py", line 677, in urlopen
    chunked=chunked,
  File "d:\scripts\py\lib\site-packages\urllib3\connectionpool.py", line 381, in _make_request
    self._validate_conn(conn)
  File "d:\scripts\py\lib\site-packages\urllib3\connectionpool.py", line 976, in _validate_conn
    conn.connect()
  File "d:\scripts\py\lib\site-packages\urllib3\connection.py", line 308, in connect
    conn = self._new_conn()
  File "d:\scripts\py\lib\site-packages\urllib3\connection.py", line 172, in _new_conn
    self, "Failed to establish a new connection: %s" % e
urllib3.exceptions.NewConnectionError: <urllib3.connection.HTTPSConnection object at 0x00000261D2312160>: Failed to establish a new connection: [WinError 10060] A connection attempt failed because the connected party did not properly respond after a period of time, or established connection failed because connected host has failed to respond

During handling of the above exception, another exception occurred:

Traceback (most recent call last):
  File "d:\scripts\py\lib\site-packages\requests\adapters.py", line 449, in send
    timeout=timeout
  File "d:\scripts\py\lib\site-packages\urllib3\connectionpool.py", line 725, in urlopen
    method, url, error=e, _pool=self, _stacktrace=sys.exc_info()[2]
  File "d:\scripts\py\lib\site-packages\urllib3\util\retry.py", line 439, in increment
    raise MaxRetryError(_pool, url, error or ResponseError(cause))
urllib3.exceptions.MaxRetryError: HTTPSConnectionPool(host='10.17.84.220', port=4343): Max retries exceeded with url: /v1/api/login (Caused by NewConnectionError('<urllib3.connection.HTTPSConnection object at 0x00000261D2312160>: Failed to establish a new connection: [WinError 10060] A connection attempt failed because the connected party did not properly respond after a period of time, or established connection failed because connected host has failed to respond'))

During handling of the above exception, another exception occurred:

Traceback (most recent call last):
  File "D:\scripts\GIT\Aruba_Controller_upgrade\Aruba_Wireless_Upgrade_APP.py", line 101, in get_session
    res = r_session.post(login_url, data = login_post,verify=False)
  File "d:\scripts\py\lib\site-packages\requests\sessions.py", line 578, in post
    return self.request('POST', url, data=data, json=json, **kwargs)
  File "d:\scripts\py\lib\site-packages\requests\sessions.py", line 530, in request
    resp = self.send(prep, **send_kwargs)
  File "d:\scripts\py\lib\site-packages\requests\sessions.py", line 643, in send
    r = adapter.send(request, **kwargs)
  File "d:\scripts\py\lib\site-packages\requests\adapters.py", line 516, in send
    raise ConnectionError(e, request=request)
requests.exceptions.ConnectionError: HTTPSConnectionPool(host='10.17.84.220', port=4343): Max retries exceeded with url: /v1/api/login (Caused by NewConnectionError('<urllib3.connection.HTTPSConnection object at 0x00000261D2312160>: Failed to establish a new connection: [WinError 10060] A connection attempt failed because the connected party did not properly respond after a period of time, or established connection failed because connected host has failed to respond'))
2020-09-24 09:13:04,289 > INFO > INFO:Login Success => 10.17.84.221:4343
2020-09-24 09:13:20,225 > INFO > INFO:PRECHECK started for : (MM) NaaS-MM-1:10.17.84.220:4343
2020-09-24 09:13:25,908 > INFO > INFO:Login Success => 10.17.84.220:4343
2020-09-24 09:13:25,951 > INFO > INFO:Executing NaaS-MM-1 - 10.17.84.220:4343 => show clock
2020-09-24 09:13:28,423 > INFO > INFO:Executing NaaS-MM-1 - 10.17.84.220:4343 => show version
2020-09-24 09:13:29,276 > INFO > INFO:Executing NaaS-MM-1 - 10.17.84.220:4343 => show image version
2020-09-24 09:13:30,050 > INFO > INFO:Executing NaaS-MM-1 - 10.17.84.220:4343 => show storage
2020-09-24 09:13:30,816 > INFO > INFO:Executing NaaS-MM-1 - 10.17.84.220:4343 => show cpuload
2020-09-24 09:13:31,584 > INFO > INFO:Executing NaaS-MM-1 - 10.17.84.220:4343 => show memory
2020-09-24 09:13:32,358 > INFO > INFO:Executing NaaS-MM-1 - 10.17.84.220:4343 => show boot
2020-09-24 09:13:33,149 > INFO > INFO:Executing NaaS-MM-1 - 10.17.84.220:4343 => show switches
2020-09-24 09:13:33,916 > INFO > INFO:Executing NaaS-MM-1 - 10.17.84.220:4343 => show switchinfo
2020-09-24 09:13:34,704 > INFO > INFO:Executing NaaS-MM-1 - 10.17.84.220:4343 => show boot history
2020-09-24 09:13:35,609 > INFO > INFO:Executing NaaS-MM-1 - 10.17.84.220:4343 => show crypto ipsec sa
2020-09-24 09:13:36,367 > INFO > INFO:Executing NaaS-MM-1 - 10.17.84.220:4343 => show master-redundancy
2020-09-24 09:13:37,109 > INFO > INFO:Executing NaaS-MM-1 - 10.17.84.220:4343 => show database synchronize
2020-09-24 09:13:38,086 > INFO > INFO:Executing NaaS-MM-1 - 10.17.84.220:4343 => show license
2020-09-24 09:13:39,224 > INFO > INFO:Executing NaaS-MM-1 - 10.17.84.220:4343 => show running-config
2020-09-24 09:13:40,437 > INFO > INFO:PRECHECK started for : (MD) NaaS-VMC-1:10.17.84.221:4343
2020-09-24 09:13:42,944 > INFO > INFO:Session Valid : 10.17.84.221:4343
2020-09-24 09:13:42,986 > INFO > INFO:Executing NaaS-VMC-1 - 10.17.84.221:4343 => show clock
2020-09-24 09:13:44,719 > INFO > INFO:Executing NaaS-VMC-1 - 10.17.84.221:4343 => show version
2020-09-24 09:13:45,487 > INFO > INFO:Executing NaaS-VMC-1 - 10.17.84.221:4343 => show image version
2020-09-24 09:13:46,418 > INFO > INFO:Executing NaaS-VMC-1 - 10.17.84.221:4343 => show storage
2020-09-24 09:13:47,179 > INFO > INFO:Executing NaaS-VMC-1 - 10.17.84.221:4343 => show cpuload
2020-09-24 09:13:48,615 > INFO > INFO:Executing NaaS-VMC-1 - 10.17.84.221:4343 => show memory
2020-09-24 09:13:50,134 > INFO > INFO:Executing NaaS-VMC-1 - 10.17.84.221:4343 => show boot
2020-09-24 09:13:51,269 > INFO > INFO:Executing NaaS-VMC-1 - 10.17.84.221:4343 => show switches
2020-09-24 09:13:52,245 > INFO > INFO:Executing NaaS-VMC-1 - 10.17.84.221:4343 => show switchinfo
2020-09-24 09:13:53,221 > INFO > INFO:Executing NaaS-VMC-1 - 10.17.84.221:4343 => show boot history
2020-09-24 09:13:54,690 > INFO > INFO:Executing NaaS-VMC-1 - 10.17.84.221:4343 => show user
2020-09-24 09:13:55,454 > INFO > INFO:Executing NaaS-VMC-1 - 10.17.84.221:4343 => show ap database long
2020-09-24 09:13:56,600 > INFO > INFO:Executing NaaS-VMC-1 - 10.17.84.221:4343 => show ap bss-table
2020-09-24 09:13:57,374 > INFO > INFO:Executing NaaS-VMC-1 - 10.17.84.221:4343 => show ap essid
2020-09-24 09:13:58,690 > INFO > INFO:Executing NaaS-VMC-1 - 10.17.84.221:4343 => show ap active counters
2020-09-24 09:14:00,641 > INFO > INFO:Executing NaaS-VMC-1 - 10.17.84.221:4343 => show ap debug counters
2020-09-24 09:14:02,259 > INFO > INFO:Executing NaaS-VMC-1 - 10.17.84.221:4343 => show lc-cluster group-membership
2020-09-24 09:14:03,759 > INFO > INFO:Executing NaaS-VMC-1 - 10.17.84.221:4343 => show switches
2020-09-24 09:14:04,520 > INFO > INFO:Executing NaaS-VMC-1 - 10.17.84.221:4343 => show license
2020-09-24 09:14:05,273 > INFO > INFO:Executing NaaS-VMC-1 - 10.17.84.221:4343 => show running-config
2020-09-24 09:14:06,462 > INFO > INFO:Executing NaaS-VMC-1 - 10.17.84.221:4343 => show boot
2020-09-24 09:14:07,262 > INFO > INFO:Executing NaaS-VMC-1 - 10.17.84.221:4343 => show version
2020-09-24 09:14:08,063 > INFO > INFO:Precheck Completed
2020-09-24 09:14:08,094 > INFO > INFO:==== Completed ====
