2020-09-14 21:17:33,247 > INFO > JOBNAME:1600098453_2288127
2020-09-14 21:17:33,247 > INFO > CONFIG FILE:D:\scripts\GIT\Aruba_Controller_upgrade\conf_files\LAB WIRELESS UPGRADE
2020-09-14 21:17:33,315 > INFO > Starting Job
2020-09-14 21:17:33,329 > INFO > INFO:Running: 1600098453_2288127 Type:precheck,all
2020-09-14 21:17:33,344 > INFO > INFO:Starting Configuration LAB WIRELESS UPGRADE Validation
2020-09-14 21:17:33,378 > INFO > Inserting upgrade list to upgrade.db
2020-09-14 21:17:37,445 > INFO > yes
2020-09-14 21:17:37,446 > INFO > INFO:Starting precheck
2020-09-14 21:17:37,459 > INFO > INFO:Executing Precheck
2020-09-14 21:17:37,487 > INFO > INFO:Installation Disk Auto not provided for 10.17.84.220:4343 , Trying to auto detect
2020-09-14 21:17:58,534 > ERROR > ERROR:Login error : 10.17.84.220:4343
2020-09-14 21:17:58,554 > DEBUG > ERROR:Login error : 10.17.84.220:4343
2020-09-14 21:17:58,571 > ERROR > Login error:10.17.84.220:4343 
Traceback (most recent call last):
  File "D:\scripts\py\lib\site-packages\urllib3\connection.py", line 160, in _new_conn
    (self._dns_host, self.port), self.timeout, **extra_kw
  File "D:\scripts\py\lib\site-packages\urllib3\util\connection.py", line 84, in create_connection
    raise err
  File "D:\scripts\py\lib\site-packages\urllib3\util\connection.py", line 74, in create_connection
    sock.connect(sa)
TimeoutError: [WinError 10060] A connection attempt failed because the connected party did not properly respond after a period of time, or established connection failed because connected host has failed to respond

During handling of the above exception, another exception occurred:

Traceback (most recent call last):
  File "D:\scripts\py\lib\site-packages\urllib3\connectionpool.py", line 677, in urlopen
    chunked=chunked,
  File "D:\scripts\py\lib\site-packages\urllib3\connectionpool.py", line 381, in _make_request
    self._validate_conn(conn)
  File "D:\scripts\py\lib\site-packages\urllib3\connectionpool.py", line 976, in _validate_conn
    conn.connect()
  File "D:\scripts\py\lib\site-packages\urllib3\connection.py", line 308, in connect
    conn = self._new_conn()
  File "D:\scripts\py\lib\site-packages\urllib3\connection.py", line 172, in _new_conn
    self, "Failed to establish a new connection: %s" % e
urllib3.exceptions.NewConnectionError: <urllib3.connection.HTTPSConnection object at 0x000002A93802C4E0>: Failed to establish a new connection: [WinError 10060] A connection attempt failed because the connected party did not properly respond after a period of time, or established connection failed because connected host has failed to respond

During handling of the above exception, another exception occurred:

Traceback (most recent call last):
  File "D:\scripts\py\lib\site-packages\requests\adapters.py", line 449, in send
    timeout=timeout
  File "D:\scripts\py\lib\site-packages\urllib3\connectionpool.py", line 725, in urlopen
    method, url, error=e, _pool=self, _stacktrace=sys.exc_info()[2]
  File "D:\scripts\py\lib\site-packages\urllib3\util\retry.py", line 439, in increment
    raise MaxRetryError(_pool, url, error or ResponseError(cause))
urllib3.exceptions.MaxRetryError: HTTPSConnectionPool(host='10.17.84.220', port=4343): Max retries exceeded with url: /v1/api/login (Caused by NewConnectionError('<urllib3.connection.HTTPSConnection object at 0x000002A93802C4E0>: Failed to establish a new connection: [WinError 10060] A connection attempt failed because the connected party did not properly respond after a period of time, or established connection failed because connected host has failed to respond'))

During handling of the above exception, another exception occurred:

Traceback (most recent call last):
  File "D:\scripts\GIT\Aruba_Controller_upgrade\Aruba_Wireless_Upgrade_APP.py", line 100, in get_session
    res = r_session.post(login_url, data = login_post,verify=False)
  File "D:\scripts\py\lib\site-packages\requests\sessions.py", line 578, in post
    return self.request('POST', url, data=data, json=json, **kwargs)
  File "D:\scripts\py\lib\site-packages\requests\sessions.py", line 530, in request
    resp = self.send(prep, **send_kwargs)
  File "D:\scripts\py\lib\site-packages\requests\sessions.py", line 643, in send
    r = adapter.send(request, **kwargs)
  File "D:\scripts\py\lib\site-packages\requests\adapters.py", line 516, in send
    raise ConnectionError(e, request=request)
requests.exceptions.ConnectionError: HTTPSConnectionPool(host='10.17.84.220', port=4343): Max retries exceeded with url: /v1/api/login (Caused by NewConnectionError('<urllib3.connection.HTTPSConnection object at 0x000002A93802C4E0>: Failed to establish a new connection: [WinError 10060] A connection attempt failed because the connected party did not properly respond after a period of time, or established connection failed because connected host has failed to respond'))
2020-09-14 21:17:58,642 > ERROR > ERROR:NaaS-MM-1-10.17.84.220:4343 : Auto detect alternative partition failed
2020-09-14 21:17:58,658 > DEBUG > ERROR:NaaS-MM-1-10.17.84.220:4343 : Auto detect alternative partition failed
2020-09-14 21:17:58,673 > ERROR > Auto detect alternative partition failed
Traceback (most recent call last):
  File "D:\scripts\GIT\Aruba_Controller_upgrade\Aruba_Wireless_Upgrade_APP.py", line 283, in find_alternative_partition
    out = cmd_out.get("show boot")
AttributeError: 'NoneType' object has no attribute 'get'
2020-09-14 21:17:58,720 > INFO > INFO:Installation Disk Auto not provided for 10.17.84.221:4343 , Trying to auto detect
2020-09-14 21:18:19,742 > ERROR > ERROR:Login error : 10.17.84.221:4343
2020-09-14 21:18:19,761 > DEBUG > ERROR:Login error : 10.17.84.221:4343
2020-09-14 21:18:19,780 > ERROR > Login error:10.17.84.221:4343 
Traceback (most recent call last):
  File "D:\scripts\py\lib\site-packages\urllib3\connection.py", line 160, in _new_conn
    (self._dns_host, self.port), self.timeout, **extra_kw
  File "D:\scripts\py\lib\site-packages\urllib3\util\connection.py", line 84, in create_connection
    raise err
  File "D:\scripts\py\lib\site-packages\urllib3\util\connection.py", line 74, in create_connection
    sock.connect(sa)
TimeoutError: [WinError 10060] A connection attempt failed because the connected party did not properly respond after a period of time, or established connection failed because connected host has failed to respond

During handling of the above exception, another exception occurred:

Traceback (most recent call last):
  File "D:\scripts\py\lib\site-packages\urllib3\connectionpool.py", line 677, in urlopen
    chunked=chunked,
  File "D:\scripts\py\lib\site-packages\urllib3\connectionpool.py", line 381, in _make_request
    self._validate_conn(conn)
  File "D:\scripts\py\lib\site-packages\urllib3\connectionpool.py", line 976, in _validate_conn
    conn.connect()
  File "D:\scripts\py\lib\site-packages\urllib3\connection.py", line 308, in connect
    conn = self._new_conn()
  File "D:\scripts\py\lib\site-packages\urllib3\connection.py", line 172, in _new_conn
    self, "Failed to establish a new connection: %s" % e
urllib3.exceptions.NewConnectionError: <urllib3.connection.HTTPSConnection object at 0x000002A937FFA5F8>: Failed to establish a new connection: [WinError 10060] A connection attempt failed because the connected party did not properly respond after a period of time, or established connection failed because connected host has failed to respond

During handling of the above exception, another exception occurred:

Traceback (most recent call last):
  File "D:\scripts\py\lib\site-packages\requests\adapters.py", line 449, in send
    timeout=timeout
  File "D:\scripts\py\lib\site-packages\urllib3\connectionpool.py", line 725, in urlopen
    method, url, error=e, _pool=self, _stacktrace=sys.exc_info()[2]
  File "D:\scripts\py\lib\site-packages\urllib3\util\retry.py", line 439, in increment
    raise MaxRetryError(_pool, url, error or ResponseError(cause))
urllib3.exceptions.MaxRetryError: HTTPSConnectionPool(host='10.17.84.221', port=4343): Max retries exceeded with url: /v1/api/login (Caused by NewConnectionError('<urllib3.connection.HTTPSConnection object at 0x000002A937FFA5F8>: Failed to establish a new connection: [WinError 10060] A connection attempt failed because the connected party did not properly respond after a period of time, or established connection failed because connected host has failed to respond'))

During handling of the above exception, another exception occurred:

Traceback (most recent call last):
  File "D:\scripts\GIT\Aruba_Controller_upgrade\Aruba_Wireless_Upgrade_APP.py", line 100, in get_session
    res = r_session.post(login_url, data = login_post,verify=False)
  File "D:\scripts\py\lib\site-packages\requests\sessions.py", line 578, in post
    return self.request('POST', url, data=data, json=json, **kwargs)
  File "D:\scripts\py\lib\site-packages\requests\sessions.py", line 530, in request
    resp = self.send(prep, **send_kwargs)
  File "D:\scripts\py\lib\site-packages\requests\sessions.py", line 643, in send
    r = adapter.send(request, **kwargs)
  File "D:\scripts\py\lib\site-packages\requests\adapters.py", line 516, in send
    raise ConnectionError(e, request=request)
requests.exceptions.ConnectionError: HTTPSConnectionPool(host='10.17.84.221', port=4343): Max retries exceeded with url: /v1/api/login (Caused by NewConnectionError('<urllib3.connection.HTTPSConnection object at 0x000002A937FFA5F8>: Failed to establish a new connection: [WinError 10060] A connection attempt failed because the connected party did not properly respond after a period of time, or established connection failed because connected host has failed to respond'))
2020-09-14 21:18:19,800 > ERROR > ERROR:NaaS-VMC-1-10.17.84.221:4343 : Auto detect alternative partition failed
2020-09-14 21:18:19,817 > DEBUG > ERROR:NaaS-VMC-1-10.17.84.221:4343 : Auto detect alternative partition failed
2020-09-14 21:18:19,833 > ERROR > Auto detect alternative partition failed
Traceback (most recent call last):
  File "D:\scripts\GIT\Aruba_Controller_upgrade\Aruba_Wireless_Upgrade_APP.py", line 283, in find_alternative_partition
    out = cmd_out.get("show boot")
AttributeError: 'NoneType' object has no attribute 'get'
2020-09-14 21:18:19,880 > INFO > INFO:Precheck started for : (MM) NaaS-MM-1:10.17.84.220:4343
2020-09-14 21:18:40,899 > ERROR > ERROR:Login error : 10.17.84.220:4343
2020-09-14 21:18:40,914 > DEBUG > ERROR:Login error : 10.17.84.220:4343
2020-09-14 21:18:40,929 > ERROR > Login error:10.17.84.220:4343 
Traceback (most recent call last):
  File "D:\scripts\py\lib\site-packages\urllib3\connection.py", line 160, in _new_conn
    (self._dns_host, self.port), self.timeout, **extra_kw
  File "D:\scripts\py\lib\site-packages\urllib3\util\connection.py", line 84, in create_connection
    raise err
  File "D:\scripts\py\lib\site-packages\urllib3\util\connection.py", line 74, in create_connection
    sock.connect(sa)
TimeoutError: [WinError 10060] A connection attempt failed because the connected party did not properly respond after a period of time, or established connection failed because connected host has failed to respond

During handling of the above exception, another exception occurred:

Traceback (most recent call last):
  File "D:\scripts\py\lib\site-packages\urllib3\connectionpool.py", line 677, in urlopen
    chunked=chunked,
  File "D:\scripts\py\lib\site-packages\urllib3\connectionpool.py", line 381, in _make_request
    self._validate_conn(conn)
  File "D:\scripts\py\lib\site-packages\urllib3\connectionpool.py", line 976, in _validate_conn
    conn.connect()
  File "D:\scripts\py\lib\site-packages\urllib3\connection.py", line 308, in connect
    conn = self._new_conn()
  File "D:\scripts\py\lib\site-packages\urllib3\connection.py", line 172, in _new_conn
    self, "Failed to establish a new connection: %s" % e
urllib3.exceptions.NewConnectionError: <urllib3.connection.HTTPSConnection object at 0x000002A93802CB38>: Failed to establish a new connection: [WinError 10060] A connection attempt failed because the connected party did not properly respond after a period of time, or established connection failed because connected host has failed to respond

During handling of the above exception, another exception occurred:

Traceback (most recent call last):
  File "D:\scripts\py\lib\site-packages\requests\adapters.py", line 449, in send
    timeout=timeout
  File "D:\scripts\py\lib\site-packages\urllib3\connectionpool.py", line 725, in urlopen
    method, url, error=e, _pool=self, _stacktrace=sys.exc_info()[2]
  File "D:\scripts\py\lib\site-packages\urllib3\util\retry.py", line 439, in increment
    raise MaxRetryError(_pool, url, error or ResponseError(cause))
urllib3.exceptions.MaxRetryError: HTTPSConnectionPool(host='10.17.84.220', port=4343): Max retries exceeded with url: /v1/api/login (Caused by NewConnectionError('<urllib3.connection.HTTPSConnection object at 0x000002A93802CB38>: Failed to establish a new connection: [WinError 10060] A connection attempt failed because the connected party did not properly respond after a period of time, or established connection failed because connected host has failed to respond'))

During handling of the above exception, another exception occurred:

Traceback (most recent call last):
  File "D:\scripts\GIT\Aruba_Controller_upgrade\Aruba_Wireless_Upgrade_APP.py", line 100, in get_session
    res = r_session.post(login_url, data = login_post,verify=False)
  File "D:\scripts\py\lib\site-packages\requests\sessions.py", line 578, in post
    return self.request('POST', url, data=data, json=json, **kwargs)
  File "D:\scripts\py\lib\site-packages\requests\sessions.py", line 530, in request
    resp = self.send(prep, **send_kwargs)
  File "D:\scripts\py\lib\site-packages\requests\sessions.py", line 643, in send
    r = adapter.send(request, **kwargs)
  File "D:\scripts\py\lib\site-packages\requests\adapters.py", line 516, in send
    raise ConnectionError(e, request=request)
requests.exceptions.ConnectionError: HTTPSConnectionPool(host='10.17.84.220', port=4343): Max retries exceeded with url: /v1/api/login (Caused by NewConnectionError('<urllib3.connection.HTTPSConnection object at 0x000002A93802CB38>: Failed to establish a new connection: [WinError 10060] A connection attempt failed because the connected party did not properly respond after a period of time, or established connection failed because connected host has failed to respond'))
2020-09-14 21:18:40,930 > ERROR > ERROR:Precheck failed for => NaaS-MM-1:10.17.84.220:4343
2020-09-14 21:18:40,944 > DEBUG > ERROR:Precheck failed for => NaaS-MM-1:10.17.84.220:4343
2020-09-14 21:18:41,002 > INFO > INFO:Precheck started for : (MD) NaaS-VMC-1:10.17.84.221:4343
2020-09-14 21:19:02,023 > ERROR > ERROR:Login error : 10.17.84.221:4343
2020-09-14 21:19:02,042 > DEBUG > ERROR:Login error : 10.17.84.221:4343
2020-09-14 21:19:02,058 > ERROR > Login error:10.17.84.221:4343 
Traceback (most recent call last):
  File "D:\scripts\py\lib\site-packages\urllib3\connection.py", line 160, in _new_conn
    (self._dns_host, self.port), self.timeout, **extra_kw
  File "D:\scripts\py\lib\site-packages\urllib3\util\connection.py", line 84, in create_connection
    raise err
  File "D:\scripts\py\lib\site-packages\urllib3\util\connection.py", line 74, in create_connection
    sock.connect(sa)
TimeoutError: [WinError 10060] A connection attempt failed because the connected party did not properly respond after a period of time, or established connection failed because connected host has failed to respond

During handling of the above exception, another exception occurred:

Traceback (most recent call last):
  File "D:\scripts\py\lib\site-packages\urllib3\connectionpool.py", line 677, in urlopen
    chunked=chunked,
  File "D:\scripts\py\lib\site-packages\urllib3\connectionpool.py", line 381, in _make_request
    self._validate_conn(conn)
  File "D:\scripts\py\lib\site-packages\urllib3\connectionpool.py", line 976, in _validate_conn
    conn.connect()
  File "D:\scripts\py\lib\site-packages\urllib3\connection.py", line 308, in connect
    conn = self._new_conn()
  File "D:\scripts\py\lib\site-packages\urllib3\connection.py", line 172, in _new_conn
    self, "Failed to establish a new connection: %s" % e
urllib3.exceptions.NewConnectionError: <urllib3.connection.HTTPSConnection object at 0x000002A93803BA90>: Failed to establish a new connection: [WinError 10060] A connection attempt failed because the connected party did not properly respond after a period of time, or established connection failed because connected host has failed to respond

During handling of the above exception, another exception occurred:

Traceback (most recent call last):
  File "D:\scripts\py\lib\site-packages\requests\adapters.py", line 449, in send
    timeout=timeout
  File "D:\scripts\py\lib\site-packages\urllib3\connectionpool.py", line 725, in urlopen
    method, url, error=e, _pool=self, _stacktrace=sys.exc_info()[2]
  File "D:\scripts\py\lib\site-packages\urllib3\util\retry.py", line 439, in increment
    raise MaxRetryError(_pool, url, error or ResponseError(cause))
urllib3.exceptions.MaxRetryError: HTTPSConnectionPool(host='10.17.84.221', port=4343): Max retries exceeded with url: /v1/api/login (Caused by NewConnectionError('<urllib3.connection.HTTPSConnection object at 0x000002A93803BA90>: Failed to establish a new connection: [WinError 10060] A connection attempt failed because the connected party did not properly respond after a period of time, or established connection failed because connected host has failed to respond'))

During handling of the above exception, another exception occurred:

Traceback (most recent call last):
  File "D:\scripts\GIT\Aruba_Controller_upgrade\Aruba_Wireless_Upgrade_APP.py", line 100, in get_session
    res = r_session.post(login_url, data = login_post,verify=False)
  File "D:\scripts\py\lib\site-packages\requests\sessions.py", line 578, in post
    return self.request('POST', url, data=data, json=json, **kwargs)
  File "D:\scripts\py\lib\site-packages\requests\sessions.py", line 530, in request
    resp = self.send(prep, **send_kwargs)
  File "D:\scripts\py\lib\site-packages\requests\sessions.py", line 643, in send
    r = adapter.send(request, **kwargs)
  File "D:\scripts\py\lib\site-packages\requests\adapters.py", line 516, in send
    raise ConnectionError(e, request=request)
requests.exceptions.ConnectionError: HTTPSConnectionPool(host='10.17.84.221', port=4343): Max retries exceeded with url: /v1/api/login (Caused by NewConnectionError('<urllib3.connection.HTTPSConnection object at 0x000002A93803BA90>: Failed to establish a new connection: [WinError 10060] A connection attempt failed because the connected party did not properly respond after a period of time, or established connection failed because connected host has failed to respond'))
2020-09-14 21:19:02,061 > ERROR > ERROR:Precheck failed for => NaaS-VMC-1:10.17.84.221:4343
2020-09-14 21:19:02,079 > DEBUG > ERROR:Precheck failed for => NaaS-VMC-1:10.17.84.221:4343
2020-09-14 21:19:02,114 > INFO > INFO:Precheck Completed
2020-09-14 21:19:22,173 > INFO > INFO:Total upgrade hosts:2
2020-09-14 21:19:22,199 > INFO > INFO:MM: Preparing for host NaaS-MM-1 IP: 10.17.84.220:4343
2020-09-14 21:19:30,264 > WARNING > WARNING:User aborted to install : Do you want to install: Image Version:8.6.0.5-75979 on Disk:None Host:NaaS-MM-1:10.17.84.220:4343
2020-09-14 21:19:30,281 > DEBUG > WARNING:User aborted to install : Do you want to install: Image Version:8.6.0.5-75979 on Disk:None Host:NaaS-MM-1:10.17.84.220:4343
2020-09-14 21:19:34,654 > INFO > INFO:Login Success => 10.17.84.220:4343
2020-09-14 21:19:38,234 > ERROR > validate_image_upload
Traceback (most recent call last):
  File "D:\scripts\GIT\Aruba_Controller_upgrade\Aruba_Wireless_Upgrade_APP.py", line 456, in validate_image_upload
    if int(disk) == int(first_partition):
TypeError: int() argument must be a string, a bytes-like object or a number, not 'NoneType'
2020-09-14 21:19:38,234 > INFO > INFO:User accepted : Do you want to install: Image Version:8.6.0.5-75979 on Disk:None Host:NaaS-MM-1:10.17.84.220:4343
2020-09-14 21:19:39,226 > INFO > INFO:Session Valid : 10.17.84.220:4343
2020-09-14 21:19:39,263 > INFO > INFO:NaaS-MM-1:10.17.84.220:4343- Installing AOS: ArubaOS_MM_8.6.0.5_75979 from ftp server:10.17.84.225
2020-09-14 21:20:21,975 > INFO > JOBNAME:1600098621_9565606
2020-09-14 21:20:21,975 > INFO > CONFIG FILE:D:\scripts\GIT\Aruba_Controller_upgrade\conf_files\LAB WIRELESS UPGRADE
2020-09-14 21:20:22,042 > INFO > Starting Job
2020-09-14 21:20:22,057 > INFO > INFO:Running: 1600098621_9565606 Type:precheck,all
2020-09-14 21:20:22,074 > INFO > INFO:Starting Configuration LAB WIRELESS UPGRADE Validation
2020-09-14 21:20:22,110 > INFO > Inserting upgrade list to upgrade.db
2020-09-14 21:20:24,161 > INFO > yes
2020-09-14 21:20:24,161 > INFO > INFO:Starting precheck
2020-09-14 21:20:24,176 > INFO > INFO:Executing Precheck
2020-09-14 21:20:24,210 > INFO > INFO:Installation Disk Auto not provided for 10.17.84.220:4343 , Trying to auto detect
2020-09-14 21:20:27,685 > INFO > INFO:Login Success => 10.17.84.220:4343
2020-09-14 21:20:31,203 > INFO > INFO:NaaS-MM-1-10.17.84.220:4343 :Auto detect alternative partition: 1
2020-09-14 21:20:31,265 > INFO > INFO:Installation Disk Auto not provided for 10.17.84.221:4343 , Trying to auto detect
2020-09-14 21:20:36,100 > DEBUG > DEBUG:b'<html>  <script>  top.(null)("<re><SUCCESS>10.17.84.225</SUCCESS></re>", "image");  </script></html>'
2020-09-14 21:20:36,147 > INFO > INFO:File copy completed COMPLETED: UPLOADED IMAGE TO DISK None ArubaOS_MM_8.6.0.5_75979
2020-09-14 21:20:36,165 > INFO > b'<html>  <script>  top.(null)("<re><SUCCESS>10.17.84.225</SUCCESS></re>", "image");  </script></html>'
2020-09-14 21:20:36,182 > INFO > INFO:MD: Preparing for host NaaS-VMC-1 IP: 10.17.84.221:4343
2020-09-14 21:20:38,027 > INFO > INFO:Login Success => 10.17.84.221:4343
2020-09-14 21:20:41,580 > INFO > INFO:NaaS-VMC-1-10.17.84.221:4343 :Auto detect alternative partition: 1
2020-09-14 21:20:41,663 > INFO > INFO:Precheck started for : (MM) NaaS-MM-1:10.17.84.220:4343
2020-09-14 21:20:43,807 > INFO > INFO:Session Valid : 10.17.84.220:4343
2020-09-14 21:20:43,888 > INFO > INFO:Executing NaaS-MM-1 - 10.17.84.220:4343 => show clock
2020-09-14 21:20:44,909 > INFO > INFO:Executing NaaS-MM-1 - 10.17.84.220:4343 => show version
2020-09-14 21:20:45,966 > INFO > INFO:Executing NaaS-MM-1 - 10.17.84.220:4343 => show image version
2020-09-14 21:20:46,967 > INFO > INFO:Executing NaaS-MM-1 - 10.17.84.220:4343 => show storage
2020-09-14 21:20:47,981 > INFO > INFO:Executing NaaS-MM-1 - 10.17.84.220:4343 => show cpuload
2020-09-14 21:20:49,005 > INFO > INFO:Executing NaaS-MM-1 - 10.17.84.220:4343 => show memory
2020-09-14 21:20:50,045 > INFO > INFO:Executing NaaS-MM-1 - 10.17.84.220:4343 => show boot
2020-09-14 21:20:51,078 > INFO > INFO:Executing NaaS-MM-1 - 10.17.84.220:4343 => show switches
2020-09-14 21:20:52,859 > INFO > INFO:Executing NaaS-MM-1 - 10.17.84.220:4343 => show switchinfo
2020-09-14 21:20:53,923 > INFO > INFO:Executing NaaS-MM-1 - 10.17.84.220:4343 => show boot history
2020-09-14 21:20:54,268 > WARNING > WARNING:User aborted to install : Do you want to install: Image Version:8.5.0.10-76207 on Disk:None Host:NaaS-VMC-1:10.17.84.221:4343
2020-09-14 21:20:54,282 > DEBUG > WARNING:User aborted to install : Do you want to install: Image Version:8.5.0.10-76207 on Disk:None Host:NaaS-VMC-1:10.17.84.221:4343
2020-09-14 21:20:56,144 > INFO > INFO:Executing NaaS-MM-1 - 10.17.84.220:4343 => show crypto ipsec sa
2020-09-14 21:20:57,126 > INFO > INFO:Executing NaaS-MM-1 - 10.17.84.220:4343 => show master-redundancy
2020-09-14 21:20:57,800 > INFO > INFO:Login Success => 10.17.84.221:4343
2020-09-14 21:20:58,761 > INFO > INFO:Executing NaaS-MM-1 - 10.17.84.220:4343 => show database synchronize
2020-09-14 21:21:00,637 > INFO > INFO:Executing NaaS-MM-1 - 10.17.84.220:4343 => show license
2020-09-14 21:21:01,460 > ERROR > validate_image_upload
Traceback (most recent call last):
  File "D:\scripts\GIT\Aruba_Controller_upgrade\Aruba_Wireless_Upgrade_APP.py", line 456, in validate_image_upload
    if int(disk) == int(first_partition):
TypeError: int() argument must be a string, a bytes-like object or a number, not 'NoneType'
2020-09-14 21:21:01,460 > INFO > INFO:User accepted : Do you want to install: Image Version:8.5.0.10-76207 on Disk:None Host:NaaS-VMC-1:10.17.84.221:4343
2020-09-14 21:21:01,670 > INFO > INFO:Executing NaaS-MM-1 - 10.17.84.220:4343 => show running-config
2020-09-14 21:21:02,506 > INFO > INFO:Session Valid : 10.17.84.221:4343
2020-09-14 21:21:03,880 > INFO > INFO:NaaS-VMC-1:10.17.84.221:4343- Installing AOS: ArubaOS_VMC_8.5.0.10-FIPS_76207 from ftp server:10.17.84.225
2020-09-14 21:21:06,678 > INFO > INFO:Precheck started for : (MD) NaaS-VMC-1:10.17.84.221:4343
2020-09-14 21:21:10,194 > INFO > INFO:Session Valid : 10.17.84.221:4343
2020-09-14 21:21:11,222 > INFO > INFO:Executing NaaS-VMC-1 - 10.17.84.221:4343 => show clock
2020-09-14 21:21:12,242 > INFO > INFO:Executing NaaS-VMC-1 - 10.17.84.221:4343 => show version
2020-09-14 21:21:13,851 > INFO > INFO:Executing NaaS-VMC-1 - 10.17.84.221:4343 => show image version
2020-09-14 21:21:15,685 > INFO > INFO:Executing NaaS-VMC-1 - 10.17.84.221:4343 => show storage
2020-09-14 21:21:17,278 > INFO > INFO:Executing NaaS-VMC-1 - 10.17.84.221:4343 => show cpuload
2020-09-14 21:21:18,380 > INFO > INFO:Executing NaaS-VMC-1 - 10.17.84.221:4343 => show memory
2020-09-14 21:21:19,464 > INFO > INFO:Executing NaaS-VMC-1 - 10.17.84.221:4343 => show boot
2020-09-14 21:21:20,513 > INFO > INFO:Executing NaaS-VMC-1 - 10.17.84.221:4343 => show switches
2020-09-14 21:21:21,529 > INFO > INFO:Executing NaaS-VMC-1 - 10.17.84.221:4343 => show switchinfo
2020-09-14 21:21:22,585 > INFO > INFO:Executing NaaS-VMC-1 - 10.17.84.221:4343 => show boot history
2020-09-14 21:21:29,142 > INFO > INFO:Executing NaaS-VMC-1 - 10.17.84.221:4343 => show user
2020-09-14 21:21:30,101 > INFO > INFO:Executing NaaS-VMC-1 - 10.17.84.221:4343 => show ap database long
2020-09-14 21:21:31,066 > INFO > INFO:Executing NaaS-VMC-1 - 10.17.84.221:4343 => show ap bss-table
2020-09-14 21:21:32,629 > INFO > INFO:Executing NaaS-VMC-1 - 10.17.84.221:4343 => show ap essid
2020-09-14 21:21:33,606 > INFO > INFO:Executing NaaS-VMC-1 - 10.17.84.221:4343 => show ap active counters
2020-09-14 21:21:34,631 > INFO > INFO:Executing NaaS-VMC-1 - 10.17.84.221:4343 => show ap debug counters
2020-09-14 21:21:35,653 > INFO > INFO:Executing NaaS-VMC-1 - 10.17.84.221:4343 => show lc-cluster group-membership
2020-09-14 21:21:36,626 > INFO > INFO:Executing NaaS-VMC-1 - 10.17.84.221:4343 => show switches
2020-09-14 21:21:37,866 > INFO > INFO:Executing NaaS-VMC-1 - 10.17.84.221:4343 => show license
2020-09-14 21:21:38,836 > INFO > INFO:Executing NaaS-VMC-1 - 10.17.84.221:4343 => show running-config
2020-09-14 21:21:45,187 > INFO > INFO:Executing NaaS-VMC-1 - 10.17.84.221:4343 => show boot
2020-09-14 21:21:46,202 > INFO > INFO:Executing NaaS-VMC-1 - 10.17.84.221:4343 => show version
2020-09-14 21:21:47,189 > INFO > INFO:Precheck Completed
2020-09-14 21:21:53,241 > INFO > INFO:Total upgrade hosts:2
2020-09-14 21:21:53,264 > INFO > INFO:MM: Preparing for host NaaS-MM-1 IP: 10.17.84.220:4343
2020-09-14 21:21:59,369 > WARNING > WARNING:User aborted to install : Do you want to install: Image Version:8.6.0.5-75979 on Disk:1 Host:NaaS-MM-1:10.17.84.220:4343
2020-09-14 21:21:59,386 > DEBUG > WARNING:User aborted to install : Do you want to install: Image Version:8.6.0.5-75979 on Disk:1 Host:NaaS-MM-1:10.17.84.220:4343
2020-09-14 21:22:02,646 > INFO > INFO:Session Valid : 10.17.84.220:4343
2020-09-14 21:22:04,054 > DEBUG > SUCCESS:New Image Installed for (MM) Host:NaaS-MM-1:10.17.84.220:4343 Disk:1 Version:8.6.0.5 Build:75979
2020-09-14 21:22:04,995 > INFO > INFO:MD: Preparing for host NaaS-VMC-1 IP: 10.17.84.221:4343
2020-09-14 21:22:13,061 > WARNING > WARNING:User aborted to install : Do you want to install: Image Version:8.5.0.10-76207 on Disk:1 Host:NaaS-VMC-1:10.17.84.221:4343
2020-09-14 21:22:13,080 > DEBUG > WARNING:User aborted to install : Do you want to install: Image Version:8.5.0.10-76207 on Disk:1 Host:NaaS-VMC-1:10.17.84.221:4343
2020-09-14 21:22:16,452 > INFO > INFO:Session Valid : 10.17.84.221:4343
2020-09-14 21:22:17,687 > DEBUG > SUCCESS:New Image Installed for (MD) Host:NaaS-VMC-1:10.17.84.221:4343 Disk:1 Version:8.5.0.10 Build:76207
2020-09-14 21:22:28,835 > WARNING > WARNING:Skipping AP's preimage....
2020-09-14 21:22:29,943 > DEBUG > WARNING:Skipping AP's preimage....
2020-09-14 21:22:29,962 > INFO > INFO:Starting Upgrade
2020-09-14 21:22:36,000 > INFO > no
2020-09-14 21:22:36,000 > WARNING > WARNING:TERMINATED User aborted the postcheck
2020-09-14 21:22:37,059 > DEBUG > WARNING:TERMINATED User aborted the postcheck
2020-09-14 21:22:37,128 > INFO > INFO:==== Completed ====
2020-09-14 21:22:42,291 > DEBUG > DEBUG:b'<html>  <script>  top.(null)("<re><SUCCESS>10.17.84.225</SUCCESS></re>", "image");  </script></html>'
2020-09-14 21:22:42,362 > INFO > INFO:File copy completed COMPLETED: UPLOADED IMAGE TO DISK None ArubaOS_VMC_8.5.0.10-FIPS_76207
2020-09-14 21:22:42,377 > INFO > b'<html>  <script>  top.(null)("<re><SUCCESS>10.17.84.225</SUCCESS></re>", "image");  </script></html>'
2020-09-14 21:22:42,390 > WARNING > WARNING:Job Terminated by user
2020-09-14 21:22:42,404 > DEBUG > WARNING:Job Terminated by user
2020-09-14 21:22:42,433 > INFO > INFO:==== Completed ====
2020-09-14 21:22:42,460 > INFO > INFO:==== Completed ====
