2020-10-26 21:01:49,853 > INFO > JOBNAME:1603726309_8236785
2020-10-26 21:01:49,854 > INFO > CONFIG FILE:D:\scripts\GIT\Aruba_Controller_upgrade\conf_files\LAB WIRELESS UPGRADE 8.5
2020-10-26 21:01:50,055 > INFO > Starting Job
2020-10-26 21:01:50,083 > INFO > INFO:Running: 1603726309_8236785 Type:precheck
2020-10-26 21:01:50,107 > INFO > INFO:Starting Configuration LAB WIRELESS UPGRADE 8.5 Validation
2020-10-26 21:01:50,143 > INFO > Inserting upgrade list to upgrade.db
2020-10-26 21:01:54,225 > INFO > yes
2020-10-26 21:01:54,226 > INFO > INFO:Starting precheck
2020-10-26 21:01:54,246 > INFO > INFO:Executing Precheck
2020-10-26 21:02:15,307 > ERROR > ERROR:Login error : 10.17.84.220:4343
2020-10-26 21:02:15,330 > DEBUG > ERROR:Login error : 10.17.84.220:4343
2020-10-26 21:02:15,348 > ERROR > Login error:10.17.84.220:4343 
Traceback (most recent call last):
  File "D:\scripts\py\lib\site-packages\urllib3\connection.py", line 160, in _new_conn
    (self._dns_host, self.port), self.timeout, **extra_kw
  File "D:\scripts\py\lib\site-packages\urllib3\util\connection.py", line 84, in create_connection
    raise err
  File "D:\scripts\py\lib\site-packages\urllib3\util\connection.py", line 74, in create_connection
    sock.connect(sa)
TimeoutError: [WinError 10060] A connection attempt failed because the connected party did not properly respond after a period of time, or established connection failed because connected host has failed to respond

During handling of the above exception, another exception occurred:

Traceback (most recent call last):
  File "D:\scripts\py\lib\site-packages\urllib3\connectionpool.py", line 677, in urlopen
    chunked=chunked,
  File "D:\scripts\py\lib\site-packages\urllib3\connectionpool.py", line 381, in _make_request
    self._validate_conn(conn)
  File "D:\scripts\py\lib\site-packages\urllib3\connectionpool.py", line 976, in _validate_conn
    conn.connect()
  File "D:\scripts\py\lib\site-packages\urllib3\connection.py", line 308, in connect
    conn = self._new_conn()
  File "D:\scripts\py\lib\site-packages\urllib3\connection.py", line 172, in _new_conn
    self, "Failed to establish a new connection: %s" % e
urllib3.exceptions.NewConnectionError: <urllib3.connection.HTTPSConnection object at 0x000001BA307F4278>: Failed to establish a new connection: [WinError 10060] A connection attempt failed because the connected party did not properly respond after a period of time, or established connection failed because connected host has failed to respond

During handling of the above exception, another exception occurred:

Traceback (most recent call last):
  File "D:\scripts\py\lib\site-packages\requests\adapters.py", line 449, in send
    timeout=timeout
  File "D:\scripts\py\lib\site-packages\urllib3\connectionpool.py", line 725, in urlopen
    method, url, error=e, _pool=self, _stacktrace=sys.exc_info()[2]
  File "D:\scripts\py\lib\site-packages\urllib3\util\retry.py", line 439, in increment
    raise MaxRetryError(_pool, url, error or ResponseError(cause))
urllib3.exceptions.MaxRetryError: HTTPSConnectionPool(host='10.17.84.220', port=4343): Max retries exceeded with url: /v1/api/login (Caused by NewConnectionError('<urllib3.connection.HTTPSConnection object at 0x000001BA307F4278>: Failed to establish a new connection: [WinError 10060] A connection attempt failed because the connected party did not properly respond after a period of time, or established connection failed because connected host has failed to respond'))

During handling of the above exception, another exception occurred:

Traceback (most recent call last):
  File "D:\scripts\GIT\Aruba_Controller_upgrade\Aruba_Wireless_Upgrade_APP.py", line 105, in get_session
    res = r_session.post(login_url, data = login_post,verify=False)
  File "D:\scripts\py\lib\site-packages\requests\sessions.py", line 578, in post
    return self.request('POST', url, data=data, json=json, **kwargs)
  File "D:\scripts\py\lib\site-packages\requests\sessions.py", line 530, in request
    resp = self.send(prep, **send_kwargs)
  File "D:\scripts\py\lib\site-packages\requests\sessions.py", line 643, in send
    r = adapter.send(request, **kwargs)
  File "D:\scripts\py\lib\site-packages\requests\adapters.py", line 516, in send
    raise ConnectionError(e, request=request)
requests.exceptions.ConnectionError: HTTPSConnectionPool(host='10.17.84.220', port=4343): Max retries exceeded with url: /v1/api/login (Caused by NewConnectionError('<urllib3.connection.HTTPSConnection object at 0x000001BA307F4278>: Failed to establish a new connection: [WinError 10060] A connection attempt failed because the connected party did not properly respond after a period of time, or established connection failed because connected host has failed to respond'))
2020-10-26 21:02:15,356 > ERROR > get_version
Traceback (most recent call last):
  File "D:\scripts\GIT\Aruba_Controller_upgrade\wireless_validation.py", line 33, in validating_login
    _version = cmd_out.get("show clock")
AttributeError: 'tuple' object has no attribute 'get'
2020-10-26 21:02:36,389 > ERROR > ERROR:Login error : 10.17.84.221:4343
2020-10-26 21:02:36,410 > DEBUG > ERROR:Login error : 10.17.84.221:4343
2020-10-26 21:02:36,431 > ERROR > Login error:10.17.84.221:4343 
Traceback (most recent call last):
  File "D:\scripts\py\lib\site-packages\urllib3\connection.py", line 160, in _new_conn
    (self._dns_host, self.port), self.timeout, **extra_kw
  File "D:\scripts\py\lib\site-packages\urllib3\util\connection.py", line 84, in create_connection
    raise err
  File "D:\scripts\py\lib\site-packages\urllib3\util\connection.py", line 74, in create_connection
    sock.connect(sa)
TimeoutError: [WinError 10060] A connection attempt failed because the connected party did not properly respond after a period of time, or established connection failed because connected host has failed to respond

During handling of the above exception, another exception occurred:

Traceback (most recent call last):
  File "D:\scripts\py\lib\site-packages\urllib3\connectionpool.py", line 677, in urlopen
    chunked=chunked,
  File "D:\scripts\py\lib\site-packages\urllib3\connectionpool.py", line 381, in _make_request
    self._validate_conn(conn)
  File "D:\scripts\py\lib\site-packages\urllib3\connectionpool.py", line 976, in _validate_conn
    conn.connect()
  File "D:\scripts\py\lib\site-packages\urllib3\connection.py", line 308, in connect
    conn = self._new_conn()
  File "D:\scripts\py\lib\site-packages\urllib3\connection.py", line 172, in _new_conn
    self, "Failed to establish a new connection: %s" % e
urllib3.exceptions.NewConnectionError: <urllib3.connection.HTTPSConnection object at 0x000001BA308829B0>: Failed to establish a new connection: [WinError 10060] A connection attempt failed because the connected party did not properly respond after a period of time, or established connection failed because connected host has failed to respond

During handling of the above exception, another exception occurred:

Traceback (most recent call last):
  File "D:\scripts\py\lib\site-packages\requests\adapters.py", line 449, in send
    timeout=timeout
  File "D:\scripts\py\lib\site-packages\urllib3\connectionpool.py", line 725, in urlopen
    method, url, error=e, _pool=self, _stacktrace=sys.exc_info()[2]
  File "D:\scripts\py\lib\site-packages\urllib3\util\retry.py", line 439, in increment
    raise MaxRetryError(_pool, url, error or ResponseError(cause))
urllib3.exceptions.MaxRetryError: HTTPSConnectionPool(host='10.17.84.221', port=4343): Max retries exceeded with url: /v1/api/login (Caused by NewConnectionError('<urllib3.connection.HTTPSConnection object at 0x000001BA308829B0>: Failed to establish a new connection: [WinError 10060] A connection attempt failed because the connected party did not properly respond after a period of time, or established connection failed because connected host has failed to respond'))

During handling of the above exception, another exception occurred:

Traceback (most recent call last):
  File "D:\scripts\GIT\Aruba_Controller_upgrade\Aruba_Wireless_Upgrade_APP.py", line 105, in get_session
    res = r_session.post(login_url, data = login_post,verify=False)
  File "D:\scripts\py\lib\site-packages\requests\sessions.py", line 578, in post
    return self.request('POST', url, data=data, json=json, **kwargs)
  File "D:\scripts\py\lib\site-packages\requests\sessions.py", line 530, in request
    resp = self.send(prep, **send_kwargs)
  File "D:\scripts\py\lib\site-packages\requests\sessions.py", line 643, in send
    r = adapter.send(request, **kwargs)
  File "D:\scripts\py\lib\site-packages\requests\adapters.py", line 516, in send
    raise ConnectionError(e, request=request)
requests.exceptions.ConnectionError: HTTPSConnectionPool(host='10.17.84.221', port=4343): Max retries exceeded with url: /v1/api/login (Caused by NewConnectionError('<urllib3.connection.HTTPSConnection object at 0x000001BA308829B0>: Failed to establish a new connection: [WinError 10060] A connection attempt failed because the connected party did not properly respond after a period of time, or established connection failed because connected host has failed to respond'))
2020-10-26 21:02:36,432 > ERROR > get_version
Traceback (most recent call last):
  File "D:\scripts\GIT\Aruba_Controller_upgrade\wireless_validation.py", line 33, in validating_login
    _version = cmd_out.get("show clock")
AttributeError: 'tuple' object has no attribute 'get'
2020-10-26 21:02:57,478 > ERROR > ERROR:Login error : 10.17.84.220:4343
2020-10-26 21:02:57,738 > DEBUG > ERROR:Login error : 10.17.84.220:4343
2020-10-26 21:02:57,770 > ERROR > Login error:10.17.84.220:4343 
Traceback (most recent call last):
  File "D:\scripts\py\lib\site-packages\urllib3\connection.py", line 160, in _new_conn
    (self._dns_host, self.port), self.timeout, **extra_kw
  File "D:\scripts\py\lib\site-packages\urllib3\util\connection.py", line 84, in create_connection
    raise err
  File "D:\scripts\py\lib\site-packages\urllib3\util\connection.py", line 74, in create_connection
    sock.connect(sa)
TimeoutError: [WinError 10060] A connection attempt failed because the connected party did not properly respond after a period of time, or established connection failed because connected host has failed to respond

During handling of the above exception, another exception occurred:

Traceback (most recent call last):
  File "D:\scripts\py\lib\site-packages\urllib3\connectionpool.py", line 677, in urlopen
    chunked=chunked,
  File "D:\scripts\py\lib\site-packages\urllib3\connectionpool.py", line 381, in _make_request
    self._validate_conn(conn)
  File "D:\scripts\py\lib\site-packages\urllib3\connectionpool.py", line 976, in _validate_conn
    conn.connect()
  File "D:\scripts\py\lib\site-packages\urllib3\connection.py", line 308, in connect
    conn = self._new_conn()
  File "D:\scripts\py\lib\site-packages\urllib3\connection.py", line 172, in _new_conn
    self, "Failed to establish a new connection: %s" % e
urllib3.exceptions.NewConnectionError: <urllib3.connection.HTTPSConnection object at 0x000001BA308A06D8>: Failed to establish a new connection: [WinError 10060] A connection attempt failed because the connected party did not properly respond after a period of time, or established connection failed because connected host has failed to respond

During handling of the above exception, another exception occurred:

Traceback (most recent call last):
  File "D:\scripts\py\lib\site-packages\requests\adapters.py", line 449, in send
    timeout=timeout
  File "D:\scripts\py\lib\site-packages\urllib3\connectionpool.py", line 725, in urlopen
    method, url, error=e, _pool=self, _stacktrace=sys.exc_info()[2]
  File "D:\scripts\py\lib\site-packages\urllib3\util\retry.py", line 439, in increment
    raise MaxRetryError(_pool, url, error or ResponseError(cause))
urllib3.exceptions.MaxRetryError: HTTPSConnectionPool(host='10.17.84.220', port=4343): Max retries exceeded with url: /v1/api/login (Caused by NewConnectionError('<urllib3.connection.HTTPSConnection object at 0x000001BA308A06D8>: Failed to establish a new connection: [WinError 10060] A connection attempt failed because the connected party did not properly respond after a period of time, or established connection failed because connected host has failed to respond'))

During handling of the above exception, another exception occurred:

Traceback (most recent call last):
  File "D:\scripts\GIT\Aruba_Controller_upgrade\Aruba_Wireless_Upgrade_APP.py", line 105, in get_session
    res = r_session.post(login_url, data = login_post,verify=False)
  File "D:\scripts\py\lib\site-packages\requests\sessions.py", line 578, in post
    return self.request('POST', url, data=data, json=json, **kwargs)
  File "D:\scripts\py\lib\site-packages\requests\sessions.py", line 530, in request
    resp = self.send(prep, **send_kwargs)
  File "D:\scripts\py\lib\site-packages\requests\sessions.py", line 643, in send
    r = adapter.send(request, **kwargs)
  File "D:\scripts\py\lib\site-packages\requests\adapters.py", line 516, in send
    raise ConnectionError(e, request=request)
requests.exceptions.ConnectionError: HTTPSConnectionPool(host='10.17.84.220', port=4343): Max retries exceeded with url: /v1/api/login (Caused by NewConnectionError('<urllib3.connection.HTTPSConnection object at 0x000001BA308A06D8>: Failed to establish a new connection: [WinError 10060] A connection attempt failed because the connected party did not properly respond after a period of time, or established connection failed because connected host has failed to respond'))
2020-10-26 21:03:18,817 > ERROR > ERROR:Login error : 10.17.84.221:4343
2020-10-26 21:03:19,093 > DEBUG > ERROR:Login error : 10.17.84.221:4343
2020-10-26 21:03:19,117 > ERROR > Login error:10.17.84.221:4343 
Traceback (most recent call last):
  File "D:\scripts\py\lib\site-packages\urllib3\connection.py", line 160, in _new_conn
    (self._dns_host, self.port), self.timeout, **extra_kw
  File "D:\scripts\py\lib\site-packages\urllib3\util\connection.py", line 84, in create_connection
    raise err
  File "D:\scripts\py\lib\site-packages\urllib3\util\connection.py", line 74, in create_connection
    sock.connect(sa)
TimeoutError: [WinError 10060] A connection attempt failed because the connected party did not properly respond after a period of time, or established connection failed because connected host has failed to respond

During handling of the above exception, another exception occurred:

Traceback (most recent call last):
  File "D:\scripts\py\lib\site-packages\urllib3\connectionpool.py", line 677, in urlopen
    chunked=chunked,
  File "D:\scripts\py\lib\site-packages\urllib3\connectionpool.py", line 381, in _make_request
    self._validate_conn(conn)
  File "D:\scripts\py\lib\site-packages\urllib3\connectionpool.py", line 976, in _validate_conn
    conn.connect()
  File "D:\scripts\py\lib\site-packages\urllib3\connection.py", line 308, in connect
    conn = self._new_conn()
  File "D:\scripts\py\lib\site-packages\urllib3\connection.py", line 172, in _new_conn
    self, "Failed to establish a new connection: %s" % e
urllib3.exceptions.NewConnectionError: <urllib3.connection.HTTPSConnection object at 0x000001BA308A0B00>: Failed to establish a new connection: [WinError 10060] A connection attempt failed because the connected party did not properly respond after a period of time, or established connection failed because connected host has failed to respond

During handling of the above exception, another exception occurred:

Traceback (most recent call last):
  File "D:\scripts\py\lib\site-packages\requests\adapters.py", line 449, in send
    timeout=timeout
  File "D:\scripts\py\lib\site-packages\urllib3\connectionpool.py", line 725, in urlopen
    method, url, error=e, _pool=self, _stacktrace=sys.exc_info()[2]
  File "D:\scripts\py\lib\site-packages\urllib3\util\retry.py", line 439, in increment
    raise MaxRetryError(_pool, url, error or ResponseError(cause))
urllib3.exceptions.MaxRetryError: HTTPSConnectionPool(host='10.17.84.221', port=4343): Max retries exceeded with url: /v1/api/login (Caused by NewConnectionError('<urllib3.connection.HTTPSConnection object at 0x000001BA308A0B00>: Failed to establish a new connection: [WinError 10060] A connection attempt failed because the connected party did not properly respond after a period of time, or established connection failed because connected host has failed to respond'))

During handling of the above exception, another exception occurred:

Traceback (most recent call last):
  File "D:\scripts\GIT\Aruba_Controller_upgrade\Aruba_Wireless_Upgrade_APP.py", line 105, in get_session
    res = r_session.post(login_url, data = login_post,verify=False)
  File "D:\scripts\py\lib\site-packages\requests\sessions.py", line 578, in post
    return self.request('POST', url, data=data, json=json, **kwargs)
  File "D:\scripts\py\lib\site-packages\requests\sessions.py", line 530, in request
    resp = self.send(prep, **send_kwargs)
  File "D:\scripts\py\lib\site-packages\requests\sessions.py", line 643, in send
    r = adapter.send(request, **kwargs)
  File "D:\scripts\py\lib\site-packages\requests\adapters.py", line 516, in send
    raise ConnectionError(e, request=request)
requests.exceptions.ConnectionError: HTTPSConnectionPool(host='10.17.84.221', port=4343): Max retries exceeded with url: /v1/api/login (Caused by NewConnectionError('<urllib3.connection.HTTPSConnection object at 0x000001BA308A0B00>: Failed to establish a new connection: [WinError 10060] A connection attempt failed because the connected party did not properly respond after a period of time, or established connection failed because connected host has failed to respond'))
2020-10-26 21:03:40,140 > ERROR > ERROR:Login error : 10.17.84.220:4343
2020-10-26 21:03:40,169 > DEBUG > ERROR:Login error : 10.17.84.220:4343
2020-10-26 21:03:40,188 > ERROR > Login error:10.17.84.220:4343 
Traceback (most recent call last):
  File "D:\scripts\py\lib\site-packages\urllib3\connection.py", line 160, in _new_conn
    (self._dns_host, self.port), self.timeout, **extra_kw
  File "D:\scripts\py\lib\site-packages\urllib3\util\connection.py", line 84, in create_connection
    raise err
  File "D:\scripts\py\lib\site-packages\urllib3\util\connection.py", line 74, in create_connection
    sock.connect(sa)
TimeoutError: [WinError 10060] A connection attempt failed because the connected party did not properly respond after a period of time, or established connection failed because connected host has failed to respond

During handling of the above exception, another exception occurred:

Traceback (most recent call last):
  File "D:\scripts\py\lib\site-packages\urllib3\connectionpool.py", line 677, in urlopen
    chunked=chunked,
  File "D:\scripts\py\lib\site-packages\urllib3\connectionpool.py", line 381, in _make_request
    self._validate_conn(conn)
  File "D:\scripts\py\lib\site-packages\urllib3\connectionpool.py", line 976, in _validate_conn
    conn.connect()
  File "D:\scripts\py\lib\site-packages\urllib3\connection.py", line 308, in connect
    conn = self._new_conn()
  File "D:\scripts\py\lib\site-packages\urllib3\connection.py", line 172, in _new_conn
    self, "Failed to establish a new connection: %s" % e
urllib3.exceptions.NewConnectionError: <urllib3.connection.HTTPSConnection object at 0x000001BA308A9A20>: Failed to establish a new connection: [WinError 10060] A connection attempt failed because the connected party did not properly respond after a period of time, or established connection failed because connected host has failed to respond

During handling of the above exception, another exception occurred:

Traceback (most recent call last):
  File "D:\scripts\py\lib\site-packages\requests\adapters.py", line 449, in send
    timeout=timeout
  File "D:\scripts\py\lib\site-packages\urllib3\connectionpool.py", line 725, in urlopen
    method, url, error=e, _pool=self, _stacktrace=sys.exc_info()[2]
  File "D:\scripts\py\lib\site-packages\urllib3\util\retry.py", line 439, in increment
    raise MaxRetryError(_pool, url, error or ResponseError(cause))
urllib3.exceptions.MaxRetryError: HTTPSConnectionPool(host='10.17.84.220', port=4343): Max retries exceeded with url: /v1/api/login (Caused by NewConnectionError('<urllib3.connection.HTTPSConnection object at 0x000001BA308A9A20>: Failed to establish a new connection: [WinError 10060] A connection attempt failed because the connected party did not properly respond after a period of time, or established connection failed because connected host has failed to respond'))

During handling of the above exception, another exception occurred:

Traceback (most recent call last):
  File "D:\scripts\GIT\Aruba_Controller_upgrade\Aruba_Wireless_Upgrade_APP.py", line 105, in get_session
    res = r_session.post(login_url, data = login_post,verify=False)
  File "D:\scripts\py\lib\site-packages\requests\sessions.py", line 578, in post
    return self.request('POST', url, data=data, json=json, **kwargs)
  File "D:\scripts\py\lib\site-packages\requests\sessions.py", line 530, in request
    resp = self.send(prep, **send_kwargs)
  File "D:\scripts\py\lib\site-packages\requests\sessions.py", line 643, in send
    r = adapter.send(request, **kwargs)
  File "D:\scripts\py\lib\site-packages\requests\adapters.py", line 516, in send
    raise ConnectionError(e, request=request)
requests.exceptions.ConnectionError: HTTPSConnectionPool(host='10.17.84.220', port=4343): Max retries exceeded with url: /v1/api/login (Caused by NewConnectionError('<urllib3.connection.HTTPSConnection object at 0x000001BA308A9A20>: Failed to establish a new connection: [WinError 10060] A connection attempt failed because the connected party did not properly respond after a period of time, or established connection failed because connected host has failed to respond'))
2020-10-26 21:03:40,189 > ERROR > get_system_health
Traceback (most recent call last):
  File "D:\scripts\GIT\Aruba_Controller_upgrade\wireless_validation.py", line 174, in get_system_health
    if host_output.get("show storage") != None:
AttributeError: 'NoneType' object has no attribute 'get'
2020-10-26 21:04:01,209 > ERROR > ERROR:Login error : 10.17.84.221:4343
2020-10-26 21:04:01,231 > DEBUG > ERROR:Login error : 10.17.84.221:4343
2020-10-26 21:04:01,252 > ERROR > Login error:10.17.84.221:4343 
Traceback (most recent call last):
  File "D:\scripts\py\lib\site-packages\urllib3\connection.py", line 160, in _new_conn
    (self._dns_host, self.port), self.timeout, **extra_kw
  File "D:\scripts\py\lib\site-packages\urllib3\util\connection.py", line 84, in create_connection
    raise err
  File "D:\scripts\py\lib\site-packages\urllib3\util\connection.py", line 74, in create_connection
    sock.connect(sa)
TimeoutError: [WinError 10060] A connection attempt failed because the connected party did not properly respond after a period of time, or established connection failed because connected host has failed to respond

During handling of the above exception, another exception occurred:

Traceback (most recent call last):
  File "D:\scripts\py\lib\site-packages\urllib3\connectionpool.py", line 677, in urlopen
    chunked=chunked,
  File "D:\scripts\py\lib\site-packages\urllib3\connectionpool.py", line 381, in _make_request
    self._validate_conn(conn)
  File "D:\scripts\py\lib\site-packages\urllib3\connectionpool.py", line 976, in _validate_conn
    conn.connect()
  File "D:\scripts\py\lib\site-packages\urllib3\connection.py", line 308, in connect
    conn = self._new_conn()
  File "D:\scripts\py\lib\site-packages\urllib3\connection.py", line 172, in _new_conn
    self, "Failed to establish a new connection: %s" % e
urllib3.exceptions.NewConnectionError: <urllib3.connection.HTTPSConnection object at 0x000001BA308A09B0>: Failed to establish a new connection: [WinError 10060] A connection attempt failed because the connected party did not properly respond after a period of time, or established connection failed because connected host has failed to respond

During handling of the above exception, another exception occurred:

Traceback (most recent call last):
  File "D:\scripts\py\lib\site-packages\requests\adapters.py", line 449, in send
    timeout=timeout
  File "D:\scripts\py\lib\site-packages\urllib3\connectionpool.py", line 725, in urlopen
    method, url, error=e, _pool=self, _stacktrace=sys.exc_info()[2]
  File "D:\scripts\py\lib\site-packages\urllib3\util\retry.py", line 439, in increment
    raise MaxRetryError(_pool, url, error or ResponseError(cause))
urllib3.exceptions.MaxRetryError: HTTPSConnectionPool(host='10.17.84.221', port=4343): Max retries exceeded with url: /v1/api/login (Caused by NewConnectionError('<urllib3.connection.HTTPSConnection object at 0x000001BA308A09B0>: Failed to establish a new connection: [WinError 10060] A connection attempt failed because the connected party did not properly respond after a period of time, or established connection failed because connected host has failed to respond'))

During handling of the above exception, another exception occurred:

Traceback (most recent call last):
  File "D:\scripts\GIT\Aruba_Controller_upgrade\Aruba_Wireless_Upgrade_APP.py", line 105, in get_session
    res = r_session.post(login_url, data = login_post,verify=False)
  File "D:\scripts\py\lib\site-packages\requests\sessions.py", line 578, in post
    return self.request('POST', url, data=data, json=json, **kwargs)
  File "D:\scripts\py\lib\site-packages\requests\sessions.py", line 530, in request
    resp = self.send(prep, **send_kwargs)
  File "D:\scripts\py\lib\site-packages\requests\sessions.py", line 643, in send
    r = adapter.send(request, **kwargs)
  File "D:\scripts\py\lib\site-packages\requests\adapters.py", line 516, in send
    raise ConnectionError(e, request=request)
requests.exceptions.ConnectionError: HTTPSConnectionPool(host='10.17.84.221', port=4343): Max retries exceeded with url: /v1/api/login (Caused by NewConnectionError('<urllib3.connection.HTTPSConnection object at 0x000001BA308A09B0>: Failed to establish a new connection: [WinError 10060] A connection attempt failed because the connected party did not properly respond after a period of time, or established connection failed because connected host has failed to respond'))
2020-10-26 21:04:01,253 > ERROR > get_system_health
Traceback (most recent call last):
  File "D:\scripts\GIT\Aruba_Controller_upgrade\wireless_validation.py", line 174, in get_system_health
    if host_output.get("show storage") != None:
AttributeError: 'NoneType' object has no attribute 'get'
2020-10-26 21:04:22,302 > ERROR > ERROR:Login error : 10.17.84.220:4343
2020-10-26 21:04:22,375 > DEBUG > ERROR:Login error : 10.17.84.220:4343
2020-10-26 21:04:22,395 > ERROR > Login error:10.17.84.220:4343 
Traceback (most recent call last):
  File "D:\scripts\py\lib\site-packages\urllib3\connection.py", line 160, in _new_conn
    (self._dns_host, self.port), self.timeout, **extra_kw
  File "D:\scripts\py\lib\site-packages\urllib3\util\connection.py", line 84, in create_connection
    raise err
  File "D:\scripts\py\lib\site-packages\urllib3\util\connection.py", line 74, in create_connection
    sock.connect(sa)
TimeoutError: [WinError 10060] A connection attempt failed because the connected party did not properly respond after a period of time, or established connection failed because connected host has failed to respond

During handling of the above exception, another exception occurred:

Traceback (most recent call last):
  File "D:\scripts\py\lib\site-packages\urllib3\connectionpool.py", line 677, in urlopen
    chunked=chunked,
  File "D:\scripts\py\lib\site-packages\urllib3\connectionpool.py", line 381, in _make_request
    self._validate_conn(conn)
  File "D:\scripts\py\lib\site-packages\urllib3\connectionpool.py", line 976, in _validate_conn
    conn.connect()
  File "D:\scripts\py\lib\site-packages\urllib3\connection.py", line 308, in connect
    conn = self._new_conn()
  File "D:\scripts\py\lib\site-packages\urllib3\connection.py", line 172, in _new_conn
    self, "Failed to establish a new connection: %s" % e
urllib3.exceptions.NewConnectionError: <urllib3.connection.HTTPSConnection object at 0x000001BA308A9C88>: Failed to establish a new connection: [WinError 10060] A connection attempt failed because the connected party did not properly respond after a period of time, or established connection failed because connected host has failed to respond

During handling of the above exception, another exception occurred:

Traceback (most recent call last):
  File "D:\scripts\py\lib\site-packages\requests\adapters.py", line 449, in send
    timeout=timeout
  File "D:\scripts\py\lib\site-packages\urllib3\connectionpool.py", line 725, in urlopen
    method, url, error=e, _pool=self, _stacktrace=sys.exc_info()[2]
  File "D:\scripts\py\lib\site-packages\urllib3\util\retry.py", line 439, in increment
    raise MaxRetryError(_pool, url, error or ResponseError(cause))
urllib3.exceptions.MaxRetryError: HTTPSConnectionPool(host='10.17.84.220', port=4343): Max retries exceeded with url: /v1/api/login (Caused by NewConnectionError('<urllib3.connection.HTTPSConnection object at 0x000001BA308A9C88>: Failed to establish a new connection: [WinError 10060] A connection attempt failed because the connected party did not properly respond after a period of time, or established connection failed because connected host has failed to respond'))

During handling of the above exception, another exception occurred:

Traceback (most recent call last):
  File "D:\scripts\GIT\Aruba_Controller_upgrade\Aruba_Wireless_Upgrade_APP.py", line 105, in get_session
    res = r_session.post(login_url, data = login_post,verify=False)
  File "D:\scripts\py\lib\site-packages\requests\sessions.py", line 578, in post
    return self.request('POST', url, data=data, json=json, **kwargs)
  File "D:\scripts\py\lib\site-packages\requests\sessions.py", line 530, in request
    resp = self.send(prep, **send_kwargs)
  File "D:\scripts\py\lib\site-packages\requests\sessions.py", line 643, in send
    r = adapter.send(request, **kwargs)
  File "D:\scripts\py\lib\site-packages\requests\adapters.py", line 516, in send
    raise ConnectionError(e, request=request)
requests.exceptions.ConnectionError: HTTPSConnectionPool(host='10.17.84.220', port=4343): Max retries exceeded with url: /v1/api/login (Caused by NewConnectionError('<urllib3.connection.HTTPSConnection object at 0x000001BA308A9C88>: Failed to establish a new connection: [WinError 10060] A connection attempt failed because the connected party did not properly respond after a period of time, or established connection failed because connected host has failed to respond'))
2020-10-26 21:04:43,422 > ERROR > ERROR:Login error : 10.17.84.221:4343
2020-10-26 21:04:43,440 > DEBUG > ERROR:Login error : 10.17.84.221:4343
2020-10-26 21:04:43,461 > ERROR > Login error:10.17.84.221:4343 
Traceback (most recent call last):
  File "D:\scripts\py\lib\site-packages\urllib3\connection.py", line 160, in _new_conn
    (self._dns_host, self.port), self.timeout, **extra_kw
  File "D:\scripts\py\lib\site-packages\urllib3\util\connection.py", line 84, in create_connection
    raise err
  File "D:\scripts\py\lib\site-packages\urllib3\util\connection.py", line 74, in create_connection
    sock.connect(sa)
TimeoutError: [WinError 10060] A connection attempt failed because the connected party did not properly respond after a period of time, or established connection failed because connected host has failed to respond

During handling of the above exception, another exception occurred:

Traceback (most recent call last):
  File "D:\scripts\py\lib\site-packages\urllib3\connectionpool.py", line 677, in urlopen
    chunked=chunked,
  File "D:\scripts\py\lib\site-packages\urllib3\connectionpool.py", line 381, in _make_request
    self._validate_conn(conn)
  File "D:\scripts\py\lib\site-packages\urllib3\connectionpool.py", line 976, in _validate_conn
    conn.connect()
  File "D:\scripts\py\lib\site-packages\urllib3\connection.py", line 308, in connect
    conn = self._new_conn()
  File "D:\scripts\py\lib\site-packages\urllib3\connection.py", line 172, in _new_conn
    self, "Failed to establish a new connection: %s" % e
urllib3.exceptions.NewConnectionError: <urllib3.connection.HTTPSConnection object at 0x000001BA2F7C52B0>: Failed to establish a new connection: [WinError 10060] A connection attempt failed because the connected party did not properly respond after a period of time, or established connection failed because connected host has failed to respond

During handling of the above exception, another exception occurred:

Traceback (most recent call last):
  File "D:\scripts\py\lib\site-packages\requests\adapters.py", line 449, in send
    timeout=timeout
  File "D:\scripts\py\lib\site-packages\urllib3\connectionpool.py", line 725, in urlopen
    method, url, error=e, _pool=self, _stacktrace=sys.exc_info()[2]
  File "D:\scripts\py\lib\site-packages\urllib3\util\retry.py", line 439, in increment
    raise MaxRetryError(_pool, url, error or ResponseError(cause))
urllib3.exceptions.MaxRetryError: HTTPSConnectionPool(host='10.17.84.221', port=4343): Max retries exceeded with url: /v1/api/login (Caused by NewConnectionError('<urllib3.connection.HTTPSConnection object at 0x000001BA2F7C52B0>: Failed to establish a new connection: [WinError 10060] A connection attempt failed because the connected party did not properly respond after a period of time, or established connection failed because connected host has failed to respond'))

During handling of the above exception, another exception occurred:

Traceback (most recent call last):
  File "D:\scripts\GIT\Aruba_Controller_upgrade\Aruba_Wireless_Upgrade_APP.py", line 105, in get_session
    res = r_session.post(login_url, data = login_post,verify=False)
  File "D:\scripts\py\lib\site-packages\requests\sessions.py", line 578, in post
    return self.request('POST', url, data=data, json=json, **kwargs)
  File "D:\scripts\py\lib\site-packages\requests\sessions.py", line 530, in request
    resp = self.send(prep, **send_kwargs)
  File "D:\scripts\py\lib\site-packages\requests\sessions.py", line 643, in send
    r = adapter.send(request, **kwargs)
  File "D:\scripts\py\lib\site-packages\requests\adapters.py", line 516, in send
    raise ConnectionError(e, request=request)
requests.exceptions.ConnectionError: HTTPSConnectionPool(host='10.17.84.221', port=4343): Max retries exceeded with url: /v1/api/login (Caused by NewConnectionError('<urllib3.connection.HTTPSConnection object at 0x000001BA2F7C52B0>: Failed to establish a new connection: [WinError 10060] A connection attempt failed because the connected party did not properly respond after a period of time, or established connection failed because connected host has failed to respond'))
2020-10-26 21:04:43,495 > INFO > INFO:Precheck Completed
2020-10-26 21:04:43,518 > ERROR > create_report
Traceback (most recent call last):
  File "D:\scripts\GIT\Aruba_Controller_upgrade\Aruba_Wireless_Upgrade_APP.py", line 1280, in create_report
    report = r_gen.create_report()
  File "D:\scripts\GIT\Aruba_Controller_upgrade\reports.py", line 77, in create_report
    self.create_header()
  File "D:\scripts\GIT\Aruba_Controller_upgrade\reports.py", line 70, in create_header
    self.precheck_gen()
  File "D:\scripts\GIT\Aruba_Controller_upgrade\reports.py", line 21, in precheck_gen
    for chk in precheck_data:
TypeError: 'NoneType' object is not iterable
2020-10-26 21:04:43,538 > INFO > INFO:==== Completed ====
