2020-09-10 17:25:56,855 > INFO > JOBNAME:1599738956_1932974
2020-09-10 17:25:56,856 > INFO > CONFIG FILE:D:\scripts\GIT\Aruba_Controller_upgrade\conf_files\configuration_2.yaml
2020-09-10 17:25:56,907 > INFO > Starting Job
2020-09-10 17:25:56,931 > INFO > INFO:Running: 1599738956_1932974 Type:precheck,all
2020-09-10 17:25:56,973 > INFO > INFO:Starting Configuration configuration_2.yaml Validation
2020-09-10 17:25:57,019 > INFO > Inserting upgrade list to upgrade.db
2020-09-10 17:25:57,075 > INFO > INFO:Starting precheck
2020-09-10 17:25:57,099 > INFO > INFO:Executing Precheck
2020-09-10 17:25:57,130 > INFO > INFO:Precheck started for : (MM) NaaS-MM-1:10.17.84.220:4343
2020-09-10 17:26:18,181 > ERROR > ERROR:Login error : 10.17.84.220:4343
2020-09-10 17:26:18,207 > DEBUG > ERROR:Login error : 10.17.84.220:4343
2020-09-10 17:26:18,231 > ERROR > Login error:10.17.84.220:4343 
Traceback (most recent call last):
  File "d:\scripts\py\lib\site-packages\urllib3\connection.py", line 160, in _new_conn
    (self._dns_host, self.port), self.timeout, **extra_kw
  File "d:\scripts\py\lib\site-packages\urllib3\util\connection.py", line 84, in create_connection
    raise err
  File "d:\scripts\py\lib\site-packages\urllib3\util\connection.py", line 74, in create_connection
    sock.connect(sa)
TimeoutError: [WinError 10060] A connection attempt failed because the connected party did not properly respond after a period of time, or established connection failed because connected host has failed to respond

During handling of the above exception, another exception occurred:

Traceback (most recent call last):
  File "d:\scripts\py\lib\site-packages\urllib3\connectionpool.py", line 677, in urlopen
    chunked=chunked,
  File "d:\scripts\py\lib\site-packages\urllib3\connectionpool.py", line 381, in _make_request
    self._validate_conn(conn)
  File "d:\scripts\py\lib\site-packages\urllib3\connectionpool.py", line 976, in _validate_conn
    conn.connect()
  File "d:\scripts\py\lib\site-packages\urllib3\connection.py", line 308, in connect
    conn = self._new_conn()
  File "d:\scripts\py\lib\site-packages\urllib3\connection.py", line 172, in _new_conn
    self, "Failed to establish a new connection: %s" % e
urllib3.exceptions.NewConnectionError: <urllib3.connection.HTTPSConnection object at 0x000001529E28A048>: Failed to establish a new connection: [WinError 10060] A connection attempt failed because the connected party did not properly respond after a period of time, or established connection failed because connected host has failed to respond

During handling of the above exception, another exception occurred:

Traceback (most recent call last):
  File "d:\scripts\py\lib\site-packages\requests\adapters.py", line 449, in send
    timeout=timeout
  File "d:\scripts\py\lib\site-packages\urllib3\connectionpool.py", line 725, in urlopen
    method, url, error=e, _pool=self, _stacktrace=sys.exc_info()[2]
  File "d:\scripts\py\lib\site-packages\urllib3\util\retry.py", line 439, in increment
    raise MaxRetryError(_pool, url, error or ResponseError(cause))
urllib3.exceptions.MaxRetryError: HTTPSConnectionPool(host='10.17.84.220', port=4343): Max retries exceeded with url: /v1/api/login (Caused by NewConnectionError('<urllib3.connection.HTTPSConnection object at 0x000001529E28A048>: Failed to establish a new connection: [WinError 10060] A connection attempt failed because the connected party did not properly respond after a period of time, or established connection failed because connected host has failed to respond'))

During handling of the above exception, another exception occurred:

Traceback (most recent call last):
  File "D:\scripts\GIT\Aruba_Controller_upgrade\Aruba_Wireless_Upgrade_APP.py", line 94, in get_session
    res = r_session.post(login_url, data = login_post,verify=False)
  File "d:\scripts\py\lib\site-packages\requests\sessions.py", line 578, in post
    return self.request('POST', url, data=data, json=json, **kwargs)
  File "d:\scripts\py\lib\site-packages\requests\sessions.py", line 530, in request
    resp = self.send(prep, **send_kwargs)
  File "d:\scripts\py\lib\site-packages\requests\sessions.py", line 643, in send
    r = adapter.send(request, **kwargs)
  File "d:\scripts\py\lib\site-packages\requests\adapters.py", line 516, in send
    raise ConnectionError(e, request=request)
requests.exceptions.ConnectionError: HTTPSConnectionPool(host='10.17.84.220', port=4343): Max retries exceeded with url: /v1/api/login (Caused by NewConnectionError('<urllib3.connection.HTTPSConnection object at 0x000001529E28A048>: Failed to establish a new connection: [WinError 10060] A connection attempt failed because the connected party did not properly respond after a period of time, or established connection failed because connected host has failed to respond'))
2020-09-10 17:26:18,235 > ERROR > ERROR:Precheck failed for => NaaS-MM-1:10.17.84.220:4343
2020-09-10 17:26:18,272 > DEBUG > ERROR:Precheck failed for => NaaS-MM-1:10.17.84.220:4343
2020-09-10 17:26:18,299 > INFO > INFO:Precheck started for : (MD) NaaS-VMC-1:10.17.84.221:4343
2020-09-10 17:26:39,325 > ERROR > ERROR:Login error : 10.17.84.221:4343
2020-09-10 17:26:39,360 > DEBUG > ERROR:Login error : 10.17.84.221:4343
2020-09-10 17:26:39,383 > ERROR > Login error:10.17.84.221:4343 
Traceback (most recent call last):
  File "d:\scripts\py\lib\site-packages\urllib3\connection.py", line 160, in _new_conn
    (self._dns_host, self.port), self.timeout, **extra_kw
  File "d:\scripts\py\lib\site-packages\urllib3\util\connection.py", line 84, in create_connection
    raise err
  File "d:\scripts\py\lib\site-packages\urllib3\util\connection.py", line 74, in create_connection
    sock.connect(sa)
TimeoutError: [WinError 10060] A connection attempt failed because the connected party did not properly respond after a period of time, or established connection failed because connected host has failed to respond

During handling of the above exception, another exception occurred:

Traceback (most recent call last):
  File "d:\scripts\py\lib\site-packages\urllib3\connectionpool.py", line 677, in urlopen
    chunked=chunked,
  File "d:\scripts\py\lib\site-packages\urllib3\connectionpool.py", line 381, in _make_request
    self._validate_conn(conn)
  File "d:\scripts\py\lib\site-packages\urllib3\connectionpool.py", line 976, in _validate_conn
    conn.connect()
  File "d:\scripts\py\lib\site-packages\urllib3\connection.py", line 308, in connect
    conn = self._new_conn()
  File "d:\scripts\py\lib\site-packages\urllib3\connection.py", line 172, in _new_conn
    self, "Failed to establish a new connection: %s" % e
urllib3.exceptions.NewConnectionError: <urllib3.connection.HTTPSConnection object at 0x000001529E280DD8>: Failed to establish a new connection: [WinError 10060] A connection attempt failed because the connected party did not properly respond after a period of time, or established connection failed because connected host has failed to respond

During handling of the above exception, another exception occurred:

Traceback (most recent call last):
  File "d:\scripts\py\lib\site-packages\requests\adapters.py", line 449, in send
    timeout=timeout
  File "d:\scripts\py\lib\site-packages\urllib3\connectionpool.py", line 725, in urlopen
    method, url, error=e, _pool=self, _stacktrace=sys.exc_info()[2]
  File "d:\scripts\py\lib\site-packages\urllib3\util\retry.py", line 439, in increment
    raise MaxRetryError(_pool, url, error or ResponseError(cause))
urllib3.exceptions.MaxRetryError: HTTPSConnectionPool(host='10.17.84.221', port=4343): Max retries exceeded with url: /v1/api/login (Caused by NewConnectionError('<urllib3.connection.HTTPSConnection object at 0x000001529E280DD8>: Failed to establish a new connection: [WinError 10060] A connection attempt failed because the connected party did not properly respond after a period of time, or established connection failed because connected host has failed to respond'))

During handling of the above exception, another exception occurred:

Traceback (most recent call last):
  File "D:\scripts\GIT\Aruba_Controller_upgrade\Aruba_Wireless_Upgrade_APP.py", line 94, in get_session
    res = r_session.post(login_url, data = login_post,verify=False)
  File "d:\scripts\py\lib\site-packages\requests\sessions.py", line 578, in post
    return self.request('POST', url, data=data, json=json, **kwargs)
  File "d:\scripts\py\lib\site-packages\requests\sessions.py", line 530, in request
    resp = self.send(prep, **send_kwargs)
  File "d:\scripts\py\lib\site-packages\requests\sessions.py", line 643, in send
    r = adapter.send(request, **kwargs)
  File "d:\scripts\py\lib\site-packages\requests\adapters.py", line 516, in send
    raise ConnectionError(e, request=request)
requests.exceptions.ConnectionError: HTTPSConnectionPool(host='10.17.84.221', port=4343): Max retries exceeded with url: /v1/api/login (Caused by NewConnectionError('<urllib3.connection.HTTPSConnection object at 0x000001529E280DD8>: Failed to establish a new connection: [WinError 10060] A connection attempt failed because the connected party did not properly respond after a period of time, or established connection failed because connected host has failed to respond'))
2020-09-10 17:26:39,384 > ERROR > ERROR:Precheck failed for => NaaS-VMC-1:10.17.84.221:4343
2020-09-10 17:26:39,406 > DEBUG > ERROR:Precheck failed for => NaaS-VMC-1:10.17.84.221:4343
2020-09-10 17:26:39,439 > INFO > INFO:Precheck Completed
2020-09-10 17:26:39,466 > INFO > INFO:Total upgrade hosts:2
2020-09-10 17:26:39,505 > INFO > INFO:MM: Preparing for host NaaS-MM-1 IP: 10.17.84.220:4343
2020-09-10 17:26:39,525 > ERROR > get_image_details: 
Traceback (most recent call last):
  File "D:\scripts\GIT\Aruba_Controller_upgrade\Aruba_Wireless_Upgrade_APP.py", line 385, in execute_cmd
    host_ip = single_host.get("host")
AttributeError: 'str' object has no attribute 'get'
2020-09-10 17:26:39,525 > INFO > INFO:MD: Preparing for host NaaS-VMC-1 IP: 10.17.84.221:4343
2020-09-10 17:26:39,545 > ERROR > get_image_details: 
Traceback (most recent call last):
  File "D:\scripts\GIT\Aruba_Controller_upgrade\Aruba_Wireless_Upgrade_APP.py", line 385, in execute_cmd
    host_ip = single_host.get("host")
AttributeError: 'str' object has no attribute 'get'
2020-09-10 17:26:39,545 > ERROR > AP_IMAGE_PRELOAD: 
Traceback (most recent call last):
  File "D:\scripts\GIT\Aruba_Controller_upgrade\Aruba_Wireless_Upgrade_APP.py", line 554, in AP_IMAGE_PRELOAD
    max_ap_image_load = self.config.get("max_ap_image_load")
AttributeError: 'Aruba_Wireless_upgrade' object has no attribute 'config'
2020-09-10 17:26:39,546 > INFO > INFO:Starting all
2020-09-10 17:26:39,597 > INFO > INFO:==== Completed ====
