2020-09-13 06:48:26,450 > INFO > JOBNAME:1599959906_4167628
2020-09-13 06:48:26,451 > INFO > CONFIG FILE:D:\scripts\GIT\Aruba_Controller_upgrade\conf_files\LAB WIRELESS UPGRADE
2020-09-13 06:48:26,488 > INFO > Starting Job
2020-09-13 06:48:26,506 > INFO > INFO:Running: 1599959906_4167628 Type:precheck
2020-09-13 06:48:26,523 > INFO > INFO:Starting Configuration LAB WIRELESS UPGRADE Validation
2020-09-13 06:48:26,587 > INFO > Inserting upgrade list to upgrade.db
2020-09-13 06:48:30,643 > INFO > yes
2020-09-13 06:48:30,643 > INFO > INFO:Starting precheck
2020-09-13 06:48:30,665 > INFO > INFO:Executing Precheck
2020-09-13 06:48:30,708 > INFO > INFO:Precheck started for : (MM) NaaS-MM-1:10.17.84.220:4343
2020-09-13 06:48:30,748 > ERROR > ERROR:Login error : 10.17.84.220:4343
2020-09-13 06:48:30,768 > DEBUG > ERROR:Login error : 10.17.84.220:4343
2020-09-13 06:48:30,786 > ERROR > Login error:10.17.84.220:4343 
Traceback (most recent call last):
  File "d:\scripts\py\lib\site-packages\urllib3\connection.py", line 160, in _new_conn
    (self._dns_host, self.port), self.timeout, **extra_kw
  File "d:\scripts\py\lib\site-packages\urllib3\util\connection.py", line 84, in create_connection
    raise err
  File "d:\scripts\py\lib\site-packages\urllib3\util\connection.py", line 74, in create_connection
    sock.connect(sa)
OSError: [WinError 10065] A socket operation was attempted to an unreachable host

During handling of the above exception, another exception occurred:

Traceback (most recent call last):
  File "d:\scripts\py\lib\site-packages\urllib3\connectionpool.py", line 677, in urlopen
    chunked=chunked,
  File "d:\scripts\py\lib\site-packages\urllib3\connectionpool.py", line 381, in _make_request
    self._validate_conn(conn)
  File "d:\scripts\py\lib\site-packages\urllib3\connectionpool.py", line 976, in _validate_conn
    conn.connect()
  File "d:\scripts\py\lib\site-packages\urllib3\connection.py", line 308, in connect
    conn = self._new_conn()
  File "d:\scripts\py\lib\site-packages\urllib3\connection.py", line 172, in _new_conn
    self, "Failed to establish a new connection: %s" % e
urllib3.exceptions.NewConnectionError: <urllib3.connection.HTTPSConnection object at 0x0000016117E79BE0>: Failed to establish a new connection: [WinError 10065] A socket operation was attempted to an unreachable host

During handling of the above exception, another exception occurred:

Traceback (most recent call last):
  File "d:\scripts\py\lib\site-packages\requests\adapters.py", line 449, in send
    timeout=timeout
  File "d:\scripts\py\lib\site-packages\urllib3\connectionpool.py", line 725, in urlopen
    method, url, error=e, _pool=self, _stacktrace=sys.exc_info()[2]
  File "d:\scripts\py\lib\site-packages\urllib3\util\retry.py", line 439, in increment
    raise MaxRetryError(_pool, url, error or ResponseError(cause))
urllib3.exceptions.MaxRetryError: HTTPSConnectionPool(host='10.17.84.220', port=4343): Max retries exceeded with url: /v1/api/login (Caused by NewConnectionError('<urllib3.connection.HTTPSConnection object at 0x0000016117E79BE0>: Failed to establish a new connection: [WinError 10065] A socket operation was attempted to an unreachable host'))

During handling of the above exception, another exception occurred:

Traceback (most recent call last):
  File "D:\scripts\GIT\Aruba_Controller_upgrade\Aruba_Wireless_Upgrade_APP.py", line 97, in get_session
    res = r_session.post(login_url, data = login_post,verify=False)
  File "d:\scripts\py\lib\site-packages\requests\sessions.py", line 578, in post
    return self.request('POST', url, data=data, json=json, **kwargs)
  File "d:\scripts\py\lib\site-packages\requests\sessions.py", line 530, in request
    resp = self.send(prep, **send_kwargs)
  File "d:\scripts\py\lib\site-packages\requests\sessions.py", line 643, in send
    r = adapter.send(request, **kwargs)
  File "d:\scripts\py\lib\site-packages\requests\adapters.py", line 516, in send
    raise ConnectionError(e, request=request)
requests.exceptions.ConnectionError: HTTPSConnectionPool(host='10.17.84.220', port=4343): Max retries exceeded with url: /v1/api/login (Caused by NewConnectionError('<urllib3.connection.HTTPSConnection object at 0x0000016117E79BE0>: Failed to establish a new connection: [WinError 10065] A socket operation was attempted to an unreachable host'))
2020-09-13 06:48:30,796 > ERROR > ERROR:Precheck failed for => NaaS-MM-1:10.17.84.220:4343
2020-09-13 06:48:30,813 > DEBUG > ERROR:Precheck failed for => NaaS-MM-1:10.17.84.220:4343
2020-09-13 06:48:30,861 > INFO > INFO:Precheck started for : (MD) NaaS-VMC-1:10.17.84.221:4343
2020-09-13 06:48:31,069 > ERROR > ERROR:Login error : 10.17.84.221:4343
2020-09-13 06:48:31,087 > DEBUG > ERROR:Login error : 10.17.84.221:4343
2020-09-13 06:48:31,106 > ERROR > Login error:10.17.84.221:4343 
Traceback (most recent call last):
  File "d:\scripts\py\lib\site-packages\urllib3\connection.py", line 160, in _new_conn
    (self._dns_host, self.port), self.timeout, **extra_kw
  File "d:\scripts\py\lib\site-packages\urllib3\util\connection.py", line 84, in create_connection
    raise err
  File "d:\scripts\py\lib\site-packages\urllib3\util\connection.py", line 74, in create_connection
    sock.connect(sa)
OSError: [WinError 10065] A socket operation was attempted to an unreachable host

During handling of the above exception, another exception occurred:

Traceback (most recent call last):
  File "d:\scripts\py\lib\site-packages\urllib3\connectionpool.py", line 677, in urlopen
    chunked=chunked,
  File "d:\scripts\py\lib\site-packages\urllib3\connectionpool.py", line 381, in _make_request
    self._validate_conn(conn)
  File "d:\scripts\py\lib\site-packages\urllib3\connectionpool.py", line 976, in _validate_conn
    conn.connect()
  File "d:\scripts\py\lib\site-packages\urllib3\connection.py", line 308, in connect
    conn = self._new_conn()
  File "d:\scripts\py\lib\site-packages\urllib3\connection.py", line 172, in _new_conn
    self, "Failed to establish a new connection: %s" % e
urllib3.exceptions.NewConnectionError: <urllib3.connection.HTTPSConnection object at 0x0000016117E74E48>: Failed to establish a new connection: [WinError 10065] A socket operation was attempted to an unreachable host

During handling of the above exception, another exception occurred:

Traceback (most recent call last):
  File "d:\scripts\py\lib\site-packages\requests\adapters.py", line 449, in send
    timeout=timeout
  File "d:\scripts\py\lib\site-packages\urllib3\connectionpool.py", line 725, in urlopen
    method, url, error=e, _pool=self, _stacktrace=sys.exc_info()[2]
  File "d:\scripts\py\lib\site-packages\urllib3\util\retry.py", line 439, in increment
    raise MaxRetryError(_pool, url, error or ResponseError(cause))
urllib3.exceptions.MaxRetryError: HTTPSConnectionPool(host='10.17.84.221', port=4343): Max retries exceeded with url: /v1/api/login (Caused by NewConnectionError('<urllib3.connection.HTTPSConnection object at 0x0000016117E74E48>: Failed to establish a new connection: [WinError 10065] A socket operation was attempted to an unreachable host'))

During handling of the above exception, another exception occurred:

Traceback (most recent call last):
  File "D:\scripts\GIT\Aruba_Controller_upgrade\Aruba_Wireless_Upgrade_APP.py", line 97, in get_session
    res = r_session.post(login_url, data = login_post,verify=False)
  File "d:\scripts\py\lib\site-packages\requests\sessions.py", line 578, in post
    return self.request('POST', url, data=data, json=json, **kwargs)
  File "d:\scripts\py\lib\site-packages\requests\sessions.py", line 530, in request
    resp = self.send(prep, **send_kwargs)
  File "d:\scripts\py\lib\site-packages\requests\sessions.py", line 643, in send
    r = adapter.send(request, **kwargs)
  File "d:\scripts\py\lib\site-packages\requests\adapters.py", line 516, in send
    raise ConnectionError(e, request=request)
requests.exceptions.ConnectionError: HTTPSConnectionPool(host='10.17.84.221', port=4343): Max retries exceeded with url: /v1/api/login (Caused by NewConnectionError('<urllib3.connection.HTTPSConnection object at 0x0000016117E74E48>: Failed to establish a new connection: [WinError 10065] A socket operation was attempted to an unreachable host'))
2020-09-13 06:48:31,109 > ERROR > ERROR:Precheck failed for => NaaS-VMC-1:10.17.84.221:4343
2020-09-13 06:48:31,126 > DEBUG > ERROR:Precheck failed for => NaaS-VMC-1:10.17.84.221:4343
2020-09-13 06:48:31,206 > INFO > INFO:Precheck Completed
2020-09-13 06:48:31,237 > INFO > INFO:==== Completed ====
2020-09-13 06:49:14,924 > INFO > JOBNAME:1599959953_8748357
2020-09-13 06:49:14,925 > INFO > CONFIG FILE:D:\scripts\GIT\Aruba_Controller_upgrade\conf_files\LAB WIRELESS UPGRADE
2020-09-13 06:49:14,965 > INFO > Starting Job
2020-09-13 06:49:14,982 > INFO > INFO:Running: 1599959953_8748357 Type:precheck
2020-09-13 06:49:14,999 > INFO > INFO:Starting Configuration LAB WIRELESS UPGRADE Validation
2020-09-13 06:49:15,087 > INFO > Inserting upgrade list to upgrade.db
2020-09-13 06:49:19,155 > INFO > yes
2020-09-13 06:49:19,156 > INFO > INFO:Starting precheck
2020-09-13 06:49:19,211 > INFO > INFO:Executing Precheck
2020-09-13 06:49:19,291 > INFO > INFO:Precheck started for : (MM) NaaS-MM-1:10.17.84.220:4343
2020-09-13 06:49:40,343 > ERROR > ERROR:Login error : 10.17.84.220:4343
2020-09-13 06:49:40,370 > DEBUG > ERROR:Login error : 10.17.84.220:4343
2020-09-13 06:49:40,394 > ERROR > Login error:10.17.84.220:4343 
Traceback (most recent call last):
  File "d:\scripts\py\lib\site-packages\urllib3\connection.py", line 160, in _new_conn
    (self._dns_host, self.port), self.timeout, **extra_kw
  File "d:\scripts\py\lib\site-packages\urllib3\util\connection.py", line 84, in create_connection
    raise err
  File "d:\scripts\py\lib\site-packages\urllib3\util\connection.py", line 74, in create_connection
    sock.connect(sa)
TimeoutError: [WinError 10060] A connection attempt failed because the connected party did not properly respond after a period of time, or established connection failed because connected host has failed to respond

During handling of the above exception, another exception occurred:

Traceback (most recent call last):
  File "d:\scripts\py\lib\site-packages\urllib3\connectionpool.py", line 677, in urlopen
    chunked=chunked,
  File "d:\scripts\py\lib\site-packages\urllib3\connectionpool.py", line 381, in _make_request
    self._validate_conn(conn)
  File "d:\scripts\py\lib\site-packages\urllib3\connectionpool.py", line 976, in _validate_conn
    conn.connect()
  File "d:\scripts\py\lib\site-packages\urllib3\connection.py", line 308, in connect
    conn = self._new_conn()
  File "d:\scripts\py\lib\site-packages\urllib3\connection.py", line 172, in _new_conn
    self, "Failed to establish a new connection: %s" % e
urllib3.exceptions.NewConnectionError: <urllib3.connection.HTTPSConnection object at 0x0000016117E74EF0>: Failed to establish a new connection: [WinError 10060] A connection attempt failed because the connected party did not properly respond after a period of time, or established connection failed because connected host has failed to respond

During handling of the above exception, another exception occurred:

Traceback (most recent call last):
  File "d:\scripts\py\lib\site-packages\requests\adapters.py", line 449, in send
    timeout=timeout
  File "d:\scripts\py\lib\site-packages\urllib3\connectionpool.py", line 725, in urlopen
    method, url, error=e, _pool=self, _stacktrace=sys.exc_info()[2]
  File "d:\scripts\py\lib\site-packages\urllib3\util\retry.py", line 439, in increment
    raise MaxRetryError(_pool, url, error or ResponseError(cause))
urllib3.exceptions.MaxRetryError: HTTPSConnectionPool(host='10.17.84.220', port=4343): Max retries exceeded with url: /v1/api/login (Caused by NewConnectionError('<urllib3.connection.HTTPSConnection object at 0x0000016117E74EF0>: Failed to establish a new connection: [WinError 10060] A connection attempt failed because the connected party did not properly respond after a period of time, or established connection failed because connected host has failed to respond'))

During handling of the above exception, another exception occurred:

Traceback (most recent call last):
  File "D:\scripts\GIT\Aruba_Controller_upgrade\Aruba_Wireless_Upgrade_APP.py", line 97, in get_session
    res = r_session.post(login_url, data = login_post,verify=False)
  File "d:\scripts\py\lib\site-packages\requests\sessions.py", line 578, in post
    return self.request('POST', url, data=data, json=json, **kwargs)
  File "d:\scripts\py\lib\site-packages\requests\sessions.py", line 530, in request
    resp = self.send(prep, **send_kwargs)
  File "d:\scripts\py\lib\site-packages\requests\sessions.py", line 643, in send
    r = adapter.send(request, **kwargs)
  File "d:\scripts\py\lib\site-packages\requests\adapters.py", line 516, in send
    raise ConnectionError(e, request=request)
requests.exceptions.ConnectionError: HTTPSConnectionPool(host='10.17.84.220', port=4343): Max retries exceeded with url: /v1/api/login (Caused by NewConnectionError('<urllib3.connection.HTTPSConnection object at 0x0000016117E74EF0>: Failed to establish a new connection: [WinError 10060] A connection attempt failed because the connected party did not properly respond after a period of time, or established connection failed because connected host has failed to respond'))
2020-09-13 06:49:40,401 > ERROR > ERROR:Precheck failed for => NaaS-MM-1:10.17.84.220:4343
2020-09-13 06:49:40,423 > DEBUG > ERROR:Precheck failed for => NaaS-MM-1:10.17.84.220:4343
2020-09-13 06:49:40,482 > INFO > INFO:Precheck started for : (MD) NaaS-VMC-1:10.17.84.221:4343
2020-09-13 06:50:01,505 > ERROR > ERROR:Login error : 10.17.84.221:4343
2020-09-13 06:50:01,531 > DEBUG > ERROR:Login error : 10.17.84.221:4343
2020-09-13 06:50:01,549 > ERROR > Login error:10.17.84.221:4343 
Traceback (most recent call last):
  File "d:\scripts\py\lib\site-packages\urllib3\connection.py", line 160, in _new_conn
    (self._dns_host, self.port), self.timeout, **extra_kw
  File "d:\scripts\py\lib\site-packages\urllib3\util\connection.py", line 84, in create_connection
    raise err
  File "d:\scripts\py\lib\site-packages\urllib3\util\connection.py", line 74, in create_connection
    sock.connect(sa)
TimeoutError: [WinError 10060] A connection attempt failed because the connected party did not properly respond after a period of time, or established connection failed because connected host has failed to respond

During handling of the above exception, another exception occurred:

Traceback (most recent call last):
  File "d:\scripts\py\lib\site-packages\urllib3\connectionpool.py", line 677, in urlopen
    chunked=chunked,
  File "d:\scripts\py\lib\site-packages\urllib3\connectionpool.py", line 381, in _make_request
    self._validate_conn(conn)
  File "d:\scripts\py\lib\site-packages\urllib3\connectionpool.py", line 976, in _validate_conn
    conn.connect()
  File "d:\scripts\py\lib\site-packages\urllib3\connection.py", line 308, in connect
    conn = self._new_conn()
  File "d:\scripts\py\lib\site-packages\urllib3\connection.py", line 172, in _new_conn
    self, "Failed to establish a new connection: %s" % e
urllib3.exceptions.NewConnectionError: <urllib3.connection.HTTPSConnection object at 0x0000016117E88518>: Failed to establish a new connection: [WinError 10060] A connection attempt failed because the connected party did not properly respond after a period of time, or established connection failed because connected host has failed to respond

During handling of the above exception, another exception occurred:

Traceback (most recent call last):
  File "d:\scripts\py\lib\site-packages\requests\adapters.py", line 449, in send
    timeout=timeout
  File "d:\scripts\py\lib\site-packages\urllib3\connectionpool.py", line 725, in urlopen
    method, url, error=e, _pool=self, _stacktrace=sys.exc_info()[2]
  File "d:\scripts\py\lib\site-packages\urllib3\util\retry.py", line 439, in increment
    raise MaxRetryError(_pool, url, error or ResponseError(cause))
urllib3.exceptions.MaxRetryError: HTTPSConnectionPool(host='10.17.84.221', port=4343): Max retries exceeded with url: /v1/api/login (Caused by NewConnectionError('<urllib3.connection.HTTPSConnection object at 0x0000016117E88518>: Failed to establish a new connection: [WinError 10060] A connection attempt failed because the connected party did not properly respond after a period of time, or established connection failed because connected host has failed to respond'))

During handling of the above exception, another exception occurred:

Traceback (most recent call last):
  File "D:\scripts\GIT\Aruba_Controller_upgrade\Aruba_Wireless_Upgrade_APP.py", line 97, in get_session
    res = r_session.post(login_url, data = login_post,verify=False)
  File "d:\scripts\py\lib\site-packages\requests\sessions.py", line 578, in post
    return self.request('POST', url, data=data, json=json, **kwargs)
  File "d:\scripts\py\lib\site-packages\requests\sessions.py", line 530, in request
    resp = self.send(prep, **send_kwargs)
  File "d:\scripts\py\lib\site-packages\requests\sessions.py", line 643, in send
    r = adapter.send(request, **kwargs)
  File "d:\scripts\py\lib\site-packages\requests\adapters.py", line 516, in send
    raise ConnectionError(e, request=request)
requests.exceptions.ConnectionError: HTTPSConnectionPool(host='10.17.84.221', port=4343): Max retries exceeded with url: /v1/api/login (Caused by NewConnectionError('<urllib3.connection.HTTPSConnection object at 0x0000016117E88518>: Failed to establish a new connection: [WinError 10060] A connection attempt failed because the connected party did not properly respond after a period of time, or established connection failed because connected host has failed to respond'))
2020-09-13 06:50:01,552 > ERROR > ERROR:Precheck failed for => NaaS-VMC-1:10.17.84.221:4343
2020-09-13 06:50:01,570 > DEBUG > ERROR:Precheck failed for => NaaS-VMC-1:10.17.84.221:4343
2020-09-13 06:50:01,607 > INFO > INFO:Precheck Completed
2020-09-13 06:50:01,643 > INFO > INFO:==== Completed ====
2020-09-13 06:50:29,871 > INFO > JOBNAME:1599960029_842488
2020-09-13 06:50:29,872 > INFO > CONFIG FILE:D:\scripts\GIT\Aruba_Controller_upgrade\conf_files\LAB WIRELESS UPGRADE
2020-09-13 06:50:29,909 > INFO > Starting Job
2020-09-13 06:50:29,927 > INFO > INFO:Running: 1599960029_842488 Type:precheck
2020-09-13 06:50:29,948 > INFO > INFO:Starting Configuration LAB WIRELESS UPGRADE Validation
2020-09-13 06:50:30,034 > INFO > Inserting upgrade list to upgrade.db
2020-09-13 06:50:34,108 > INFO > yes
2020-09-13 06:50:34,109 > INFO > INFO:Starting precheck
2020-09-13 06:50:34,135 > INFO > INFO:Executing Precheck
2020-09-13 06:50:34,185 > INFO > INFO:Precheck started for : (MM) NaaS-MM-1:10.17.84.220:4343
2020-09-13 06:50:40,478 > INFO > INFO:Login Success => 10.17.84.220:4343
2020-09-13 06:50:40,625 > INFO > INFO:Executing NaaS-MM-1 - 10.17.84.220:4343 => show clock
2020-09-13 06:50:43,583 > INFO > INFO:Executing NaaS-MM-1 - 10.17.84.220:4343 => show version
2020-09-13 06:50:44,596 > INFO > INFO:Executing NaaS-MM-1 - 10.17.84.220:4343 => show image version
2020-09-13 06:50:45,622 > INFO > INFO:Executing NaaS-MM-1 - 10.17.84.220:4343 => show storage
2020-09-13 06:50:47,113 > INFO > INFO:Executing NaaS-MM-1 - 10.17.84.220:4343 => show cpuload
2020-09-13 06:50:48,088 > INFO > INFO:Executing NaaS-MM-1 - 10.17.84.220:4343 => show memory
2020-09-13 06:50:49,108 > INFO > INFO:Executing NaaS-MM-1 - 10.17.84.220:4343 => show boot
2020-09-13 06:50:50,245 > INFO > INFO:Executing NaaS-MM-1 - 10.17.84.220:4343 => show switches
2020-09-13 06:51:25,496 > INFO > INFO:Executing NaaS-MM-1 - 10.17.84.220:4343 => show switchinfo
2020-09-13 06:51:26,583 > INFO > INFO:Executing NaaS-MM-1 - 10.17.84.220:4343 => show boot history
2020-09-13 06:51:28,110 > INFO > INFO:Executing NaaS-MM-1 - 10.17.84.220:4343 => show crypto ipsec sa
2020-09-13 06:51:29,634 > INFO > INFO:Executing NaaS-MM-1 - 10.17.84.220:4343 => show master-redundancy
2020-09-13 06:51:31,246 > INFO > INFO:Executing NaaS-MM-1 - 10.17.84.220:4343 => show database synchronize
2020-09-13 06:51:32,528 > INFO > INFO:Executing NaaS-MM-1 - 10.17.84.220:4343 => show license
2020-09-13 06:51:34,133 > INFO > INFO:Executing NaaS-MM-1 - 10.17.84.220:4343 => show running-config
2020-09-13 06:51:36,239 > INFO > INFO:Precheck started for : (MD) NaaS-VMC-1:10.17.84.221:4343
2020-09-13 06:51:42,326 > INFO > INFO:Login Success => 10.17.84.221:4343
2020-09-13 06:51:42,395 > INFO > INFO:Executing NaaS-VMC-1 - 10.17.84.221:4343 => show clock
2020-09-13 06:51:45,219 > INFO > INFO:Executing NaaS-VMC-1 - 10.17.84.221:4343 => show version
2020-09-13 06:51:46,235 > INFO > INFO:Executing NaaS-VMC-1 - 10.17.84.221:4343 => show image version
2020-09-13 06:51:47,819 > INFO > INFO:Executing NaaS-VMC-1 - 10.17.84.221:4343 => show storage
2020-09-13 06:51:49,850 > INFO > INFO:Executing NaaS-VMC-1 - 10.17.84.221:4343 => show cpuload
2020-09-13 06:51:51,493 > INFO > INFO:Executing NaaS-VMC-1 - 10.17.84.221:4343 => show memory
2020-09-13 06:51:52,575 > INFO > INFO:Executing NaaS-VMC-1 - 10.17.84.221:4343 => show boot
2020-09-13 06:51:53,999 > INFO > INFO:Executing NaaS-VMC-1 - 10.17.84.221:4343 => show switches
2020-09-13 06:51:54,777 > INFO > INFO:Executing NaaS-VMC-1 - 10.17.84.221:4343 => show switchinfo
2020-09-13 06:51:56,651 > INFO > INFO:Executing NaaS-VMC-1 - 10.17.84.221:4343 => show boot history
2020-09-13 06:51:58,673 > INFO > INFO:Executing NaaS-VMC-1 - 10.17.84.221:4343 => show user
2020-09-13 06:52:00,540 > INFO > INFO:Executing NaaS-VMC-1 - 10.17.84.221:4343 => show ap database long
2020-09-13 06:52:01,333 > INFO > INFO:Executing NaaS-VMC-1 - 10.17.84.221:4343 => show ap bss-table
2020-09-13 06:52:03,390 > INFO > INFO:Executing NaaS-VMC-1 - 10.17.84.221:4343 => show ap essid
2020-09-13 06:52:04,877 > INFO > INFO:Executing NaaS-VMC-1 - 10.17.84.221:4343 => show ap active counters
2020-09-13 06:52:06,157 > INFO > INFO:Executing NaaS-VMC-1 - 10.17.84.221:4343 => show ap debug counters
2020-09-13 06:52:07,943 > INFO > INFO:Executing NaaS-VMC-1 - 10.17.84.221:4343 => show lc-cluster group-membership
2020-09-13 06:52:08,919 > INFO > INFO:Executing NaaS-VMC-1 - 10.17.84.221:4343 => show switches
2020-09-13 06:52:09,964 > INFO > INFO:Executing NaaS-VMC-1 - 10.17.84.221:4343 => show license
2020-09-13 06:52:10,836 > INFO > INFO:Executing NaaS-VMC-1 - 10.17.84.221:4343 => show running-config
2020-09-13 06:52:12,649 > INFO > INFO:Executing NaaS-VMC-1 - 10.17.84.221:4343 => show boot
2020-09-13 06:52:13,490 > INFO > INFO:Executing NaaS-VMC-1 - 10.17.84.221:4343 => show version
2020-09-13 06:52:15,821 > INFO > INFO:Precheck Completed
2020-09-13 06:52:15,858 > INFO > INFO:==== Completed ====
