2020-09-12 19:32:32,744 > INFO > JOBNAME:1599919352_7265594
2020-09-12 19:32:32,744 > INFO > CONFIG FILE:D:\scripts\GIT\Aruba_Controller_upgrade\conf_files\LAB WIRELESS UPGRADE
2020-09-12 19:32:32,777 > INFO > Starting Job
2020-09-12 19:32:32,791 > INFO > INFO:Running: 1599919352_7265594 Type:precheck,all
2020-09-12 19:32:32,806 > INFO > INFO:Starting Configuration LAB WIRELESS UPGRADE Validation
2020-09-12 19:32:32,840 > INFO > Inserting upgrade list to upgrade.db
2020-09-12 19:32:36,891 > INFO > yes
2020-09-12 19:32:36,891 > INFO > INFO:Starting precheck
2020-09-12 19:32:37,904 > INFO > INFO:Executing Precheck
2020-09-12 19:32:37,935 > INFO > INFO:Precheck started for : (MM) NaaS-MM-1:10.17.84.220:4343
2020-09-12 19:32:37,953 > ERROR > ERROR:Login error : 10.17.84.220:4343
2020-09-12 19:32:37,967 > DEBUG > ERROR:Login error : 10.17.84.220:4343
2020-09-12 19:32:37,980 > ERROR > Login error:10.17.84.220:4343 
Traceback (most recent call last):
  File "d:\scripts\py\lib\site-packages\urllib3\connection.py", line 160, in _new_conn
    (self._dns_host, self.port), self.timeout, **extra_kw
  File "d:\scripts\py\lib\site-packages\urllib3\util\connection.py", line 84, in create_connection
    raise err
  File "d:\scripts\py\lib\site-packages\urllib3\util\connection.py", line 74, in create_connection
    sock.connect(sa)
OSError: [WinError 10065] A socket operation was attempted to an unreachable host

During handling of the above exception, another exception occurred:

Traceback (most recent call last):
  File "d:\scripts\py\lib\site-packages\urllib3\connectionpool.py", line 677, in urlopen
    chunked=chunked,
  File "d:\scripts\py\lib\site-packages\urllib3\connectionpool.py", line 381, in _make_request
    self._validate_conn(conn)
  File "d:\scripts\py\lib\site-packages\urllib3\connectionpool.py", line 976, in _validate_conn
    conn.connect()
  File "d:\scripts\py\lib\site-packages\urllib3\connection.py", line 308, in connect
    conn = self._new_conn()
  File "d:\scripts\py\lib\site-packages\urllib3\connection.py", line 172, in _new_conn
    self, "Failed to establish a new connection: %s" % e
urllib3.exceptions.NewConnectionError: <urllib3.connection.HTTPSConnection object at 0x0000014C3ACA2940>: Failed to establish a new connection: [WinError 10065] A socket operation was attempted to an unreachable host

During handling of the above exception, another exception occurred:

Traceback (most recent call last):
  File "d:\scripts\py\lib\site-packages\requests\adapters.py", line 449, in send
    timeout=timeout
  File "d:\scripts\py\lib\site-packages\urllib3\connectionpool.py", line 725, in urlopen
    method, url, error=e, _pool=self, _stacktrace=sys.exc_info()[2]
  File "d:\scripts\py\lib\site-packages\urllib3\util\retry.py", line 439, in increment
    raise MaxRetryError(_pool, url, error or ResponseError(cause))
urllib3.exceptions.MaxRetryError: HTTPSConnectionPool(host='10.17.84.220', port=4343): Max retries exceeded with url: /v1/api/login (Caused by NewConnectionError('<urllib3.connection.HTTPSConnection object at 0x0000014C3ACA2940>: Failed to establish a new connection: [WinError 10065] A socket operation was attempted to an unreachable host'))

During handling of the above exception, another exception occurred:

Traceback (most recent call last):
  File "D:\scripts\GIT\Aruba_Controller_upgrade\Aruba_Wireless_Upgrade_APP.py", line 95, in get_session
    res = r_session.post(login_url, data = login_post,verify=False)
  File "d:\scripts\py\lib\site-packages\requests\sessions.py", line 578, in post
    return self.request('POST', url, data=data, json=json, **kwargs)
  File "d:\scripts\py\lib\site-packages\requests\sessions.py", line 530, in request
    resp = self.send(prep, **send_kwargs)
  File "d:\scripts\py\lib\site-packages\requests\sessions.py", line 643, in send
    r = adapter.send(request, **kwargs)
  File "d:\scripts\py\lib\site-packages\requests\adapters.py", line 516, in send
    raise ConnectionError(e, request=request)
requests.exceptions.ConnectionError: HTTPSConnectionPool(host='10.17.84.220', port=4343): Max retries exceeded with url: /v1/api/login (Caused by NewConnectionError('<urllib3.connection.HTTPSConnection object at 0x0000014C3ACA2940>: Failed to establish a new connection: [WinError 10065] A socket operation was attempted to an unreachable host'))
2020-09-12 19:32:37,984 > ERROR > ERROR:Precheck failed for => NaaS-MM-1:10.17.84.220:4343
2020-09-12 19:32:37,997 > DEBUG > ERROR:Precheck failed for => NaaS-MM-1:10.17.84.220:4343
2020-09-12 19:32:38,038 > INFO > INFO:Precheck started for : (MD) NaaS-VMC-1:10.17.84.221:4343
2020-09-12 19:32:38,054 > ERROR > ERROR:Login error : 10.17.84.221:4343
2020-09-12 19:32:38,067 > DEBUG > ERROR:Login error : 10.17.84.221:4343
2020-09-12 19:32:38,081 > ERROR > Login error:10.17.84.221:4343 
Traceback (most recent call last):
  File "d:\scripts\py\lib\site-packages\urllib3\connection.py", line 160, in _new_conn
    (self._dns_host, self.port), self.timeout, **extra_kw
  File "d:\scripts\py\lib\site-packages\urllib3\util\connection.py", line 84, in create_connection
    raise err
  File "d:\scripts\py\lib\site-packages\urllib3\util\connection.py", line 74, in create_connection
    sock.connect(sa)
OSError: [WinError 10065] A socket operation was attempted to an unreachable host

During handling of the above exception, another exception occurred:

Traceback (most recent call last):
  File "d:\scripts\py\lib\site-packages\urllib3\connectionpool.py", line 677, in urlopen
    chunked=chunked,
  File "d:\scripts\py\lib\site-packages\urllib3\connectionpool.py", line 381, in _make_request
    self._validate_conn(conn)
  File "d:\scripts\py\lib\site-packages\urllib3\connectionpool.py", line 976, in _validate_conn
    conn.connect()
  File "d:\scripts\py\lib\site-packages\urllib3\connection.py", line 308, in connect
    conn = self._new_conn()
  File "d:\scripts\py\lib\site-packages\urllib3\connection.py", line 172, in _new_conn
    self, "Failed to establish a new connection: %s" % e
urllib3.exceptions.NewConnectionError: <urllib3.connection.HTTPSConnection object at 0x0000014C3AC825F8>: Failed to establish a new connection: [WinError 10065] A socket operation was attempted to an unreachable host

During handling of the above exception, another exception occurred:

Traceback (most recent call last):
  File "d:\scripts\py\lib\site-packages\requests\adapters.py", line 449, in send
    timeout=timeout
  File "d:\scripts\py\lib\site-packages\urllib3\connectionpool.py", line 725, in urlopen
    method, url, error=e, _pool=self, _stacktrace=sys.exc_info()[2]
  File "d:\scripts\py\lib\site-packages\urllib3\util\retry.py", line 439, in increment
    raise MaxRetryError(_pool, url, error or ResponseError(cause))
urllib3.exceptions.MaxRetryError: HTTPSConnectionPool(host='10.17.84.221', port=4343): Max retries exceeded with url: /v1/api/login (Caused by NewConnectionError('<urllib3.connection.HTTPSConnection object at 0x0000014C3AC825F8>: Failed to establish a new connection: [WinError 10065] A socket operation was attempted to an unreachable host'))

During handling of the above exception, another exception occurred:

Traceback (most recent call last):
  File "D:\scripts\GIT\Aruba_Controller_upgrade\Aruba_Wireless_Upgrade_APP.py", line 95, in get_session
    res = r_session.post(login_url, data = login_post,verify=False)
  File "d:\scripts\py\lib\site-packages\requests\sessions.py", line 578, in post
    return self.request('POST', url, data=data, json=json, **kwargs)
  File "d:\scripts\py\lib\site-packages\requests\sessions.py", line 530, in request
    resp = self.send(prep, **send_kwargs)
  File "d:\scripts\py\lib\site-packages\requests\sessions.py", line 643, in send
    r = adapter.send(request, **kwargs)
  File "d:\scripts\py\lib\site-packages\requests\adapters.py", line 516, in send
    raise ConnectionError(e, request=request)
requests.exceptions.ConnectionError: HTTPSConnectionPool(host='10.17.84.221', port=4343): Max retries exceeded with url: /v1/api/login (Caused by NewConnectionError('<urllib3.connection.HTTPSConnection object at 0x0000014C3AC825F8>: Failed to establish a new connection: [WinError 10065] A socket operation was attempted to an unreachable host'))
2020-09-12 19:32:38,082 > ERROR > ERROR:Precheck failed for => NaaS-VMC-1:10.17.84.221:4343
2020-09-12 19:32:38,096 > DEBUG > ERROR:Precheck failed for => NaaS-VMC-1:10.17.84.221:4343
2020-09-12 19:32:38,123 > INFO > INFO:Precheck Completed
2020-09-12 19:32:38,139 > INFO > INFO:Total upgrade hosts:2
2020-09-12 19:32:38,152 > INFO > INFO:MM: Preparing for host NaaS-MM-1 IP: 10.17.84.220:4343
2020-09-12 19:32:38,167 > ERROR > ERROR:Login error : 10.17.84.220:4343
2020-09-12 19:32:38,180 > DEBUG > ERROR:Login error : 10.17.84.220:4343
2020-09-12 19:32:38,194 > ERROR > Login error:10.17.84.220:4343 
Traceback (most recent call last):
  File "d:\scripts\py\lib\site-packages\urllib3\connection.py", line 160, in _new_conn
    (self._dns_host, self.port), self.timeout, **extra_kw
  File "d:\scripts\py\lib\site-packages\urllib3\util\connection.py", line 84, in create_connection
    raise err
  File "d:\scripts\py\lib\site-packages\urllib3\util\connection.py", line 74, in create_connection
    sock.connect(sa)
OSError: [WinError 10065] A socket operation was attempted to an unreachable host

During handling of the above exception, another exception occurred:

Traceback (most recent call last):
  File "d:\scripts\py\lib\site-packages\urllib3\connectionpool.py", line 677, in urlopen
    chunked=chunked,
  File "d:\scripts\py\lib\site-packages\urllib3\connectionpool.py", line 381, in _make_request
    self._validate_conn(conn)
  File "d:\scripts\py\lib\site-packages\urllib3\connectionpool.py", line 976, in _validate_conn
    conn.connect()
  File "d:\scripts\py\lib\site-packages\urllib3\connection.py", line 308, in connect
    conn = self._new_conn()
  File "d:\scripts\py\lib\site-packages\urllib3\connection.py", line 172, in _new_conn
    self, "Failed to establish a new connection: %s" % e
urllib3.exceptions.NewConnectionError: <urllib3.connection.HTTPSConnection object at 0x0000014C3AC82C50>: Failed to establish a new connection: [WinError 10065] A socket operation was attempted to an unreachable host

During handling of the above exception, another exception occurred:

Traceback (most recent call last):
  File "d:\scripts\py\lib\site-packages\requests\adapters.py", line 449, in send
    timeout=timeout
  File "d:\scripts\py\lib\site-packages\urllib3\connectionpool.py", line 725, in urlopen
    method, url, error=e, _pool=self, _stacktrace=sys.exc_info()[2]
  File "d:\scripts\py\lib\site-packages\urllib3\util\retry.py", line 439, in increment
    raise MaxRetryError(_pool, url, error or ResponseError(cause))
urllib3.exceptions.MaxRetryError: HTTPSConnectionPool(host='10.17.84.220', port=4343): Max retries exceeded with url: /v1/api/login (Caused by NewConnectionError('<urllib3.connection.HTTPSConnection object at 0x0000014C3AC82C50>: Failed to establish a new connection: [WinError 10065] A socket operation was attempted to an unreachable host'))

During handling of the above exception, another exception occurred:

Traceback (most recent call last):
  File "D:\scripts\GIT\Aruba_Controller_upgrade\Aruba_Wireless_Upgrade_APP.py", line 95, in get_session
    res = r_session.post(login_url, data = login_post,verify=False)
  File "d:\scripts\py\lib\site-packages\requests\sessions.py", line 578, in post
    return self.request('POST', url, data=data, json=json, **kwargs)
  File "d:\scripts\py\lib\site-packages\requests\sessions.py", line 530, in request
    resp = self.send(prep, **send_kwargs)
  File "d:\scripts\py\lib\site-packages\requests\sessions.py", line 643, in send
    r = adapter.send(request, **kwargs)
  File "d:\scripts\py\lib\site-packages\requests\adapters.py", line 516, in send
    raise ConnectionError(e, request=request)
requests.exceptions.ConnectionError: HTTPSConnectionPool(host='10.17.84.220', port=4343): Max retries exceeded with url: /v1/api/login (Caused by NewConnectionError('<urllib3.connection.HTTPSConnection object at 0x0000014C3AC82C50>: Failed to establish a new connection: [WinError 10065] A socket operation was attempted to an unreachable host'))
2020-09-12 19:32:38,195 > INFO > INFO:MD: Preparing for host NaaS-VMC-1 IP: 10.17.84.221:4343
2020-09-12 19:32:38,209 > ERROR > ERROR:Login error : 10.17.84.221:4343
2020-09-12 19:32:38,223 > DEBUG > ERROR:Login error : 10.17.84.221:4343
2020-09-12 19:32:38,235 > ERROR > Login error:10.17.84.221:4343 
Traceback (most recent call last):
  File "d:\scripts\py\lib\site-packages\urllib3\connection.py", line 160, in _new_conn
    (self._dns_host, self.port), self.timeout, **extra_kw
  File "d:\scripts\py\lib\site-packages\urllib3\util\connection.py", line 84, in create_connection
    raise err
  File "d:\scripts\py\lib\site-packages\urllib3\util\connection.py", line 74, in create_connection
    sock.connect(sa)
OSError: [WinError 10065] A socket operation was attempted to an unreachable host

During handling of the above exception, another exception occurred:

Traceback (most recent call last):
  File "d:\scripts\py\lib\site-packages\urllib3\connectionpool.py", line 677, in urlopen
    chunked=chunked,
  File "d:\scripts\py\lib\site-packages\urllib3\connectionpool.py", line 381, in _make_request
    self._validate_conn(conn)
  File "d:\scripts\py\lib\site-packages\urllib3\connectionpool.py", line 976, in _validate_conn
    conn.connect()
  File "d:\scripts\py\lib\site-packages\urllib3\connection.py", line 308, in connect
    conn = self._new_conn()
  File "d:\scripts\py\lib\site-packages\urllib3\connection.py", line 172, in _new_conn
    self, "Failed to establish a new connection: %s" % e
urllib3.exceptions.NewConnectionError: <urllib3.connection.HTTPSConnection object at 0x0000014C3ACA6438>: Failed to establish a new connection: [WinError 10065] A socket operation was attempted to an unreachable host

During handling of the above exception, another exception occurred:

Traceback (most recent call last):
  File "d:\scripts\py\lib\site-packages\requests\adapters.py", line 449, in send
    timeout=timeout
  File "d:\scripts\py\lib\site-packages\urllib3\connectionpool.py", line 725, in urlopen
    method, url, error=e, _pool=self, _stacktrace=sys.exc_info()[2]
  File "d:\scripts\py\lib\site-packages\urllib3\util\retry.py", line 439, in increment
    raise MaxRetryError(_pool, url, error or ResponseError(cause))
urllib3.exceptions.MaxRetryError: HTTPSConnectionPool(host='10.17.84.221', port=4343): Max retries exceeded with url: /v1/api/login (Caused by NewConnectionError('<urllib3.connection.HTTPSConnection object at 0x0000014C3ACA6438>: Failed to establish a new connection: [WinError 10065] A socket operation was attempted to an unreachable host'))

During handling of the above exception, another exception occurred:

Traceback (most recent call last):
  File "D:\scripts\GIT\Aruba_Controller_upgrade\Aruba_Wireless_Upgrade_APP.py", line 95, in get_session
    res = r_session.post(login_url, data = login_post,verify=False)
  File "d:\scripts\py\lib\site-packages\requests\sessions.py", line 578, in post
    return self.request('POST', url, data=data, json=json, **kwargs)
  File "d:\scripts\py\lib\site-packages\requests\sessions.py", line 530, in request
    resp = self.send(prep, **send_kwargs)
  File "d:\scripts\py\lib\site-packages\requests\sessions.py", line 643, in send
    r = adapter.send(request, **kwargs)
  File "d:\scripts\py\lib\site-packages\requests\adapters.py", line 516, in send
    raise ConnectionError(e, request=request)
requests.exceptions.ConnectionError: HTTPSConnectionPool(host='10.17.84.221', port=4343): Max retries exceeded with url: /v1/api/login (Caused by NewConnectionError('<urllib3.connection.HTTPSConnection object at 0x0000014C3ACA6438>: Failed to establish a new connection: [WinError 10065] A socket operation was attempted to an unreachable host'))
2020-09-12 19:32:38,236 > ERROR > AP_IMAGE_PRELOAD: 
Traceback (most recent call last):
  File "D:\scripts\GIT\Aruba_Controller_upgrade\Aruba_Wireless_Upgrade_APP.py", line 573, in AP_IMAGE_PRELOAD
    if self.user_input("{} {} - {} from Disk {}".format(msg,host_name,host_ip,upgrade_disk),["yes","no"]) == "yes":
AttributeError: 'Aruba_Wireless_upgrade' object has no attribute 'user_input'
2020-09-12 19:32:38,237 > INFO > INFO:Starting all
2020-09-12 19:32:38,266 > INFO > INFO:==== Completed ====
