2020-09-29 05:56:17,560 > INFO > JOBNAME:1601339177_4580886
2020-09-29 05:56:17,561 > INFO > CONFIG FILE:d:\scripts\GIT\Aruba_Controller_upgrade\conf_files\LAB WIRELESS UPGRADE 8.5
2020-09-29 05:56:18,163 > INFO > Starting Job
2020-09-29 05:56:18,248 > INFO > INFO:Running: 1601339177_4580886 Type:precheck
2020-09-29 05:56:18,355 > INFO > INFO:Starting Configuration LAB WIRELESS UPGRADE 8.5 Validation
2020-09-29 05:56:18,513 > INFO > Inserting upgrade list to upgrade.db
2020-09-29 05:56:22,870 > INFO > yes
2020-09-29 05:56:22,870 > INFO > INFO:Starting precheck
2020-09-29 05:56:22,969 > INFO > INFO:Executing Precheck
2020-09-29 05:56:44,172 > ERROR > ERROR:Login error : 10.17.84.220:4343
2020-09-29 05:56:44,588 > DEBUG > ERROR:Login error : 10.17.84.220:4343
2020-09-29 05:56:44,662 > ERROR > Login error:10.17.84.220:4343 
Traceback (most recent call last):
  File "d:\scripts\py\lib\site-packages\urllib3\connection.py", line 160, in _new_conn
    (self._dns_host, self.port), self.timeout, **extra_kw
  File "d:\scripts\py\lib\site-packages\urllib3\util\connection.py", line 84, in create_connection
    raise err
  File "d:\scripts\py\lib\site-packages\urllib3\util\connection.py", line 74, in create_connection
    sock.connect(sa)
TimeoutError: [WinError 10060] A connection attempt failed because the connected party did not properly respond after a period of time, or established connection failed because connected host has failed to respond

During handling of the above exception, another exception occurred:

Traceback (most recent call last):
  File "d:\scripts\py\lib\site-packages\urllib3\connectionpool.py", line 677, in urlopen
    chunked=chunked,
  File "d:\scripts\py\lib\site-packages\urllib3\connectionpool.py", line 381, in _make_request
    self._validate_conn(conn)
  File "d:\scripts\py\lib\site-packages\urllib3\connectionpool.py", line 976, in _validate_conn
    conn.connect()
  File "d:\scripts\py\lib\site-packages\urllib3\connection.py", line 308, in connect
    conn = self._new_conn()
  File "d:\scripts\py\lib\site-packages\urllib3\connection.py", line 172, in _new_conn
    self, "Failed to establish a new connection: %s" % e
urllib3.exceptions.NewConnectionError: <urllib3.connection.HTTPSConnection object at 0x0000013AA8331D30>: Failed to establish a new connection: [WinError 10060] A connection attempt failed because the connected party did not properly respond after a period of time, or established connection failed because connected host has failed to respond

During handling of the above exception, another exception occurred:

Traceback (most recent call last):
  File "d:\scripts\py\lib\site-packages\requests\adapters.py", line 449, in send
    timeout=timeout
  File "d:\scripts\py\lib\site-packages\urllib3\connectionpool.py", line 725, in urlopen
    method, url, error=e, _pool=self, _stacktrace=sys.exc_info()[2]
  File "d:\scripts\py\lib\site-packages\urllib3\util\retry.py", line 439, in increment
    raise MaxRetryError(_pool, url, error or ResponseError(cause))
urllib3.exceptions.MaxRetryError: HTTPSConnectionPool(host='10.17.84.220', port=4343): Max retries exceeded with url: /v1/api/login (Caused by NewConnectionError('<urllib3.connection.HTTPSConnection object at 0x0000013AA8331D30>: Failed to establish a new connection: [WinError 10060] A connection attempt failed because the connected party did not properly respond after a period of time, or established connection failed because connected host has failed to respond'))

During handling of the above exception, another exception occurred:

Traceback (most recent call last):
  File "d:\scripts\GIT\Aruba_Controller_upgrade\Aruba_Wireless_Upgrade_APP.py", line 101, in get_session
    res = r_session.post(login_url, data = login_post,verify=False)
  File "d:\scripts\py\lib\site-packages\requests\sessions.py", line 578, in post
    return self.request('POST', url, data=data, json=json, **kwargs)
  File "d:\scripts\py\lib\site-packages\requests\sessions.py", line 530, in request
    resp = self.send(prep, **send_kwargs)
  File "d:\scripts\py\lib\site-packages\requests\sessions.py", line 643, in send
    r = adapter.send(request, **kwargs)
  File "d:\scripts\py\lib\site-packages\requests\adapters.py", line 516, in send
    raise ConnectionError(e, request=request)
requests.exceptions.ConnectionError: HTTPSConnectionPool(host='10.17.84.220', port=4343): Max retries exceeded with url: /v1/api/login (Caused by NewConnectionError('<urllib3.connection.HTTPSConnection object at 0x0000013AA8331D30>: Failed to establish a new connection: [WinError 10060] A connection attempt failed because the connected party did not properly respond after a period of time, or established connection failed because connected host has failed to respond'))
2020-09-29 05:57:05,921 > ERROR > ERROR:Login error : 10.17.84.220:4343
2020-09-29 05:57:06,008 > DEBUG > ERROR:Login error : 10.17.84.220:4343
2020-09-29 05:57:06,103 > ERROR > Login error:10.17.84.220:4343 
Traceback (most recent call last):
  File "d:\scripts\py\lib\site-packages\urllib3\connection.py", line 160, in _new_conn
    (self._dns_host, self.port), self.timeout, **extra_kw
  File "d:\scripts\py\lib\site-packages\urllib3\util\connection.py", line 84, in create_connection
    raise err
  File "d:\scripts\py\lib\site-packages\urllib3\util\connection.py", line 74, in create_connection
    sock.connect(sa)
TimeoutError: [WinError 10060] A connection attempt failed because the connected party did not properly respond after a period of time, or established connection failed because connected host has failed to respond

During handling of the above exception, another exception occurred:

Traceback (most recent call last):
  File "d:\scripts\py\lib\site-packages\urllib3\connectionpool.py", line 677, in urlopen
    chunked=chunked,
  File "d:\scripts\py\lib\site-packages\urllib3\connectionpool.py", line 381, in _make_request
    self._validate_conn(conn)
  File "d:\scripts\py\lib\site-packages\urllib3\connectionpool.py", line 976, in _validate_conn
    conn.connect()
  File "d:\scripts\py\lib\site-packages\urllib3\connection.py", line 308, in connect
    conn = self._new_conn()
  File "d:\scripts\py\lib\site-packages\urllib3\connection.py", line 172, in _new_conn
    self, "Failed to establish a new connection: %s" % e
urllib3.exceptions.NewConnectionError: <urllib3.connection.HTTPSConnection object at 0x0000013AA93BF748>: Failed to establish a new connection: [WinError 10060] A connection attempt failed because the connected party did not properly respond after a period of time, or established connection failed because connected host has failed to respond

During handling of the above exception, another exception occurred:

Traceback (most recent call last):
  File "d:\scripts\py\lib\site-packages\requests\adapters.py", line 449, in send
    timeout=timeout
  File "d:\scripts\py\lib\site-packages\urllib3\connectionpool.py", line 725, in urlopen
    method, url, error=e, _pool=self, _stacktrace=sys.exc_info()[2]
  File "d:\scripts\py\lib\site-packages\urllib3\util\retry.py", line 439, in increment
    raise MaxRetryError(_pool, url, error or ResponseError(cause))
urllib3.exceptions.MaxRetryError: HTTPSConnectionPool(host='10.17.84.220', port=4343): Max retries exceeded with url: /v1/api/login (Caused by NewConnectionError('<urllib3.connection.HTTPSConnection object at 0x0000013AA93BF748>: Failed to establish a new connection: [WinError 10060] A connection attempt failed because the connected party did not properly respond after a period of time, or established connection failed because connected host has failed to respond'))

During handling of the above exception, another exception occurred:

Traceback (most recent call last):
  File "d:\scripts\GIT\Aruba_Controller_upgrade\Aruba_Wireless_Upgrade_APP.py", line 101, in get_session
    res = r_session.post(login_url, data = login_post,verify=False)
  File "d:\scripts\py\lib\site-packages\requests\sessions.py", line 578, in post
    return self.request('POST', url, data=data, json=json, **kwargs)
  File "d:\scripts\py\lib\site-packages\requests\sessions.py", line 530, in request
    resp = self.send(prep, **send_kwargs)
  File "d:\scripts\py\lib\site-packages\requests\sessions.py", line 643, in send
    r = adapter.send(request, **kwargs)
  File "d:\scripts\py\lib\site-packages\requests\adapters.py", line 516, in send
    raise ConnectionError(e, request=request)
requests.exceptions.ConnectionError: HTTPSConnectionPool(host='10.17.84.220', port=4343): Max retries exceeded with url: /v1/api/login (Caused by NewConnectionError('<urllib3.connection.HTTPSConnection object at 0x0000013AA93BF748>: Failed to establish a new connection: [WinError 10060] A connection attempt failed because the connected party did not properly respond after a period of time, or established connection failed because connected host has failed to respond'))
2020-09-29 05:57:06,108 > ERROR > get_system_health
Traceback (most recent call last):
  File "d:\scripts\GIT\Aruba_Controller_upgrade\wireless_validation.py", line 83, in get_system_health
    if host_output.get("show storage") != None:
AttributeError: 'NoneType' object has no attribute 'get'
2020-09-29 05:57:27,177 > ERROR > ERROR:Login error : 10.17.84.221:4343
2020-09-29 05:57:27,301 > DEBUG > ERROR:Login error : 10.17.84.221:4343
2020-09-29 05:57:27,429 > ERROR > Login error:10.17.84.221:4343 
Traceback (most recent call last):
  File "d:\scripts\py\lib\site-packages\urllib3\connection.py", line 160, in _new_conn
    (self._dns_host, self.port), self.timeout, **extra_kw
  File "d:\scripts\py\lib\site-packages\urllib3\util\connection.py", line 84, in create_connection
    raise err
  File "d:\scripts\py\lib\site-packages\urllib3\util\connection.py", line 74, in create_connection
    sock.connect(sa)
TimeoutError: [WinError 10060] A connection attempt failed because the connected party did not properly respond after a period of time, or established connection failed because connected host has failed to respond

During handling of the above exception, another exception occurred:

Traceback (most recent call last):
  File "d:\scripts\py\lib\site-packages\urllib3\connectionpool.py", line 677, in urlopen
    chunked=chunked,
  File "d:\scripts\py\lib\site-packages\urllib3\connectionpool.py", line 381, in _make_request
    self._validate_conn(conn)
  File "d:\scripts\py\lib\site-packages\urllib3\connectionpool.py", line 976, in _validate_conn
    conn.connect()
  File "d:\scripts\py\lib\site-packages\urllib3\connection.py", line 308, in connect
    conn = self._new_conn()
  File "d:\scripts\py\lib\site-packages\urllib3\connection.py", line 172, in _new_conn
    self, "Failed to establish a new connection: %s" % e
urllib3.exceptions.NewConnectionError: <urllib3.connection.HTTPSConnection object at 0x0000013AA93E78D0>: Failed to establish a new connection: [WinError 10060] A connection attempt failed because the connected party did not properly respond after a period of time, or established connection failed because connected host has failed to respond

During handling of the above exception, another exception occurred:

Traceback (most recent call last):
  File "d:\scripts\py\lib\site-packages\requests\adapters.py", line 449, in send
    timeout=timeout
  File "d:\scripts\py\lib\site-packages\urllib3\connectionpool.py", line 725, in urlopen
    method, url, error=e, _pool=self, _stacktrace=sys.exc_info()[2]
  File "d:\scripts\py\lib\site-packages\urllib3\util\retry.py", line 439, in increment
    raise MaxRetryError(_pool, url, error or ResponseError(cause))
urllib3.exceptions.MaxRetryError: HTTPSConnectionPool(host='10.17.84.221', port=4343): Max retries exceeded with url: /v1/api/login (Caused by NewConnectionError('<urllib3.connection.HTTPSConnection object at 0x0000013AA93E78D0>: Failed to establish a new connection: [WinError 10060] A connection attempt failed because the connected party did not properly respond after a period of time, or established connection failed because connected host has failed to respond'))

During handling of the above exception, another exception occurred:

Traceback (most recent call last):
  File "d:\scripts\GIT\Aruba_Controller_upgrade\Aruba_Wireless_Upgrade_APP.py", line 101, in get_session
    res = r_session.post(login_url, data = login_post,verify=False)
  File "d:\scripts\py\lib\site-packages\requests\sessions.py", line 578, in post
    return self.request('POST', url, data=data, json=json, **kwargs)
  File "d:\scripts\py\lib\site-packages\requests\sessions.py", line 530, in request
    resp = self.send(prep, **send_kwargs)
  File "d:\scripts\py\lib\site-packages\requests\sessions.py", line 643, in send
    r = adapter.send(request, **kwargs)
  File "d:\scripts\py\lib\site-packages\requests\adapters.py", line 516, in send
    raise ConnectionError(e, request=request)
requests.exceptions.ConnectionError: HTTPSConnectionPool(host='10.17.84.221', port=4343): Max retries exceeded with url: /v1/api/login (Caused by NewConnectionError('<urllib3.connection.HTTPSConnection object at 0x0000013AA93E78D0>: Failed to establish a new connection: [WinError 10060] A connection attempt failed because the connected party did not properly respond after a period of time, or established connection failed because connected host has failed to respond'))
2020-09-29 05:57:48,436 > ERROR > ERROR:Login error : 10.17.84.221:4343
2020-09-29 05:57:48,619 > DEBUG > ERROR:Login error : 10.17.84.221:4343
2020-09-29 05:57:48,839 > ERROR > Login error:10.17.84.221:4343 
Traceback (most recent call last):
  File "d:\scripts\py\lib\site-packages\urllib3\connection.py", line 160, in _new_conn
    (self._dns_host, self.port), self.timeout, **extra_kw
  File "d:\scripts\py\lib\site-packages\urllib3\util\connection.py", line 84, in create_connection
    raise err
  File "d:\scripts\py\lib\site-packages\urllib3\util\connection.py", line 74, in create_connection
    sock.connect(sa)
TimeoutError: [WinError 10060] A connection attempt failed because the connected party did not properly respond after a period of time, or established connection failed because connected host has failed to respond

During handling of the above exception, another exception occurred:

Traceback (most recent call last):
  File "d:\scripts\py\lib\site-packages\urllib3\connectionpool.py", line 677, in urlopen
    chunked=chunked,
  File "d:\scripts\py\lib\site-packages\urllib3\connectionpool.py", line 381, in _make_request
    self._validate_conn(conn)
  File "d:\scripts\py\lib\site-packages\urllib3\connectionpool.py", line 976, in _validate_conn
    conn.connect()
  File "d:\scripts\py\lib\site-packages\urllib3\connection.py", line 308, in connect
    conn = self._new_conn()
  File "d:\scripts\py\lib\site-packages\urllib3\connection.py", line 172, in _new_conn
    self, "Failed to establish a new connection: %s" % e
urllib3.exceptions.NewConnectionError: <urllib3.connection.HTTPSConnection object at 0x0000013AA93E7978>: Failed to establish a new connection: [WinError 10060] A connection attempt failed because the connected party did not properly respond after a period of time, or established connection failed because connected host has failed to respond

During handling of the above exception, another exception occurred:

Traceback (most recent call last):
  File "d:\scripts\py\lib\site-packages\requests\adapters.py", line 449, in send
    timeout=timeout
  File "d:\scripts\py\lib\site-packages\urllib3\connectionpool.py", line 725, in urlopen
    method, url, error=e, _pool=self, _stacktrace=sys.exc_info()[2]
  File "d:\scripts\py\lib\site-packages\urllib3\util\retry.py", line 439, in increment
    raise MaxRetryError(_pool, url, error or ResponseError(cause))
urllib3.exceptions.MaxRetryError: HTTPSConnectionPool(host='10.17.84.221', port=4343): Max retries exceeded with url: /v1/api/login (Caused by NewConnectionError('<urllib3.connection.HTTPSConnection object at 0x0000013AA93E7978>: Failed to establish a new connection: [WinError 10060] A connection attempt failed because the connected party did not properly respond after a period of time, or established connection failed because connected host has failed to respond'))

During handling of the above exception, another exception occurred:

Traceback (most recent call last):
  File "d:\scripts\GIT\Aruba_Controller_upgrade\Aruba_Wireless_Upgrade_APP.py", line 101, in get_session
    res = r_session.post(login_url, data = login_post,verify=False)
  File "d:\scripts\py\lib\site-packages\requests\sessions.py", line 578, in post
    return self.request('POST', url, data=data, json=json, **kwargs)
  File "d:\scripts\py\lib\site-packages\requests\sessions.py", line 530, in request
    resp = self.send(prep, **send_kwargs)
  File "d:\scripts\py\lib\site-packages\requests\sessions.py", line 643, in send
    r = adapter.send(request, **kwargs)
  File "d:\scripts\py\lib\site-packages\requests\adapters.py", line 516, in send
    raise ConnectionError(e, request=request)
requests.exceptions.ConnectionError: HTTPSConnectionPool(host='10.17.84.221', port=4343): Max retries exceeded with url: /v1/api/login (Caused by NewConnectionError('<urllib3.connection.HTTPSConnection object at 0x0000013AA93E7978>: Failed to establish a new connection: [WinError 10060] A connection attempt failed because the connected party did not properly respond after a period of time, or established connection failed because connected host has failed to respond'))
2020-09-29 05:57:48,840 > ERROR > get_system_health
Traceback (most recent call last):
  File "d:\scripts\GIT\Aruba_Controller_upgrade\wireless_validation.py", line 83, in get_system_health
    if host_output.get("show storage") != None:
AttributeError: 'NoneType' object has no attribute 'get'
2020-09-29 05:57:49,044 > INFO > INFO:PRECHECK started for : (MM) NaaS-MM-1:10.17.84.220:4343
2020-09-29 05:57:54,572 > INFO > INFO:Login Success => 10.17.84.220:4343
2020-09-29 05:57:55,055 > INFO > INFO:Executing NaaS-MM-1 - 10.17.84.220:4343 => show clock
2020-09-29 05:57:57,323 > ERROR > ERROR:Validation failed for: NaaS-MM-1
2020-09-29 05:57:57,436 > DEBUG > ERROR:Validation failed for: NaaS-MM-1
2020-09-29 05:57:57,632 > ERROR > validating_pre_check
Traceback (most recent call last):
  File "d:\scripts\GIT\Aruba_Controller_upgrade\Aruba_Wireless_Upgrade_APP.py", line 245, in validating_pre_check
    running_disk = str(running_disk).split("PARTITION ")[1]
IndexError: list index out of range
2020-09-29 05:57:57,908 > INFO > INFO:PRECHECK started for : (MD) NaaS-VMC-1:10.17.84.221:4343
2020-09-29 05:58:03,398 > INFO > INFO:Login Success => 10.17.84.221:4343
2020-09-29 05:58:04,010 > INFO > INFO:Executing NaaS-VMC-1 - 10.17.84.221:4343 => show clock
2020-09-29 05:58:06,285 > ERROR > ERROR:Validation failed for: NaaS-VMC-1
2020-09-29 05:58:06,627 > DEBUG > ERROR:Validation failed for: NaaS-VMC-1
2020-09-29 05:58:06,700 > ERROR > validating_pre_check
Traceback (most recent call last):
  File "d:\scripts\GIT\Aruba_Controller_upgrade\Aruba_Wireless_Upgrade_APP.py", line 245, in validating_pre_check
    running_disk = str(running_disk).split("PARTITION ")[1]
IndexError: list index out of range
2020-09-29 05:58:06,803 > INFO > INFO:Precheck Completed
2020-09-29 05:58:07,028 > INFO > INFO:==== Completed ====
2020-09-29 06:01:38,468 > INFO > JOBNAME:1601339498_373947
2020-09-29 06:01:38,469 > INFO > CONFIG FILE:d:\scripts\GIT\Aruba_Controller_upgrade\conf_files\LAB WIRELESS UPGRADE 8.5
2020-09-29 06:01:38,980 > INFO > Starting Job
2020-09-29 06:01:39,079 > INFO > INFO:Running: 1601339498_373947 Type:precheck
2020-09-29 06:01:39,153 > INFO > INFO:Starting Configuration LAB WIRELESS UPGRADE 8.5 Validation
2020-09-29 06:01:39,240 > INFO > Inserting upgrade list to upgrade.db
2020-09-29 06:01:43,455 > INFO > yes
2020-09-29 06:01:43,455 > INFO > INFO:Starting precheck
2020-09-29 06:01:43,547 > INFO > INFO:Executing Precheck
2020-09-29 06:01:45,766 > INFO > INFO:Login Success => 10.17.84.220:4343
2020-09-29 06:01:50,632 > INFO > INFO:Session Valid : 10.17.84.220:4343
2020-09-29 06:01:54,826 > INFO > INFO:Login Success => 10.17.84.221:4343
2020-09-29 06:01:58,524 > INFO > INFO:Session Valid : 10.17.84.221:4343
2020-09-29 06:02:00,706 > INFO > INFO:PRECHECK started for : (MM) NaaS-MM-1:10.17.84.220:4343
2020-09-29 06:02:01,483 > INFO > INFO:Session Valid : 10.17.84.220:4343
2020-09-29 06:02:01,880 > INFO > INFO:Executing NaaS-MM-1 - 10.17.84.220:4343 => show clock
2020-09-29 06:02:02,674 > ERROR > ERROR:Validation failed for: NaaS-MM-1
2020-09-29 06:02:02,755 > DEBUG > ERROR:Validation failed for: NaaS-MM-1
2020-09-29 06:02:02,857 > ERROR > validating_pre_check
Traceback (most recent call last):
  File "d:\scripts\GIT\Aruba_Controller_upgrade\Aruba_Wireless_Upgrade_APP.py", line 245, in validating_pre_check
    running_disk = str(running_disk).split("PARTITION ")[1]
IndexError: list index out of range
2020-09-29 06:02:03,053 > INFO > INFO:PRECHECK started for : (MD) NaaS-VMC-1:10.17.84.221:4343
2020-09-29 06:02:03,834 > INFO > INFO:Session Valid : 10.17.84.221:4343
2020-09-29 06:02:04,140 > INFO > INFO:Executing NaaS-VMC-1 - 10.17.84.221:4343 => show clock
2020-09-29 06:02:04,912 > ERROR > ERROR:Validation failed for: NaaS-VMC-1
2020-09-29 06:02:05,099 > DEBUG > ERROR:Validation failed for: NaaS-VMC-1
2020-09-29 06:02:05,242 > ERROR > validating_pre_check
Traceback (most recent call last):
  File "d:\scripts\GIT\Aruba_Controller_upgrade\Aruba_Wireless_Upgrade_APP.py", line 245, in validating_pre_check
    running_disk = str(running_disk).split("PARTITION ")[1]
IndexError: list index out of range
2020-09-29 06:02:05,306 > INFO > INFO:Precheck Completed
2020-09-29 06:02:05,452 > INFO > INFO:==== Completed ====
