2020-09-10 17:31:27,112 > INFO > JOBNAME:1599739287_0216343
2020-09-10 17:31:27,113 > INFO > CONFIG FILE:D:\scripts\GIT\Aruba_Controller_upgrade\conf_files\configuration_2.yaml
2020-09-10 17:31:27,175 > INFO > Starting Job
2020-09-10 17:31:27,212 > INFO > INFO:Running: 1599739287_0216343 Type:precheck,all
2020-09-10 17:31:27,236 > INFO > INFO:Starting Configuration configuration_2.yaml Validation
2020-09-10 17:31:27,291 > INFO > Inserting upgrade list to upgrade.db
2020-09-10 17:31:27,349 > INFO > INFO:Starting precheck
2020-09-10 17:31:27,372 > INFO > INFO:Executing Precheck
2020-09-10 17:31:27,396 > INFO > INFO:Precheck started for : (MM) NaaS-MM-1:10.17.84.220:4343
2020-09-10 17:31:48,429 > ERROR > ERROR:Login error : 10.17.84.220:4343
2020-09-10 17:31:48,469 > DEBUG > ERROR:Login error : 10.17.84.220:4343
2020-09-10 17:31:48,500 > ERROR > Login error:10.17.84.220:4343 
Traceback (most recent call last):
  File "d:\scripts\py\lib\site-packages\urllib3\connection.py", line 160, in _new_conn
    (self._dns_host, self.port), self.timeout, **extra_kw
  File "d:\scripts\py\lib\site-packages\urllib3\util\connection.py", line 84, in create_connection
    raise err
  File "d:\scripts\py\lib\site-packages\urllib3\util\connection.py", line 74, in create_connection
    sock.connect(sa)
TimeoutError: [WinError 10060] A connection attempt failed because the connected party did not properly respond after a period of time, or established connection failed because connected host has failed to respond

During handling of the above exception, another exception occurred:

Traceback (most recent call last):
  File "d:\scripts\py\lib\site-packages\urllib3\connectionpool.py", line 677, in urlopen
    chunked=chunked,
  File "d:\scripts\py\lib\site-packages\urllib3\connectionpool.py", line 381, in _make_request
    self._validate_conn(conn)
  File "d:\scripts\py\lib\site-packages\urllib3\connectionpool.py", line 976, in _validate_conn
    conn.connect()
  File "d:\scripts\py\lib\site-packages\urllib3\connection.py", line 308, in connect
    conn = self._new_conn()
  File "d:\scripts\py\lib\site-packages\urllib3\connection.py", line 172, in _new_conn
    self, "Failed to establish a new connection: %s" % e
urllib3.exceptions.NewConnectionError: <urllib3.connection.HTTPSConnection object at 0x00000292DC38E128>: Failed to establish a new connection: [WinError 10060] A connection attempt failed because the connected party did not properly respond after a period of time, or established connection failed because connected host has failed to respond

During handling of the above exception, another exception occurred:

Traceback (most recent call last):
  File "d:\scripts\py\lib\site-packages\requests\adapters.py", line 449, in send
    timeout=timeout
  File "d:\scripts\py\lib\site-packages\urllib3\connectionpool.py", line 725, in urlopen
    method, url, error=e, _pool=self, _stacktrace=sys.exc_info()[2]
  File "d:\scripts\py\lib\site-packages\urllib3\util\retry.py", line 439, in increment
    raise MaxRetryError(_pool, url, error or ResponseError(cause))
urllib3.exceptions.MaxRetryError: HTTPSConnectionPool(host='10.17.84.220', port=4343): Max retries exceeded with url: /v1/api/login (Caused by NewConnectionError('<urllib3.connection.HTTPSConnection object at 0x00000292DC38E128>: Failed to establish a new connection: [WinError 10060] A connection attempt failed because the connected party did not properly respond after a period of time, or established connection failed because connected host has failed to respond'))

During handling of the above exception, another exception occurred:

Traceback (most recent call last):
  File "D:\scripts\GIT\Aruba_Controller_upgrade\Aruba_Wireless_Upgrade_APP.py", line 94, in get_session
    res = r_session.post(login_url, data = login_post,verify=False)
  File "d:\scripts\py\lib\site-packages\requests\sessions.py", line 578, in post
    return self.request('POST', url, data=data, json=json, **kwargs)
  File "d:\scripts\py\lib\site-packages\requests\sessions.py", line 530, in request
    resp = self.send(prep, **send_kwargs)
  File "d:\scripts\py\lib\site-packages\requests\sessions.py", line 643, in send
    r = adapter.send(request, **kwargs)
  File "d:\scripts\py\lib\site-packages\requests\adapters.py", line 516, in send
    raise ConnectionError(e, request=request)
requests.exceptions.ConnectionError: HTTPSConnectionPool(host='10.17.84.220', port=4343): Max retries exceeded with url: /v1/api/login (Caused by NewConnectionError('<urllib3.connection.HTTPSConnection object at 0x00000292DC38E128>: Failed to establish a new connection: [WinError 10060] A connection attempt failed because the connected party did not properly respond after a period of time, or established connection failed because connected host has failed to respond'))
2020-09-10 17:31:48,506 > ERROR > ERROR:Precheck failed for => NaaS-MM-1:10.17.84.220:4343
2020-09-10 17:31:48,532 > DEBUG > ERROR:Precheck failed for => NaaS-MM-1:10.17.84.220:4343
2020-09-10 17:31:48,557 > INFO > INFO:Precheck started for : (MD) NaaS-VMC-1:10.17.84.221:4343
2020-09-10 17:32:09,587 > ERROR > ERROR:Login error : 10.17.84.221:4343
2020-09-10 17:32:09,659 > DEBUG > ERROR:Login error : 10.17.84.221:4343
2020-09-10 17:32:09,682 > ERROR > Login error:10.17.84.221:4343 
Traceback (most recent call last):
  File "d:\scripts\py\lib\site-packages\urllib3\connection.py", line 160, in _new_conn
    (self._dns_host, self.port), self.timeout, **extra_kw
  File "d:\scripts\py\lib\site-packages\urllib3\util\connection.py", line 84, in create_connection
    raise err
  File "d:\scripts\py\lib\site-packages\urllib3\util\connection.py", line 74, in create_connection
    sock.connect(sa)
TimeoutError: [WinError 10060] A connection attempt failed because the connected party did not properly respond after a period of time, or established connection failed because connected host has failed to respond

During handling of the above exception, another exception occurred:

Traceback (most recent call last):
  File "d:\scripts\py\lib\site-packages\urllib3\connectionpool.py", line 677, in urlopen
    chunked=chunked,
  File "d:\scripts\py\lib\site-packages\urllib3\connectionpool.py", line 381, in _make_request
    self._validate_conn(conn)
  File "d:\scripts\py\lib\site-packages\urllib3\connectionpool.py", line 976, in _validate_conn
    conn.connect()
  File "d:\scripts\py\lib\site-packages\urllib3\connection.py", line 308, in connect
    conn = self._new_conn()
  File "d:\scripts\py\lib\site-packages\urllib3\connection.py", line 172, in _new_conn
    self, "Failed to establish a new connection: %s" % e
urllib3.exceptions.NewConnectionError: <urllib3.connection.HTTPSConnection object at 0x00000292DC38E5C0>: Failed to establish a new connection: [WinError 10060] A connection attempt failed because the connected party did not properly respond after a period of time, or established connection failed because connected host has failed to respond

During handling of the above exception, another exception occurred:

Traceback (most recent call last):
  File "d:\scripts\py\lib\site-packages\requests\adapters.py", line 449, in send
    timeout=timeout
  File "d:\scripts\py\lib\site-packages\urllib3\connectionpool.py", line 725, in urlopen
    method, url, error=e, _pool=self, _stacktrace=sys.exc_info()[2]
  File "d:\scripts\py\lib\site-packages\urllib3\util\retry.py", line 439, in increment
    raise MaxRetryError(_pool, url, error or ResponseError(cause))
urllib3.exceptions.MaxRetryError: HTTPSConnectionPool(host='10.17.84.221', port=4343): Max retries exceeded with url: /v1/api/login (Caused by NewConnectionError('<urllib3.connection.HTTPSConnection object at 0x00000292DC38E5C0>: Failed to establish a new connection: [WinError 10060] A connection attempt failed because the connected party did not properly respond after a period of time, or established connection failed because connected host has failed to respond'))

During handling of the above exception, another exception occurred:

Traceback (most recent call last):
  File "D:\scripts\GIT\Aruba_Controller_upgrade\Aruba_Wireless_Upgrade_APP.py", line 94, in get_session
    res = r_session.post(login_url, data = login_post,verify=False)
  File "d:\scripts\py\lib\site-packages\requests\sessions.py", line 578, in post
    return self.request('POST', url, data=data, json=json, **kwargs)
  File "d:\scripts\py\lib\site-packages\requests\sessions.py", line 530, in request
    resp = self.send(prep, **send_kwargs)
  File "d:\scripts\py\lib\site-packages\requests\sessions.py", line 643, in send
    r = adapter.send(request, **kwargs)
  File "d:\scripts\py\lib\site-packages\requests\adapters.py", line 516, in send
    raise ConnectionError(e, request=request)
requests.exceptions.ConnectionError: HTTPSConnectionPool(host='10.17.84.221', port=4343): Max retries exceeded with url: /v1/api/login (Caused by NewConnectionError('<urllib3.connection.HTTPSConnection object at 0x00000292DC38E5C0>: Failed to establish a new connection: [WinError 10060] A connection attempt failed because the connected party did not properly respond after a period of time, or established connection failed because connected host has failed to respond'))
2020-09-10 17:32:09,683 > ERROR > ERROR:Precheck failed for => NaaS-VMC-1:10.17.84.221:4343
2020-09-10 17:32:09,706 > DEBUG > ERROR:Precheck failed for => NaaS-VMC-1:10.17.84.221:4343
2020-09-10 17:32:09,728 > INFO > INFO:Precheck Completed
2020-09-10 17:32:09,750 > INFO > INFO:Total upgrade hosts:2
2020-09-10 17:32:09,773 > INFO > INFO:MM: Preparing for host NaaS-MM-1 IP: 10.17.84.220:4343
2020-09-10 17:32:30,810 > ERROR > ERROR:Login error : 10.17.84.220:4343
2020-09-10 17:32:30,843 > DEBUG > ERROR:Login error : 10.17.84.220:4343
2020-09-10 17:32:30,875 > ERROR > Login error:10.17.84.220:4343 
Traceback (most recent call last):
  File "d:\scripts\py\lib\site-packages\urllib3\connection.py", line 160, in _new_conn
    (self._dns_host, self.port), self.timeout, **extra_kw
  File "d:\scripts\py\lib\site-packages\urllib3\util\connection.py", line 84, in create_connection
    raise err
  File "d:\scripts\py\lib\site-packages\urllib3\util\connection.py", line 74, in create_connection
    sock.connect(sa)
TimeoutError: [WinError 10060] A connection attempt failed because the connected party did not properly respond after a period of time, or established connection failed because connected host has failed to respond

During handling of the above exception, another exception occurred:

Traceback (most recent call last):
  File "d:\scripts\py\lib\site-packages\urllib3\connectionpool.py", line 677, in urlopen
    chunked=chunked,
  File "d:\scripts\py\lib\site-packages\urllib3\connectionpool.py", line 381, in _make_request
    self._validate_conn(conn)
  File "d:\scripts\py\lib\site-packages\urllib3\connectionpool.py", line 976, in _validate_conn
    conn.connect()
  File "d:\scripts\py\lib\site-packages\urllib3\connection.py", line 308, in connect
    conn = self._new_conn()
  File "d:\scripts\py\lib\site-packages\urllib3\connection.py", line 172, in _new_conn
    self, "Failed to establish a new connection: %s" % e
urllib3.exceptions.NewConnectionError: <urllib3.connection.HTTPSConnection object at 0x00000292DB36B0F0>: Failed to establish a new connection: [WinError 10060] A connection attempt failed because the connected party did not properly respond after a period of time, or established connection failed because connected host has failed to respond

During handling of the above exception, another exception occurred:

Traceback (most recent call last):
  File "d:\scripts\py\lib\site-packages\requests\adapters.py", line 449, in send
    timeout=timeout
  File "d:\scripts\py\lib\site-packages\urllib3\connectionpool.py", line 725, in urlopen
    method, url, error=e, _pool=self, _stacktrace=sys.exc_info()[2]
  File "d:\scripts\py\lib\site-packages\urllib3\util\retry.py", line 439, in increment
    raise MaxRetryError(_pool, url, error or ResponseError(cause))
urllib3.exceptions.MaxRetryError: HTTPSConnectionPool(host='10.17.84.220', port=4343): Max retries exceeded with url: /v1/api/login (Caused by NewConnectionError('<urllib3.connection.HTTPSConnection object at 0x00000292DB36B0F0>: Failed to establish a new connection: [WinError 10060] A connection attempt failed because the connected party did not properly respond after a period of time, or established connection failed because connected host has failed to respond'))

During handling of the above exception, another exception occurred:

Traceback (most recent call last):
  File "D:\scripts\GIT\Aruba_Controller_upgrade\Aruba_Wireless_Upgrade_APP.py", line 94, in get_session
    res = r_session.post(login_url, data = login_post,verify=False)
  File "d:\scripts\py\lib\site-packages\requests\sessions.py", line 578, in post
    return self.request('POST', url, data=data, json=json, **kwargs)
  File "d:\scripts\py\lib\site-packages\requests\sessions.py", line 530, in request
    resp = self.send(prep, **send_kwargs)
  File "d:\scripts\py\lib\site-packages\requests\sessions.py", line 643, in send
    r = adapter.send(request, **kwargs)
  File "d:\scripts\py\lib\site-packages\requests\adapters.py", line 516, in send
    raise ConnectionError(e, request=request)
requests.exceptions.ConnectionError: HTTPSConnectionPool(host='10.17.84.220', port=4343): Max retries exceeded with url: /v1/api/login (Caused by NewConnectionError('<urllib3.connection.HTTPSConnection object at 0x00000292DB36B0F0>: Failed to establish a new connection: [WinError 10060] A connection attempt failed because the connected party did not properly respond after a period of time, or established connection failed because connected host has failed to respond'))
2020-09-10 17:32:30,876 > INFO > INFO:MD: Preparing for host NaaS-VMC-1 IP: 10.17.84.221:4343
2020-09-10 17:32:51,914 > ERROR > ERROR:Login error : 10.17.84.221:4343
2020-09-10 17:32:51,939 > DEBUG > ERROR:Login error : 10.17.84.221:4343
2020-09-10 17:32:51,981 > ERROR > Login error:10.17.84.221:4343 
Traceback (most recent call last):
  File "d:\scripts\py\lib\site-packages\urllib3\connection.py", line 160, in _new_conn
    (self._dns_host, self.port), self.timeout, **extra_kw
  File "d:\scripts\py\lib\site-packages\urllib3\util\connection.py", line 84, in create_connection
    raise err
  File "d:\scripts\py\lib\site-packages\urllib3\util\connection.py", line 74, in create_connection
    sock.connect(sa)
TimeoutError: [WinError 10060] A connection attempt failed because the connected party did not properly respond after a period of time, or established connection failed because connected host has failed to respond

During handling of the above exception, another exception occurred:

Traceback (most recent call last):
  File "d:\scripts\py\lib\site-packages\urllib3\connectionpool.py", line 677, in urlopen
    chunked=chunked,
  File "d:\scripts\py\lib\site-packages\urllib3\connectionpool.py", line 381, in _make_request
    self._validate_conn(conn)
  File "d:\scripts\py\lib\site-packages\urllib3\connectionpool.py", line 976, in _validate_conn
    conn.connect()
  File "d:\scripts\py\lib\site-packages\urllib3\connection.py", line 308, in connect
    conn = self._new_conn()
  File "d:\scripts\py\lib\site-packages\urllib3\connection.py", line 172, in _new_conn
    self, "Failed to establish a new connection: %s" % e
urllib3.exceptions.NewConnectionError: <urllib3.connection.HTTPSConnection object at 0x00000292DC3831D0>: Failed to establish a new connection: [WinError 10060] A connection attempt failed because the connected party did not properly respond after a period of time, or established connection failed because connected host has failed to respond

During handling of the above exception, another exception occurred:

Traceback (most recent call last):
  File "d:\scripts\py\lib\site-packages\requests\adapters.py", line 449, in send
    timeout=timeout
  File "d:\scripts\py\lib\site-packages\urllib3\connectionpool.py", line 725, in urlopen
    method, url, error=e, _pool=self, _stacktrace=sys.exc_info()[2]
  File "d:\scripts\py\lib\site-packages\urllib3\util\retry.py", line 439, in increment
    raise MaxRetryError(_pool, url, error or ResponseError(cause))
urllib3.exceptions.MaxRetryError: HTTPSConnectionPool(host='10.17.84.221', port=4343): Max retries exceeded with url: /v1/api/login (Caused by NewConnectionError('<urllib3.connection.HTTPSConnection object at 0x00000292DC3831D0>: Failed to establish a new connection: [WinError 10060] A connection attempt failed because the connected party did not properly respond after a period of time, or established connection failed because connected host has failed to respond'))

During handling of the above exception, another exception occurred:

Traceback (most recent call last):
  File "D:\scripts\GIT\Aruba_Controller_upgrade\Aruba_Wireless_Upgrade_APP.py", line 94, in get_session
    res = r_session.post(login_url, data = login_post,verify=False)
  File "d:\scripts\py\lib\site-packages\requests\sessions.py", line 578, in post
    return self.request('POST', url, data=data, json=json, **kwargs)
  File "d:\scripts\py\lib\site-packages\requests\sessions.py", line 530, in request
    resp = self.send(prep, **send_kwargs)
  File "d:\scripts\py\lib\site-packages\requests\sessions.py", line 643, in send
    r = adapter.send(request, **kwargs)
  File "d:\scripts\py\lib\site-packages\requests\adapters.py", line 516, in send
    raise ConnectionError(e, request=request)
requests.exceptions.ConnectionError: HTTPSConnectionPool(host='10.17.84.221', port=4343): Max retries exceeded with url: /v1/api/login (Caused by NewConnectionError('<urllib3.connection.HTTPSConnection object at 0x00000292DC3831D0>: Failed to establish a new connection: [WinError 10060] A connection attempt failed because the connected party did not properly respond after a period of time, or established connection failed because connected host has failed to respond'))
2020-09-10 17:32:51,983 > ERROR > AP_IMAGE_PRELOAD: 
Traceback (most recent call last):
  File "D:\scripts\GIT\Aruba_Controller_upgrade\Aruba_Wireless_Upgrade_APP.py", line 551, in AP_IMAGE_PRELOAD
    max_ap_image_load = self.single_host.get("max_ap_image_load")
AttributeError: 'Aruba_Wireless_upgrade' object has no attribute 'single_host'
2020-09-10 17:32:51,983 > INFO > INFO:Starting all
2020-09-10 17:32:52,057 > INFO > INFO:==== Completed ====
2020-09-10 17:35:27,352 > INFO > JOBNAME:1599739527_237389
2020-09-10 17:35:27,352 > INFO > CONFIG FILE:D:\scripts\GIT\Aruba_Controller_upgrade\conf_files\configuration_2.yaml
2020-09-10 17:35:27,505 > INFO > Starting Job
2020-09-10 17:35:27,530 > INFO > INFO:Running: 1599739527_237389 Type:precheck,all
2020-09-10 17:35:27,552 > INFO > INFO:Starting Configuration configuration_2.yaml Validation
2020-09-10 17:35:27,602 > INFO > Inserting upgrade list to upgrade.db
2020-09-10 17:35:27,706 > INFO > INFO:Starting precheck
2020-09-10 17:35:27,729 > INFO > INFO:Executing Precheck
2020-09-10 17:35:27,753 > INFO > INFO:Precheck started for : (MM) NaaS-MM-1:10.17.84.220:4343
2020-09-10 17:35:30,780 > INFO > INFO:Login Success => 10.17.84.220:4343
2020-09-10 17:35:30,806 > INFO > INFO:Executing NaaS-MM-1 - 10.17.84.220:4343 => show clock
2020-09-10 17:35:33,686 > INFO > INFO:Executing NaaS-MM-1 - 10.17.84.220:4343 => show version
2020-09-10 17:35:34,783 > INFO > INFO:Executing NaaS-MM-1 - 10.17.84.220:4343 => show image version
2020-09-10 17:35:35,737 > INFO > INFO:Executing NaaS-MM-1 - 10.17.84.220:4343 => show storage
2020-09-10 17:35:36,619 > INFO > INFO:Executing NaaS-MM-1 - 10.17.84.220:4343 => show cpuload
2020-09-10 17:35:37,489 > INFO > INFO:Executing NaaS-MM-1 - 10.17.84.220:4343 => show memory
2020-09-10 17:35:38,349 > INFO > INFO:Executing NaaS-MM-1 - 10.17.84.220:4343 => show boot
2020-09-10 17:35:39,201 > INFO > INFO:Executing NaaS-MM-1 - 10.17.84.220:4343 => show switches
2020-09-10 17:35:40,153 > INFO > INFO:Executing NaaS-MM-1 - 10.17.84.220:4343 => show switchinfo
2020-09-10 17:35:41,416 > INFO > INFO:Executing NaaS-MM-1 - 10.17.84.220:4343 => show boot history
2020-09-10 17:35:42,874 > INFO > INFO:Executing NaaS-MM-1 - 10.17.84.220:4343 => show crypto ipsec sa
2020-09-10 17:35:43,846 > INFO > INFO:Executing NaaS-MM-1 - 10.17.84.220:4343 => show master-redundancy
2020-09-10 17:35:44,838 > INFO > INFO:Executing NaaS-MM-1 - 10.17.84.220:4343 => show database synchronize
2020-09-10 17:35:45,630 > INFO > INFO:Executing NaaS-MM-1 - 10.17.84.220:4343 => show license
2020-09-10 17:35:46,413 > INFO > INFO:Executing NaaS-MM-1 - 10.17.84.220:4343 => show running-config
2020-09-10 17:35:50,325 > INFO > INFO:Precheck started for : (MD) NaaS-VMC-1:10.17.84.221:4343
2020-09-10 17:35:56,293 > INFO > INFO:Login Success => 10.17.84.221:4343
2020-09-10 17:35:56,324 > INFO > INFO:Executing NaaS-VMC-1 - 10.17.84.221:4343 => show clock
2020-09-10 17:35:59,085 > INFO > INFO:Executing NaaS-VMC-1 - 10.17.84.221:4343 => show version
2020-09-10 17:35:59,965 > INFO > INFO:Executing NaaS-VMC-1 - 10.17.84.221:4343 => show image version
2020-09-10 17:36:00,825 > INFO > INFO:Executing NaaS-VMC-1 - 10.17.84.221:4343 => show storage
2020-09-10 17:36:01,665 > INFO > INFO:Executing NaaS-VMC-1 - 10.17.84.221:4343 => show cpuload
2020-09-10 17:36:02,525 > INFO > INFO:Executing NaaS-VMC-1 - 10.17.84.221:4343 => show memory
2020-09-10 17:36:03,341 > INFO > INFO:Executing NaaS-VMC-1 - 10.17.84.221:4343 => show boot
2020-09-10 17:36:04,201 > INFO > INFO:Executing NaaS-VMC-1 - 10.17.84.221:4343 => show switches
2020-09-10 17:36:05,046 > INFO > INFO:Executing NaaS-VMC-1 - 10.17.84.221:4343 => show switchinfo
2020-09-10 17:36:05,892 > INFO > INFO:Executing NaaS-VMC-1 - 10.17.84.221:4343 => show boot history
2020-09-10 17:36:06,831 > INFO > INFO:Executing NaaS-VMC-1 - 10.17.84.221:4343 => show user
2020-09-10 17:36:07,741 > INFO > INFO:Executing NaaS-VMC-1 - 10.17.84.221:4343 => show ap database long
2020-09-10 17:36:08,562 > INFO > INFO:Executing NaaS-VMC-1 - 10.17.84.221:4343 => show ap bss-table
2020-09-10 17:36:09,991 > INFO > INFO:Executing NaaS-VMC-1 - 10.17.84.221:4343 => show ap essid
2020-09-10 17:36:10,822 > INFO > INFO:Executing NaaS-VMC-1 - 10.17.84.221:4343 => show ap active counters
2020-09-10 17:36:11,657 > INFO > INFO:Executing NaaS-VMC-1 - 10.17.84.221:4343 => show ap debug counters
2020-09-10 17:36:12,606 > INFO > INFO:Executing NaaS-VMC-1 - 10.17.84.221:4343 => show lc-cluster group-membership
2020-09-10 17:36:13,402 > INFO > INFO:Executing NaaS-VMC-1 - 10.17.84.221:4343 => show switches
2020-09-10 17:36:14,233 > INFO > INFO:Executing NaaS-VMC-1 - 10.17.84.221:4343 => show license
2020-09-10 17:36:15,064 > INFO > INFO:Executing NaaS-VMC-1 - 10.17.84.221:4343 => show running-config
2020-09-10 17:36:16,654 > INFO > INFO:Executing NaaS-VMC-1 - 10.17.84.221:4343 => show boot
2020-09-10 17:36:17,497 > INFO > INFO:Executing NaaS-VMC-1 - 10.17.84.221:4343 => show version
2020-09-10 17:36:18,434 > INFO > INFO:Precheck Completed
2020-09-10 17:36:18,459 > INFO > INFO:Total upgrade hosts:2
2020-09-10 17:36:18,504 > INFO > INFO:MM: Preparing for host NaaS-MM-1 IP: 10.17.84.220:4343
2020-09-10 17:36:21,350 > INFO > INFO:Session Valid : 10.17.84.220:4343
2020-09-10 17:36:22,636 > ERROR > validate_image_upload
Traceback (most recent call last):
  File "D:\scripts\GIT\Aruba_Controller_upgrade\Aruba_Wireless_Upgrade_APP.py", line 357, in validate_image_upload
    if int(disk) == int(first_partition):
ValueError: invalid literal for int() with base 10: 'Auto'
2020-09-10 17:36:22,636 > INFO > INFO:MD: Preparing for host NaaS-VMC-1 IP: 10.17.84.221:4343
2020-09-10 17:36:23,469 > INFO > INFO:Session Valid : 10.17.84.221:4343
2020-09-10 17:36:24,258 > ERROR > validate_image_upload
Traceback (most recent call last):
  File "D:\scripts\GIT\Aruba_Controller_upgrade\Aruba_Wireless_Upgrade_APP.py", line 357, in validate_image_upload
    if int(disk) == int(first_partition):
ValueError: invalid literal for int() with base 10: 'Auto'
2020-09-10 17:36:24,258 > ERROR > AP_IMAGE_PRELOAD: 
Traceback (most recent call last):
  File "D:\scripts\GIT\Aruba_Controller_upgrade\Aruba_Wireless_Upgrade_APP.py", line 551, in AP_IMAGE_PRELOAD
    max_ap_image_load = self.single_host.get("max_ap_image_load")
AttributeError: 'Aruba_Wireless_upgrade' object has no attribute 'single_host'
2020-09-10 17:36:24,258 > INFO > INFO:Starting all
2020-09-10 17:36:25,513 > INFO > INFO:==== Completed ====
